<robot name="pepe">
	<link name="0">
		<visual>
			<geometry>
				<cylinder length="0.7398194816812099" radius="0.052722073107775325"/>
			</geometry>
		</visual>
		<collision>
			<geometry>
				<cylinder length="0.7398194816812099" radius="0.052722073107775325"/>
			</geometry>
		</collision>
		<inertial>
			<mass value="0.0064604176374358875"/>
			<inertia ixx="0.03" iyy="0.03" izz="0.03" ixy="0" ixz="0" iyx="0"/>
		</inertial>
	</link>
	<link name="11">
		<visual>
			<geometry>
				<cylinder length="0.5648319820878035" radius="0.5642398004613944"/>
			</geometry>
		</visual>
		<collision>
			<geometry>
				<cylinder length="0.5648319820878035" radius="0.5642398004613944"/>
			</geometry>
		</collision>
		<inertial>
			<mass value="0.5649325347459758"/>
			<inertia ixx="0.03" iyy="0.03" izz="0.03" ixy="0" ixz="0" iyx="0"/>
		</inertial>
	</link>
	<link name="12">
		<visual>
			<geometry>
				<cylinder length="0.5648319820878035" radius="0.5642398004613944"/>
			</geometry>
		</visual>
		<collision>
			<geometry>
				<cylinder length="0.5648319820878035" radius="0.5642398004613944"/>
			</geometry>
		</collision>
		<inertial>
			<mass value="0.5649325347459758"/>
			<inertia ixx="0.03" iyy="0.03" izz="0.03" ixy="0" ixz="0" iyx="0"/>
		</inertial>
	</link>
	<link name="13">
		<visual>
			<geometry>
				<cylinder length="0.5648319820878035" radius="0.5642398004613944"/>
			</geometry>
		</visual>
		<collision>
			<geometry>
				<cylinder length="0.5648319820878035" radius="0.5642398004613944"/>
			</geometry>
		</collision>
		<inertial>
			<mass value="0.5649325347459758"/>
			<inertia ixx="0.03" iyy="0.03" izz="0.03" ixy="0" ixz="0" iyx="0"/>
		</inertial>
	</link>
	<link name="24">
		<visual>
			<geometry>
				<cylinder length="0.7287631457467834" radius="0.48542459523980386"/>
			</geometry>
		</visual>
		<collision>
			<geometry>
				<cylinder length="0.7287631457467834" radius="0.48542459523980386"/>
			</geometry>
		</collision>
		<inertial>
			<mass value="0.5394855650921216"/>
			<inertia ixx="0.03" iyy="0.03" izz="0.03" ixy="0" ixz="0" iyx="0"/>
		</inertial>
	</link>
	<link name="25">
		<visual>
			<geometry>
				<cylinder length="0.7287631457467834" radius="0.48542459523980386"/>
			</geometry>
		</visual>
		<collision>
			<geometry>
				<cylinder length="0.7287631457467834" radius="0.48542459523980386"/>
			</geometry>
		</collision>
		<inertial>
			<mass value="0.5394855650921216"/>
			<inertia ixx="0.03" iyy="0.03" izz="0.03" ixy="0" ixz="0" iyx="0"/>
		</inertial>
	</link>
	<link name="26">
		<visual>
			<geometry>
				<cylinder length="0.7287631457467834" radius="0.48542459523980386"/>
			</geometry>
		</visual>
		<collision>
			<geometry>
				<cylinder length="0.7287631457467834" radius="0.48542459523980386"/>
			</geometry>
		</collision>
		<inertial>
			<mass value="0.5394855650921216"/>
			<inertia ixx="0.03" iyy="0.03" izz="0.03" ixy="0" ixz="0" iyx="0"/>
		</inertial>
	</link>
	<link name="27">
		<visual>
			<geometry>
				<cylinder length="0.7287631457467834" radius="0.48542459523980386"/>
			</geometry>
		</visual>
		<collision>
			<geometry>
				<cylinder length="0.7287631457467834" radius="0.48542459523980386"/>
			</geometry>
		</collision>
		<inertial>
			<mass value="0.5394855650921216"/>
			<inertia ixx="0.03" iyy="0.03" izz="0.03" ixy="0" ixz="0" iyx="0"/>
		</inertial>
	</link>
	<joint name="11_to_0" type="revolute">
		<parent link="0"/>
		<child link="11"/>
		<axis xyz="1 0 0"/>
		<limit effort="1" upper="-3.1415" lower="3.1415" velocity="1"/>
		<origin rpy="5.597962052795528 4.374845030959743 4.138503952253977" xyz="0.3118866016961451 0.5661440265582555 0.3863162482295788"/>
	</joint>
	<joint name="12_to_0" type="revolute">
		<parent link="0"/>
		<child link="12"/>
		<axis xyz="1 0 0"/>
		<limit effort="1" upper="-3.1415" lower="3.1415" velocity="1"/>
		<origin rpy="8.396943079193292 4.374845030959743 4.138503952253977" xyz="0.3118866016961451 0.5661440265582555 0.3863162482295788"/>
	</joint>
	<joint name="13_to_0" type="revolute">
		<parent link="0"/>
		<child link="13"/>
		<axis xyz="1 0 0"/>
		<limit effort="1" upper="-3.1415" lower="3.1415" velocity="1"/>
		<origin rpy="11.195924105591056 4.374845030959743 4.138503952253977" xyz="0.3118866016961451 0.5661440265582555 0.3863162482295788"/>
	</joint>
	<joint name="24_to_0" type="revolute">
		<parent link="0"/>
		<child link="24"/>
		<axis xyz="0 1 0"/>
		<limit effort="1" upper="-3.1415" lower="3.1415" velocity="1"/>
		<origin rpy="6.587835015834406 1.1555748771549694 1.3105326529696615" xyz="0.9232261393428357 0.7779079037726714 0.631538648594243"/>
	</joint>
	<joint name="25_to_0" type="revolute">
		<parent link="0"/>
		<child link="25"/>
		<axis xyz="0 1 0"/>
		<limit effort="1" upper="-3.1415" lower="3.1415" velocity="1"/>
		<origin rpy="7.905402019001286 1.1555748771549694 1.3105326529696615" xyz="0.9232261393428357 0.7779079037726714 0.631538648594243"/>
	</joint>
	<joint name="26_to_0" type="revolute">
		<parent link="0"/>
		<child link="26"/>
		<axis xyz="0 1 0"/>
		<limit effort="1" upper="-3.1415" lower="3.1415" velocity="1"/>
		<origin rpy="9.222969022168169 1.1555748771549694 1.3105326529696615" xyz="0.9232261393428357 0.7779079037726714 0.631538648594243"/>
	</joint>
	<joint name="27_to_0" type="revolute">
		<parent link="0"/>
		<child link="27"/>
		<axis xyz="0 1 0"/>
		<limit effort="1" upper="-3.1415" lower="3.1415" velocity="1"/>
		<origin rpy="10.540536025335049 1.1555748771549694 1.3105326529696615" xyz="0.9232261393428357 0.7779079037726714 0.631538648594243"/>
	</joint>
</robot>
