<robot name="pepe">
	<link name="0">
		<visual>
			<geometry>
				<cylinder length="0.9724069702602065" radius="0.9601196510178068"/>
			</geometry>
		</visual>
		<collision>
			<geometry>
				<cylinder length="0.9724069702602065" radius="0.9601196510178068"/>
			</geometry>
		</collision>
		<inertial>
			<mass value="2.8161037643810345"/>
			<inertia ixx="0.03" iyy="0.03" izz="0.03" ixy="0" ixz="0" iyx="0"/>
		</inertial>
	</link>
	<link name="11">
		<visual>
			<geometry>
				<cylinder length="0.8157967461195692" radius="0.32445357987726464"/>
			</geometry>
		</visual>
		<collision>
			<geometry>
				<cylinder length="0.8157967461195692" radius="0.32445357987726464"/>
			</geometry>
		</collision>
		<inertial>
			<mass value="0.26979691668443595"/>
			<inertia ixx="0.03" iyy="0.03" izz="0.03" ixy="0" ixz="0" iyx="0"/>
		</inertial>
	</link>
	<link name="12">
		<visual>
			<geometry>
				<cylinder length="0.8157967461195692" radius="0.32445357987726464"/>
			</geometry>
		</visual>
		<collision>
			<geometry>
				<cylinder length="0.8157967461195692" radius="0.32445357987726464"/>
			</geometry>
		</collision>
		<inertial>
			<mass value="0.26979691668443595"/>
			<inertia ixx="0.03" iyy="0.03" izz="0.03" ixy="0" ixz="0" iyx="0"/>
		</inertial>
	</link>
	<link name="23">
		<visual>
			<geometry>
				<cylinder length="0.31253496550250237" radius="0.37575605801517764"/>
			</geometry>
		</visual>
		<collision>
			<geometry>
				<cylinder length="0.31253496550250237" radius="0.37575605801517764"/>
			</geometry>
		</collision>
		<inertial>
			<mass value="0.13863103540233496"/>
			<inertia ixx="0.03" iyy="0.03" izz="0.03" ixy="0" ixz="0" iyx="0"/>
		</inertial>
	</link>
	<link name="34">
		<visual>
			<geometry>
				<cylinder length="0.2040564871830005" radius="0.7482889396425668"/>
			</geometry>
		</visual>
		<collision>
			<geometry>
				<cylinder length="0.2040564871830005" radius="0.7482889396425668"/>
			</geometry>
		</collision>
		<inertial>
			<mass value="0.3589541103584202"/>
			<inertia ixx="0.03" iyy="0.03" izz="0.03" ixy="0" ixz="0" iyx="0"/>
		</inertial>
	</link>
	<link name="35">
		<visual>
			<geometry>
				<cylinder length="0.2040564871830005" radius="0.7482889396425668"/>
			</geometry>
		</visual>
		<collision>
			<geometry>
				<cylinder length="0.2040564871830005" radius="0.7482889396425668"/>
			</geometry>
		</collision>
		<inertial>
			<mass value="0.3589541103584202"/>
			<inertia ixx="0.03" iyy="0.03" izz="0.03" ixy="0" ixz="0" iyx="0"/>
		</inertial>
	</link>
	<link name="36">
		<visual>
			<geometry>
				<cylinder length="0.2040564871830005" radius="0.7482889396425668"/>
			</geometry>
		</visual>
		<collision>
			<geometry>
				<cylinder length="0.2040564871830005" radius="0.7482889396425668"/>
			</geometry>
		</collision>
		<inertial>
			<mass value="0.3589541103584202"/>
			<inertia ixx="0.03" iyy="0.03" izz="0.03" ixy="0" ixz="0" iyx="0"/>
		</inertial>
	</link>
	<link name="37">
		<visual>
			<geometry>
				<cylinder length="0.2040564871830005" radius="0.7482889396425668"/>
			</geometry>
		</visual>
		<collision>
			<geometry>
				<cylinder length="0.2040564871830005" radius="0.7482889396425668"/>
			</geometry>
		</collision>
		<inertial>
			<mass value="0.3589541103584202"/>
			<inertia ixx="0.03" iyy="0.03" izz="0.03" ixy="0" ixz="0" iyx="0"/>
		</inertial>
	</link>
	<joint name="11_to_0" type="revolute">
		<parent link="0"/>
		<child link="11"/>
		<axis xyz="0 0 1"/>
		<limit effort="1" upper="-3.1415" lower="3.1415" velocity="1"/>
		<origin rpy="4.925507931950128 1.9938912850860744 0.707773777047744" xyz="0.3018089232343095 0.19770403714540463 0.392045896834455"/>
	</joint>
	<joint name="12_to_0" type="revolute">
		<parent link="0"/>
		<child link="12"/>
		<axis xyz="0 0 1"/>
		<limit effort="1" upper="-3.1415" lower="3.1415" velocity="1"/>
		<origin rpy="7.388261897925192 1.9938912850860744 0.707773777047744" xyz="0.3018089232343095 0.19770403714540463 0.392045896834455"/>
	</joint>
	<joint name="23_to_0" type="revolute">
		<parent link="0"/>
		<child link="23"/>
		<axis xyz="1 0 0"/>
		<limit effort="1" upper="-3.1415" lower="3.1415" velocity="1"/>
		<origin rpy="14.240156833324486 2.7511320262002803 4.750793003916342" xyz="0.26054380147416933 0.6530402882042914 0.16106488141066266"/>
	</joint>
	<joint name="34_to_0" type="revolute">
		<parent link="0"/>
		<child link="34"/>
		<axis xyz="0 1 0"/>
		<limit effort="1" upper="-3.1415" lower="3.1415" velocity="1"/>
		<origin rpy="6.340075218630197 0.07998476401470773 1.996686727448204" xyz="0.5864566203229808 0.13068199545191084 0.2911647455957018"/>
	</joint>
	<joint name="35_to_0" type="revolute">
		<parent link="0"/>
		<child link="35"/>
		<axis xyz="0 1 0"/>
		<limit effort="1" upper="-3.1415" lower="3.1415" velocity="1"/>
		<origin rpy="7.608090262356236 0.07998476401470773 1.996686727448204" xyz="0.5864566203229808 0.13068199545191084 0.2911647455957018"/>
	</joint>
	<joint name="36_to_0" type="revolute">
		<parent link="0"/>
		<child link="36"/>
		<axis xyz="0 1 0"/>
		<limit effort="1" upper="-3.1415" lower="3.1415" velocity="1"/>
		<origin rpy="8.876105306082275 0.07998476401470773 1.996686727448204" xyz="0.5864566203229808 0.13068199545191084 0.2911647455957018"/>
	</joint>
	<joint name="37_to_0" type="revolute">
		<parent link="0"/>
		<child link="37"/>
		<axis xyz="0 1 0"/>
		<limit effort="1" upper="-3.1415" lower="3.1415" velocity="1"/>
		<origin rpy="10.144120349808315 0.07998476401470773 1.996686727448204" xyz="0.5864566203229808 0.13068199545191084 0.2911647455957018"/>
	</joint>
</robot>
