<robot name="pepe">
	<link name="0">
		<visual>
			<geometry>
				<cylinder length="0.2200615809877765" radius="0.2761654064408394"/>
			</geometry>
		</visual>
		<collision>
			<geometry>
				<cylinder length="0.2200615809877765" radius="0.2761654064408394"/>
			</geometry>
		</collision>
		<inertial>
			<mass value="0.05272695044460802"/>
			<inertia ixx="0.03" iyy="0.03" izz="0.03" ixy="0" ixz="0" iyx="0"/>
		</inertial>
	</link>
	<link name="11">
		<visual>
			<geometry>
				<cylinder length="0.7390980158932943" radius="0.539671473785115"/>
			</geometry>
		</visual>
		<collision>
			<geometry>
				<cylinder length="0.7390980158932943" radius="0.539671473785115"/>
			</geometry>
		</collision>
		<inertial>
			<mass value="0.6762555372256879"/>
			<inertia ixx="0.03" iyy="0.03" izz="0.03" ixy="0" ixz="0" iyx="0"/>
		</inertial>
	</link>
	<link name="22">
		<visual>
			<geometry>
				<cylinder length="0.4871520967295079" radius="0.2355285011149646"/>
			</geometry>
		</visual>
		<collision>
			<geometry>
				<cylinder length="0.4871520967295079" radius="0.2355285011149646"/>
			</geometry>
		</collision>
		<inertial>
			<mass value="0.0848987674694995"/>
			<inertia ixx="0.03" iyy="0.03" izz="0.03" ixy="0" ixz="0" iyx="0"/>
		</inertial>
	</link>
	<link name="23">
		<visual>
			<geometry>
				<cylinder length="0.4871520967295079" radius="0.2355285011149646"/>
			</geometry>
		</visual>
		<collision>
			<geometry>
				<cylinder length="0.4871520967295079" radius="0.2355285011149646"/>
			</geometry>
		</collision>
		<inertial>
			<mass value="0.0848987674694995"/>
			<inertia ixx="0.03" iyy="0.03" izz="0.03" ixy="0" ixz="0" iyx="0"/>
		</inertial>
	</link>
	<link name="14">
		<visual>
			<geometry>
				<cylinder length="0.7390980158932943" radius="0.539671473785115"/>
			</geometry>
		</visual>
		<collision>
			<geometry>
				<cylinder length="0.7390980158932943" radius="0.539671473785115"/>
			</geometry>
		</collision>
		<inertial>
			<mass value="0.6762555372256879"/>
			<inertia ixx="0.03" iyy="0.03" izz="0.03" ixy="0" ixz="0" iyx="0"/>
		</inertial>
	</link>
	<link name="25">
		<visual>
			<geometry>
				<cylinder length="0.4871520967295079" radius="0.2355285011149646"/>
			</geometry>
		</visual>
		<collision>
			<geometry>
				<cylinder length="0.4871520967295079" radius="0.2355285011149646"/>
			</geometry>
		</collision>
		<inertial>
			<mass value="0.0848987674694995"/>
			<inertia ixx="0.03" iyy="0.03" izz="0.03" ixy="0" ixz="0" iyx="0"/>
		</inertial>
	</link>
	<link name="26">
		<visual>
			<geometry>
				<cylinder length="0.4871520967295079" radius="0.2355285011149646"/>
			</geometry>
		</visual>
		<collision>
			<geometry>
				<cylinder length="0.4871520967295079" radius="0.2355285011149646"/>
			</geometry>
		</collision>
		<inertial>
			<mass value="0.0848987674694995"/>
			<inertia ixx="0.03" iyy="0.03" izz="0.03" ixy="0" ixz="0" iyx="0"/>
		</inertial>
	</link>
	<link name="17">
		<visual>
			<geometry>
				<cylinder length="0.7390980158932943" radius="0.539671473785115"/>
			</geometry>
		</visual>
		<collision>
			<geometry>
				<cylinder length="0.7390980158932943" radius="0.539671473785115"/>
			</geometry>
		</collision>
		<inertial>
			<mass value="0.6762555372256879"/>
			<inertia ixx="0.03" iyy="0.03" izz="0.03" ixy="0" ixz="0" iyx="0"/>
		</inertial>
	</link>
	<link name="28">
		<visual>
			<geometry>
				<cylinder length="0.4871520967295079" radius="0.2355285011149646"/>
			</geometry>
		</visual>
		<collision>
			<geometry>
				<cylinder length="0.4871520967295079" radius="0.2355285011149646"/>
			</geometry>
		</collision>
		<inertial>
			<mass value="0.0848987674694995"/>
			<inertia ixx="0.03" iyy="0.03" izz="0.03" ixy="0" ixz="0" iyx="0"/>
		</inertial>
	</link>
	<link name="29">
		<visual>
			<geometry>
				<cylinder length="0.4871520967295079" radius="0.2355285011149646"/>
			</geometry>
		</visual>
		<collision>
			<geometry>
				<cylinder length="0.4871520967295079" radius="0.2355285011149646"/>
			</geometry>
		</collision>
		<inertial>
			<mass value="0.0848987674694995"/>
			<inertia ixx="0.03" iyy="0.03" izz="0.03" ixy="0" ixz="0" iyx="0"/>
		</inertial>
	</link>
	<link name="110">
		<visual>
			<geometry>
				<cylinder length="0.7390980158932943" radius="0.539671473785115"/>
			</geometry>
		</visual>
		<collision>
			<geometry>
				<cylinder length="0.7390980158932943" radius="0.539671473785115"/>
			</geometry>
		</collision>
		<inertial>
			<mass value="0.6762555372256879"/>
			<inertia ixx="0.03" iyy="0.03" izz="0.03" ixy="0" ixz="0" iyx="0"/>
		</inertial>
	</link>
	<link name="211">
		<visual>
			<geometry>
				<cylinder length="0.4871520967295079" radius="0.2355285011149646"/>
			</geometry>
		</visual>
		<collision>
			<geometry>
				<cylinder length="0.4871520967295079" radius="0.2355285011149646"/>
			</geometry>
		</collision>
		<inertial>
			<mass value="0.0848987674694995"/>
			<inertia ixx="0.03" iyy="0.03" izz="0.03" ixy="0" ixz="0" iyx="0"/>
		</inertial>
	</link>
	<link name="212">
		<visual>
			<geometry>
				<cylinder length="0.4871520967295079" radius="0.2355285011149646"/>
			</geometry>
		</visual>
		<collision>
			<geometry>
				<cylinder length="0.4871520967295079" radius="0.2355285011149646"/>
			</geometry>
		</collision>
		<inertial>
			<mass value="0.0848987674694995"/>
			<inertia ixx="0.03" iyy="0.03" izz="0.03" ixy="0" ixz="0" iyx="0"/>
		</inertial>
	</link>
	<joint name="11_to_0" type="revolute">
		<parent link="0"/>
		<child link="11"/>
		<axis xyz="0 0 1"/>
		<limit effort="1" upper="-3.1415" lower="3.1415" velocity="1"/>
		<origin rpy="1.1685017951966374 2.607990398758587 5.279593793770392" xyz="0.7713827438134189 0.8471844793559141 0.7733132300909366"/>
	</joint>
	<joint name="22_to_11" type="revolute">
		<parent link="11"/>
		<child link="22"/>
		<axis xyz="0 0 1"/>
		<limit effort="1" upper="-3.1415" lower="3.1415" velocity="1"/>
		<origin rpy="11.62505959161293 0.22062271482782447 5.6968441093664515" xyz="0.2185246845322868 0.7707014948884033 0.15637817477119464"/>
	</joint>
	<joint name="23_to_11" type="revolute">
		<parent link="11"/>
		<child link="23"/>
		<axis xyz="0 0 1"/>
		<limit effort="1" upper="-3.1415" lower="3.1415" velocity="1"/>
		<origin rpy="17.437589387419393 0.22062271482782447 5.6968441093664515" xyz="0.2185246845322868 0.7707014948884033 0.15637817477119464"/>
	</joint>
	<joint name="14_to_0" type="revolute">
		<parent link="0"/>
		<child link="14"/>
		<axis xyz="0 0 1"/>
		<limit effort="1" upper="-3.1415" lower="3.1415" velocity="1"/>
		<origin rpy="1.7527526927949562 2.607990398758587 5.279593793770392" xyz="0.7713827438134189 0.8471844793559141 0.7733132300909366"/>
	</joint>
	<joint name="25_to_14" type="revolute">
		<parent link="14"/>
		<child link="25"/>
		<axis xyz="0 0 1"/>
		<limit effort="1" upper="-3.1415" lower="3.1415" velocity="1"/>
		<origin rpy="11.62505959161293 0.22062271482782447 5.6968441093664515" xyz="0.2185246845322868 0.7707014948884033 0.15637817477119464"/>
	</joint>
	<joint name="26_to_14" type="revolute">
		<parent link="14"/>
		<child link="26"/>
		<axis xyz="0 0 1"/>
		<limit effort="1" upper="-3.1415" lower="3.1415" velocity="1"/>
		<origin rpy="17.437589387419393 0.22062271482782447 5.6968441093664515" xyz="0.2185246845322868 0.7707014948884033 0.15637817477119464"/>
	</joint>
	<joint name="17_to_0" type="revolute">
		<parent link="0"/>
		<child link="17"/>
		<axis xyz="0 0 1"/>
		<limit effort="1" upper="-3.1415" lower="3.1415" velocity="1"/>
		<origin rpy="2.337003590393275 2.607990398758587 5.279593793770392" xyz="0.7713827438134189 0.8471844793559141 0.7733132300909366"/>
	</joint>
	<joint name="28_to_17" type="revolute">
		<parent link="17"/>
		<child link="28"/>
		<axis xyz="0 0 1"/>
		<limit effort="1" upper="-3.1415" lower="3.1415" velocity="1"/>
		<origin rpy="11.62505959161293 0.22062271482782447 5.6968441093664515" xyz="0.2185246845322868 0.7707014948884033 0.15637817477119464"/>
	</joint>
	<joint name="29_to_17" type="revolute">
		<parent link="17"/>
		<child link="29"/>
		<axis xyz="0 0 1"/>
		<limit effort="1" upper="-3.1415" lower="3.1415" velocity="1"/>
		<origin rpy="17.437589387419393 0.22062271482782447 5.6968441093664515" xyz="0.2185246845322868 0.7707014948884033 0.15637817477119464"/>
	</joint>
	<joint name="110_to_0" type="revolute">
		<parent link="0"/>
		<child link="110"/>
		<axis xyz="0 0 1"/>
		<limit effort="1" upper="-3.1415" lower="3.1415" velocity="1"/>
		<origin rpy="2.9212544879915936 2.607990398758587 5.279593793770392" xyz="0.7713827438134189 0.8471844793559141 0.7733132300909366"/>
	</joint>
	<joint name="211_to_110" type="revolute">
		<parent link="110"/>
		<child link="211"/>
		<axis xyz="0 0 1"/>
		<limit effort="1" upper="-3.1415" lower="3.1415" velocity="1"/>
		<origin rpy="11.62505959161293 0.22062271482782447 5.6968441093664515" xyz="0.2185246845322868 0.7707014948884033 0.15637817477119464"/>
	</joint>
	<joint name="212_to_110" type="revolute">
		<parent link="110"/>
		<child link="212"/>
		<axis xyz="0 0 1"/>
		<limit effort="1" upper="-3.1415" lower="3.1415" velocity="1"/>
		<origin rpy="17.437589387419393 0.22062271482782447 5.6968441093664515" xyz="0.2185246845322868 0.7707014948884033 0.15637817477119464"/>
	</joint>
</robot>
