<robot name="pepe">
	<link name="0">
		<visual>
			<geometry>
				<cylinder length="0.3163732279676421" radius="0.2570301519389081"/>
			</geometry>
		</visual>
		<collision>
			<geometry>
				<cylinder length="0.3163732279676421" radius="0.2570301519389081"/>
			</geometry>
		</collision>
		<inertial>
			<mass value="0.0656625499606453"/>
			<inertia ixx="0.03" iyy="0.03" izz="0.03" ixy="0" ixz="0" iyx="0"/>
		</inertial>
	</link>
	<link name="11">
		<visual>
			<geometry>
				<cylinder length="0.09441289300432174" radius="0.574142248387529"/>
			</geometry>
		</visual>
		<collision>
			<geometry>
				<cylinder length="0.09441289300432174" radius="0.574142248387529"/>
			</geometry>
		</collision>
		<inertial>
			<mass value="0.09777328110326605"/>
			<inertia ixx="0.03" iyy="0.03" izz="0.03" ixy="0" ixz="0" iyx="0"/>
		</inertial>
	</link>
	<link name="22">
		<visual>
			<geometry>
				<cylinder length="0.7281569920312759" radius="0.3950859853782801"/>
			</geometry>
		</visual>
		<collision>
			<geometry>
				<cylinder length="0.7281569920312759" radius="0.3950859853782801"/>
			</geometry>
		</collision>
		<inertial>
			<mass value="0.357073931956523"/>
			<inertia ixx="0.03" iyy="0.03" izz="0.03" ixy="0" ixz="0" iyx="0"/>
		</inertial>
	</link>
	<link name="23">
		<visual>
			<geometry>
				<cylinder length="0.7281569920312759" radius="0.3950859853782801"/>
			</geometry>
		</visual>
		<collision>
			<geometry>
				<cylinder length="0.7281569920312759" radius="0.3950859853782801"/>
			</geometry>
		</collision>
		<inertial>
			<mass value="0.357073931956523"/>
			<inertia ixx="0.03" iyy="0.03" izz="0.03" ixy="0" ixz="0" iyx="0"/>
		</inertial>
	</link>
	<link name="34">
		<visual>
			<geometry>
				<cylinder length="0.11504802571435624" radius="0.5565213955545212"/>
			</geometry>
		</visual>
		<collision>
			<geometry>
				<cylinder length="0.11504802571435624" radius="0.5565213955545212"/>
			</geometry>
		</collision>
		<inertial>
			<mass value="0.11194192580395648"/>
			<inertia ixx="0.03" iyy="0.03" izz="0.03" ixy="0" ixz="0" iyx="0"/>
		</inertial>
	</link>
	<link name="35">
		<visual>
			<geometry>
				<cylinder length="0.11504802571435624" radius="0.5565213955545212"/>
			</geometry>
		</visual>
		<collision>
			<geometry>
				<cylinder length="0.11504802571435624" radius="0.5565213955545212"/>
			</geometry>
		</collision>
		<inertial>
			<mass value="0.11194192580395648"/>
			<inertia ixx="0.03" iyy="0.03" izz="0.03" ixy="0" ixz="0" iyx="0"/>
		</inertial>
	</link>
	<link name="36">
		<visual>
			<geometry>
				<cylinder length="0.11504802571435624" radius="0.5565213955545212"/>
			</geometry>
		</visual>
		<collision>
			<geometry>
				<cylinder length="0.11504802571435624" radius="0.5565213955545212"/>
			</geometry>
		</collision>
		<inertial>
			<mass value="0.11194192580395648"/>
			<inertia ixx="0.03" iyy="0.03" izz="0.03" ixy="0" ixz="0" iyx="0"/>
		</inertial>
	</link>
	<link name="37">
		<visual>
			<geometry>
				<cylinder length="0.11504802571435624" radius="0.5565213955545212"/>
			</geometry>
		</visual>
		<collision>
			<geometry>
				<cylinder length="0.11504802571435624" radius="0.5565213955545212"/>
			</geometry>
		</collision>
		<inertial>
			<mass value="0.11194192580395648"/>
			<inertia ixx="0.03" iyy="0.03" izz="0.03" ixy="0" ixz="0" iyx="0"/>
		</inertial>
	</link>
	<joint name="11_to_0" type="revolute">
		<parent link="0"/>
		<child link="11"/>
		<axis xyz="1 0 0"/>
		<limit effort="1" upper="-3.1415" lower="3.1415" velocity="1"/>
		<origin rpy="6.021208138471891 3.827880140251571 3.497393685292438" xyz="0.6952506915179402 0.8815945829934303 0.4522187053142819"/>
	</joint>
	<joint name="22_to_11" type="revolute">
		<parent link="11"/>
		<child link="22"/>
		<axis xyz="0 1 0"/>
		<limit effort="1" upper="-3.1415" lower="3.1415" velocity="1"/>
		<origin rpy="3.187399433171077 3.1556927090780684 0.22993842633188863" xyz="0.4629956474248542 0.15295891958123453 0.2787447681945542"/>
	</joint>
	<joint name="23_to_11" type="revolute">
		<parent link="11"/>
		<child link="23"/>
		<axis xyz="0 1 0"/>
		<limit effort="1" upper="-3.1415" lower="3.1415" velocity="1"/>
		<origin rpy="4.781099149756615 3.1556927090780684 0.22993842633188863" xyz="0.4629956474248542 0.15295891958123453 0.2787447681945542"/>
	</joint>
	<joint name="34_to_11" type="revolute">
		<parent link="11"/>
		<child link="34"/>
		<axis xyz="0 0 1"/>
		<limit effort="1" upper="-3.1415" lower="3.1415" velocity="1"/>
		<origin rpy="14.157449600206828 0.23021835810255625 1.9643530952785648" xyz="0.4359458141653988 0.6113559670815871 0.5889783493681191"/>
	</joint>
	<joint name="35_to_11" type="revolute">
		<parent link="11"/>
		<child link="35"/>
		<axis xyz="0 0 1"/>
		<limit effort="1" upper="-3.1415" lower="3.1415" velocity="1"/>
		<origin rpy="17.696812000258536 0.23021835810255625 1.9643530952785648" xyz="0.4359458141653988 0.6113559670815871 0.5889783493681191"/>
	</joint>
	<joint name="36_to_11" type="revolute">
		<parent link="11"/>
		<child link="36"/>
		<axis xyz="0 0 1"/>
		<limit effort="1" upper="-3.1415" lower="3.1415" velocity="1"/>
		<origin rpy="21.23617440031024 0.23021835810255625 1.9643530952785648" xyz="0.4359458141653988 0.6113559670815871 0.5889783493681191"/>
	</joint>
	<joint name="37_to_11" type="revolute">
		<parent link="11"/>
		<child link="37"/>
		<axis xyz="0 0 1"/>
		<limit effort="1" upper="-3.1415" lower="3.1415" velocity="1"/>
		<origin rpy="24.775536800361948 0.23021835810255625 1.9643530952785648" xyz="0.4359458141653988 0.6113559670815871 0.5889783493681191"/>
	</joint>
</robot>
