<robot name="pepe">
	<link name="0">
		<visual>
			<geometry>
				<cylinder length="0.7398194816812099" radius="0.052722073107775325"/>
			</geometry>
		</visual>
		<collision>
			<geometry>
				<cylinder length="0.7398194816812099" radius="0.052722073107775325"/>
			</geometry>
		</collision>
		<inertial>
			<mass value="0.0064604176374358875"/>
			<inertia ixx="0.03" iyy="0.03" izz="0.03" ixy="0" ixz="0" iyx="0"/>
		</inertial>
	</link>
	<link name="11">
		<visual>
			<geometry>
				<cylinder length="0.8079665842948784" radius="0.5435762453866043"/>
			</geometry>
		</visual>
		<collision>
			<geometry>
				<cylinder length="0.8079665842948784" radius="0.5435762453866043"/>
			</geometry>
		</collision>
		<inertial>
			<mass value="0.7500050911628182"/>
			<inertia ixx="0.03" iyy="0.03" izz="0.03" ixy="0" ixz="0" iyx="0"/>
		</inertial>
	</link>
	<link name="32">
		<visual>
			<geometry>
				<cylinder length="0.9403101071836357" radius="0.5959387925319413"/>
			</geometry>
		</visual>
		<collision>
			<geometry>
				<cylinder length="0.9403101071836357" radius="0.5959387925319413"/>
			</geometry>
		</collision>
		<inertial>
			<mass value="1.0491178838041015"/>
			<inertia ixx="0.03" iyy="0.03" izz="0.03" ixy="0" ixz="0" iyx="0"/>
		</inertial>
	</link>
	<link name="33">
		<visual>
			<geometry>
				<cylinder length="0.9403101071836357" radius="0.5959387925319413"/>
			</geometry>
		</visual>
		<collision>
			<geometry>
				<cylinder length="0.9403101071836357" radius="0.5959387925319413"/>
			</geometry>
		</collision>
		<inertial>
			<mass value="1.0491178838041015"/>
			<inertia ixx="0.03" iyy="0.03" izz="0.03" ixy="0" ixz="0" iyx="0"/>
		</inertial>
	</link>
	<link name="34">
		<visual>
			<geometry>
				<cylinder length="0.9403101071836357" radius="0.5959387925319413"/>
			</geometry>
		</visual>
		<collision>
			<geometry>
				<cylinder length="0.9403101071836357" radius="0.5959387925319413"/>
			</geometry>
		</collision>
		<inertial>
			<mass value="1.0491178838041015"/>
			<inertia ixx="0.03" iyy="0.03" izz="0.03" ixy="0" ixz="0" iyx="0"/>
		</inertial>
	</link>
	<link name="35">
		<visual>
			<geometry>
				<cylinder length="0.9403101071836357" radius="0.5959387925319413"/>
			</geometry>
		</visual>
		<collision>
			<geometry>
				<cylinder length="0.9403101071836357" radius="0.5959387925319413"/>
			</geometry>
		</collision>
		<inertial>
			<mass value="1.0491178838041015"/>
			<inertia ixx="0.03" iyy="0.03" izz="0.03" ixy="0" ixz="0" iyx="0"/>
		</inertial>
	</link>
	<link name="16">
		<visual>
			<geometry>
				<cylinder length="0.8079665842948784" radius="0.5435762453866043"/>
			</geometry>
		</visual>
		<collision>
			<geometry>
				<cylinder length="0.8079665842948784" radius="0.5435762453866043"/>
			</geometry>
		</collision>
		<inertial>
			<mass value="0.7500050911628182"/>
			<inertia ixx="0.03" iyy="0.03" izz="0.03" ixy="0" ixz="0" iyx="0"/>
		</inertial>
	</link>
	<link name="37">
		<visual>
			<geometry>
				<cylinder length="0.9403101071836357" radius="0.5959387925319413"/>
			</geometry>
		</visual>
		<collision>
			<geometry>
				<cylinder length="0.9403101071836357" radius="0.5959387925319413"/>
			</geometry>
		</collision>
		<inertial>
			<mass value="1.0491178838041015"/>
			<inertia ixx="0.03" iyy="0.03" izz="0.03" ixy="0" ixz="0" iyx="0"/>
		</inertial>
	</link>
	<link name="38">
		<visual>
			<geometry>
				<cylinder length="0.9403101071836357" radius="0.5959387925319413"/>
			</geometry>
		</visual>
		<collision>
			<geometry>
				<cylinder length="0.9403101071836357" radius="0.5959387925319413"/>
			</geometry>
		</collision>
		<inertial>
			<mass value="1.0491178838041015"/>
			<inertia ixx="0.03" iyy="0.03" izz="0.03" ixy="0" ixz="0" iyx="0"/>
		</inertial>
	</link>
	<link name="39">
		<visual>
			<geometry>
				<cylinder length="0.9403101071836357" radius="0.5959387925319413"/>
			</geometry>
		</visual>
		<collision>
			<geometry>
				<cylinder length="0.9403101071836357" radius="0.5959387925319413"/>
			</geometry>
		</collision>
		<inertial>
			<mass value="1.0491178838041015"/>
			<inertia ixx="0.03" iyy="0.03" izz="0.03" ixy="0" ixz="0" iyx="0"/>
		</inertial>
	</link>
	<link name="310">
		<visual>
			<geometry>
				<cylinder length="0.9403101071836357" radius="0.5959387925319413"/>
			</geometry>
		</visual>
		<collision>
			<geometry>
				<cylinder length="0.9403101071836357" radius="0.5959387925319413"/>
			</geometry>
		</collision>
		<inertial>
			<mass value="1.0491178838041015"/>
			<inertia ixx="0.03" iyy="0.03" izz="0.03" ixy="0" ixz="0" iyx="0"/>
		</inertial>
	</link>
	<link name="111">
		<visual>
			<geometry>
				<cylinder length="0.8079665842948784" radius="0.5435762453866043"/>
			</geometry>
		</visual>
		<collision>
			<geometry>
				<cylinder length="0.8079665842948784" radius="0.5435762453866043"/>
			</geometry>
		</collision>
		<inertial>
			<mass value="0.7500050911628182"/>
			<inertia ixx="0.03" iyy="0.03" izz="0.03" ixy="0" ixz="0" iyx="0"/>
		</inertial>
	</link>
	<link name="312">
		<visual>
			<geometry>
				<cylinder length="0.9403101071836357" radius="0.5959387925319413"/>
			</geometry>
		</visual>
		<collision>
			<geometry>
				<cylinder length="0.9403101071836357" radius="0.5959387925319413"/>
			</geometry>
		</collision>
		<inertial>
			<mass value="1.0491178838041015"/>
			<inertia ixx="0.03" iyy="0.03" izz="0.03" ixy="0" ixz="0" iyx="0"/>
		</inertial>
	</link>
	<link name="313">
		<visual>
			<geometry>
				<cylinder length="0.9403101071836357" radius="0.5959387925319413"/>
			</geometry>
		</visual>
		<collision>
			<geometry>
				<cylinder length="0.9403101071836357" radius="0.5959387925319413"/>
			</geometry>
		</collision>
		<inertial>
			<mass value="1.0491178838041015"/>
			<inertia ixx="0.03" iyy="0.03" izz="0.03" ixy="0" ixz="0" iyx="0"/>
		</inertial>
	</link>
	<link name="314">
		<visual>
			<geometry>
				<cylinder length="0.9403101071836357" radius="0.5959387925319413"/>
			</geometry>
		</visual>
		<collision>
			<geometry>
				<cylinder length="0.9403101071836357" radius="0.5959387925319413"/>
			</geometry>
		</collision>
		<inertial>
			<mass value="1.0491178838041015"/>
			<inertia ixx="0.03" iyy="0.03" izz="0.03" ixy="0" ixz="0" iyx="0"/>
		</inertial>
	</link>
	<link name="315">
		<visual>
			<geometry>
				<cylinder length="0.9403101071836357" radius="0.5959387925319413"/>
			</geometry>
		</visual>
		<collision>
			<geometry>
				<cylinder length="0.9403101071836357" radius="0.5959387925319413"/>
			</geometry>
		</collision>
		<inertial>
			<mass value="1.0491178838041015"/>
			<inertia ixx="0.03" iyy="0.03" izz="0.03" ixy="0" ixz="0" iyx="0"/>
		</inertial>
	</link>
	<link name="216">
		<visual>
			<geometry>
				<cylinder length="0.506465919751153" radius="0.6094846133177597"/>
			</geometry>
		</visual>
		<collision>
			<geometry>
				<cylinder length="0.506465919751153" radius="0.6094846133177597"/>
			</geometry>
		</collision>
		<inertial>
			<mass value="0.5910518647734716"/>
			<inertia ixx="0.03" iyy="0.03" izz="0.03" ixy="0" ixz="0" iyx="0"/>
		</inertial>
	</link>
	<link name="217">
		<visual>
			<geometry>
				<cylinder length="0.506465919751153" radius="0.6094846133177597"/>
			</geometry>
		</visual>
		<collision>
			<geometry>
				<cylinder length="0.506465919751153" radius="0.6094846133177597"/>
			</geometry>
		</collision>
		<inertial>
			<mass value="0.5910518647734716"/>
			<inertia ixx="0.03" iyy="0.03" izz="0.03" ixy="0" ixz="0" iyx="0"/>
		</inertial>
	</link>
	<joint name="11_to_0" type="revolute">
		<parent link="0"/>
		<child link="11"/>
		<axis xyz="1 0 0"/>
		<limit effort="1" upper="-3.1415" lower="3.1415" velocity="1"/>
		<origin rpy="10.623475154237155 2.8342104177696292 3.1496784475622124" xyz="0.8189271008336009 0.7563699647312384 0.9146125821125136"/>
	</joint>
	<joint name="32_to_11" type="revolute">
		<parent link="11"/>
		<child link="32"/>
		<axis xyz="1 0 0"/>
		<limit effort="1" upper="-3.1415" lower="3.1415" velocity="1"/>
		<origin rpy="10.321185455198416 2.011966357609862 0.621317373788625" xyz="0.9950286019857877 0.9393290706926078 0.7308569394321185"/>
	</joint>
	<joint name="33_to_11" type="revolute">
		<parent link="11"/>
		<child link="33"/>
		<axis xyz="1 0 0"/>
		<limit effort="1" upper="-3.1415" lower="3.1415" velocity="1"/>
		<origin rpy="15.481778182797623 2.011966357609862 0.621317373788625" xyz="0.9950286019857877 0.9393290706926078 0.7308569394321185"/>
	</joint>
	<joint name="34_to_11" type="revolute">
		<parent link="11"/>
		<child link="34"/>
		<axis xyz="1 0 0"/>
		<limit effort="1" upper="-3.1415" lower="3.1415" velocity="1"/>
		<origin rpy="20.64237091039683 2.011966357609862 0.621317373788625" xyz="0.9950286019857877 0.9393290706926078 0.7308569394321185"/>
	</joint>
	<joint name="35_to_11" type="revolute">
		<parent link="11"/>
		<child link="35"/>
		<axis xyz="1 0 0"/>
		<limit effort="1" upper="-3.1415" lower="3.1415" velocity="1"/>
		<origin rpy="25.80296363799604 2.011966357609862 0.621317373788625" xyz="0.9950286019857877 0.9393290706926078 0.7308569394321185"/>
	</joint>
	<joint name="16_to_0" type="revolute">
		<parent link="0"/>
		<child link="16"/>
		<axis xyz="1 0 0"/>
		<limit effort="1" upper="-3.1415" lower="3.1415" velocity="1"/>
		<origin rpy="15.935212731355733 2.8342104177696292 3.1496784475622124" xyz="0.8189271008336009 0.7563699647312384 0.9146125821125136"/>
	</joint>
	<joint name="37_to_16" type="revolute">
		<parent link="16"/>
		<child link="37"/>
		<axis xyz="1 0 0"/>
		<limit effort="1" upper="-3.1415" lower="3.1415" velocity="1"/>
		<origin rpy="10.321185455198416 2.011966357609862 0.621317373788625" xyz="0.9950286019857877 0.9393290706926078 0.7308569394321185"/>
	</joint>
	<joint name="38_to_16" type="revolute">
		<parent link="16"/>
		<child link="38"/>
		<axis xyz="1 0 0"/>
		<limit effort="1" upper="-3.1415" lower="3.1415" velocity="1"/>
		<origin rpy="15.481778182797623 2.011966357609862 0.621317373788625" xyz="0.9950286019857877 0.9393290706926078 0.7308569394321185"/>
	</joint>
	<joint name="39_to_16" type="revolute">
		<parent link="16"/>
		<child link="39"/>
		<axis xyz="1 0 0"/>
		<limit effort="1" upper="-3.1415" lower="3.1415" velocity="1"/>
		<origin rpy="20.64237091039683 2.011966357609862 0.621317373788625" xyz="0.9950286019857877 0.9393290706926078 0.7308569394321185"/>
	</joint>
	<joint name="310_to_16" type="revolute">
		<parent link="16"/>
		<child link="310"/>
		<axis xyz="1 0 0"/>
		<limit effort="1" upper="-3.1415" lower="3.1415" velocity="1"/>
		<origin rpy="25.80296363799604 2.011966357609862 0.621317373788625" xyz="0.9950286019857877 0.9393290706926078 0.7308569394321185"/>
	</joint>
	<joint name="111_to_0" type="revolute">
		<parent link="0"/>
		<child link="111"/>
		<axis xyz="1 0 0"/>
		<limit effort="1" upper="-3.1415" lower="3.1415" velocity="1"/>
		<origin rpy="21.24695030847431 2.8342104177696292 3.1496784475622124" xyz="0.8189271008336009 0.7563699647312384 0.9146125821125136"/>
	</joint>
	<joint name="312_to_111" type="revolute">
		<parent link="111"/>
		<child link="312"/>
		<axis xyz="1 0 0"/>
		<limit effort="1" upper="-3.1415" lower="3.1415" velocity="1"/>
		<origin rpy="10.321185455198416 2.011966357609862 0.621317373788625" xyz="0.9950286019857877 0.9393290706926078 0.7308569394321185"/>
	</joint>
	<joint name="313_to_111" type="revolute">
		<parent link="111"/>
		<child link="313"/>
		<axis xyz="1 0 0"/>
		<limit effort="1" upper="-3.1415" lower="3.1415" velocity="1"/>
		<origin rpy="15.481778182797623 2.011966357609862 0.621317373788625" xyz="0.9950286019857877 0.9393290706926078 0.7308569394321185"/>
	</joint>
	<joint name="314_to_111" type="revolute">
		<parent link="111"/>
		<child link="314"/>
		<axis xyz="1 0 0"/>
		<limit effort="1" upper="-3.1415" lower="3.1415" velocity="1"/>
		<origin rpy="20.64237091039683 2.011966357609862 0.621317373788625" xyz="0.9950286019857877 0.9393290706926078 0.7308569394321185"/>
	</joint>
	<joint name="315_to_111" type="revolute">
		<parent link="111"/>
		<child link="315"/>
		<axis xyz="1 0 0"/>
		<limit effort="1" upper="-3.1415" lower="3.1415" velocity="1"/>
		<origin rpy="25.80296363799604 2.011966357609862 0.621317373788625" xyz="0.9950286019857877 0.9393290706926078 0.7308569394321185"/>
	</joint>
	<joint name="216_to_0" type="revolute">
		<parent link="0"/>
		<child link="216"/>
		<axis xyz="0 0 1"/>
		<limit effort="1" upper="-3.1415" lower="3.1415" velocity="1"/>
		<origin rpy="8.492888449428452 0.9050096959036379 3.6076154805198013" xyz="0.026822661312480456 0.7657070746088926 0.9703833558210094"/>
	</joint>
	<joint name="217_to_0" type="revolute">
		<parent link="0"/>
		<child link="217"/>
		<axis xyz="0 0 1"/>
		<limit effort="1" upper="-3.1415" lower="3.1415" velocity="1"/>
		<origin rpy="10.191466139314144 0.9050096959036379 3.6076154805198013" xyz="0.026822661312480456 0.7657070746088926 0.9703833558210094"/>
	</joint>
</robot>
