<robot name="pepe">
	<link name="0">
		<visual>
			<geometry>
				<cylinder length="0.6893211687453101" radius="0.9622298383937432"/>
			</geometry>
		</visual>
		<collision>
			<geometry>
				<cylinder length="0.6893211687453101" radius="0.9622298383937432"/>
			</geometry>
		</collision>
		<inertial>
			<mass value="2.0050681046279117"/>
			<inertia ixx="0.03" iyy="0.03" izz="0.03" ixy="0" ixz="0" iyx="0"/>
		</inertial>
	</link>
	<link name="11">
		<visual>
			<geometry>
				<cylinder length="0.24563081295102152" radius="0.6974166398949238"/>
			</geometry>
		</visual>
		<collision>
			<geometry>
				<cylinder length="0.24563081295102152" radius="0.6974166398949238"/>
			</geometry>
		</collision>
		<inertial>
			<mass value="0.37533349993301535"/>
			<inertia ixx="0.03" iyy="0.03" izz="0.03" ixy="0" ixz="0" iyx="0"/>
		</inertial>
	</link>
	<link name="22">
		<visual>
			<geometry>
				<cylinder length="0.6782894717223117" radius="0.3318759463979437"/>
			</geometry>
		</visual>
		<collision>
			<geometry>
				<cylinder length="0.6782894717223117" radius="0.3318759463979437"/>
			</geometry>
		</collision>
		<inertial>
			<mass value="0.23470184442502104"/>
			<inertia ixx="0.03" iyy="0.03" izz="0.03" ixy="0" ixz="0" iyx="0"/>
		</inertial>
	</link>
	<link name="13">
		<visual>
			<geometry>
				<cylinder length="0.24563081295102152" radius="0.6974166398949238"/>
			</geometry>
		</visual>
		<collision>
			<geometry>
				<cylinder length="0.24563081295102152" radius="0.6974166398949238"/>
			</geometry>
		</collision>
		<inertial>
			<mass value="0.37533349993301535"/>
			<inertia ixx="0.03" iyy="0.03" izz="0.03" ixy="0" ixz="0" iyx="0"/>
		</inertial>
	</link>
	<link name="24">
		<visual>
			<geometry>
				<cylinder length="0.6782894717223117" radius="0.3318759463979437"/>
			</geometry>
		</visual>
		<collision>
			<geometry>
				<cylinder length="0.6782894717223117" radius="0.3318759463979437"/>
			</geometry>
		</collision>
		<inertial>
			<mass value="0.23470184442502104"/>
			<inertia ixx="0.03" iyy="0.03" izz="0.03" ixy="0" ixz="0" iyx="0"/>
		</inertial>
	</link>
	<joint name="11_to_0" type="revolute">
		<parent link="0"/>
		<child link="11"/>
		<axis xyz="0 0 1"/>
		<limit effort="1" upper="-3.1415" lower="3.1415" velocity="1"/>
		<origin rpy="8.442207970583514 5.289662239770561 5.720727623375437" xyz="0.3291841544527887 0.004449061513461916 0.18566610202390488"/>
	</joint>
	<joint name="22_to_11" type="revolute">
		<parent link="11"/>
		<child link="22"/>
		<axis xyz="1 0 0"/>
		<limit effort="1" upper="-3.1415" lower="3.1415" velocity="1"/>
		<origin rpy="2.5684511451391243 5.063506364403056 0.33076520107912166" xyz="0.16796472666974804 0.9934904119759171 0.16790918914819897"/>
	</joint>
	<joint name="13_to_0" type="revolute">
		<parent link="0"/>
		<child link="13"/>
		<axis xyz="0 0 1"/>
		<limit effort="1" upper="-3.1415" lower="3.1415" velocity="1"/>
		<origin rpy="12.66331195587527 5.289662239770561 5.720727623375437" xyz="0.3291841544527887 0.004449061513461916 0.18566610202390488"/>
	</joint>
	<joint name="24_to_13" type="revolute">
		<parent link="13"/>
		<child link="24"/>
		<axis xyz="1 0 0"/>
		<limit effort="1" upper="-3.1415" lower="3.1415" velocity="1"/>
		<origin rpy="2.5684511451391243 5.063506364403056 0.33076520107912166" xyz="0.16796472666974804 0.9934904119759171 0.16790918914819897"/>
	</joint>
</robot>
