<robot name="pepe">
	<link name="0">
		<visual>
			<geometry>
				<cylinder length="0.2200615809877765" radius="0.2761654064408394"/>
			</geometry>
		</visual>
		<collision>
			<geometry>
				<cylinder length="0.2200615809877765" radius="0.2761654064408394"/>
			</geometry>
		</collision>
		<inertial>
			<mass value="0.05272695044460802"/>
			<inertia ixx="0.03" iyy="0.03" izz="0.03" ixy="0" ixz="0" iyx="0"/>
		</inertial>
	</link>
	<link name="11">
		<visual>
			<geometry>
				<cylinder length="0.46262696654027" radius="0.5495511403814227"/>
			</geometry>
		</visual>
		<collision>
			<geometry>
				<cylinder length="0.46262696654027" radius="0.5495511403814227"/>
			</geometry>
		</collision>
		<inertial>
			<mass value="0.43893179769285917"/>
			<inertia ixx="0.03" iyy="0.03" izz="0.03" ixy="0" ixz="0" iyx="0"/>
		</inertial>
	</link>
	<joint name="11_to_0" type="revolute">
		<parent link="0"/>
		<child link="11"/>
		<axis xyz="0 0 1"/>
		<limit effort="1" upper="-3.1415" lower="3.1415" velocity="1"/>
		<origin rpy="4.242709261096144 6.242736811171016 1.6189296120094512" xyz="0.8317592498885846 0.6506740518234515 0.028898558806017098"/>
	</joint>
</robot>
