<robot name="pepe">
	<link name="0">
		<visual>
			<geometry>
				<cylinder length="0.2800245734313499" radius="0.8938926531964959"/>
			</geometry>
		</visual>
		<collision>
			<geometry>
				<cylinder length="0.2800245734313499" radius="0.8938926531964959"/>
			</geometry>
		</collision>
		<inertial>
			<mass value="0.7029375652139432"/>
			<inertia ixx="0.03" iyy="0.03" izz="0.03" ixy="0" ixz="0" iyx="0"/>
		</inertial>
	</link>
	<link name="11">
		<visual>
			<geometry>
				<cylinder length="0.3225041586430608" radius="0.0778627378100748"/>
			</geometry>
		</visual>
		<collision>
			<geometry>
				<cylinder length="0.3225041586430608" radius="0.0778627378100748"/>
			</geometry>
		</collision>
		<inertial>
			<mass value="0.006142491051952853"/>
			<inertia ixx="0.03" iyy="0.03" izz="0.03" ixy="0" ixz="0" iyx="0"/>
		</inertial>
	</link>
	<link name="22">
		<visual>
			<geometry>
				<cylinder length="0.3374523205437715" radius="0.9545628645783232"/>
			</geometry>
		</visual>
		<collision>
			<geometry>
				<cylinder length="0.3374523205437715" radius="0.9545628645783232"/>
			</geometry>
		</collision>
		<inertial>
			<mass value="0.9659871774671127"/>
			<inertia ixx="0.03" iyy="0.03" izz="0.03" ixy="0" ixz="0" iyx="0"/>
		</inertial>
	</link>
	<link name="13">
		<visual>
			<geometry>
				<cylinder length="0.3225041586430608" radius="0.0778627378100748"/>
			</geometry>
		</visual>
		<collision>
			<geometry>
				<cylinder length="0.3225041586430608" radius="0.0778627378100748"/>
			</geometry>
		</collision>
		<inertial>
			<mass value="0.006142491051952853"/>
			<inertia ixx="0.03" iyy="0.03" izz="0.03" ixy="0" ixz="0" iyx="0"/>
		</inertial>
	</link>
	<link name="24">
		<visual>
			<geometry>
				<cylinder length="0.3374523205437715" radius="0.9545628645783232"/>
			</geometry>
		</visual>
		<collision>
			<geometry>
				<cylinder length="0.3374523205437715" radius="0.9545628645783232"/>
			</geometry>
		</collision>
		<inertial>
			<mass value="0.9659871774671127"/>
			<inertia ixx="0.03" iyy="0.03" izz="0.03" ixy="0" ixz="0" iyx="0"/>
		</inertial>
	</link>
	<joint name="11_to_0" type="revolute">
		<parent link="0"/>
		<child link="11"/>
		<axis xyz="0 0 1"/>
		<limit effort="1" upper="-3.1415" lower="3.1415" velocity="1"/>
		<origin rpy="5.416846263661991 1.8758769314554198 5.756188190019519" xyz="0.13964936821445662 0.9467466802753118 0.5269241652254824"/>
	</joint>
	<joint name="22_to_11" type="revolute">
		<parent link="11"/>
		<child link="22"/>
		<axis xyz="0 1 0"/>
		<limit effort="1" upper="-3.1415" lower="3.1415" velocity="1"/>
		<origin rpy="4.720353367528521 4.089860697198579 5.309253897237312" xyz="0.2695820798534396 0.17447192425989322 0.616327942580527"/>
	</joint>
	<joint name="13_to_0" type="revolute">
		<parent link="0"/>
		<child link="13"/>
		<axis xyz="0 0 1"/>
		<limit effort="1" upper="-3.1415" lower="3.1415" velocity="1"/>
		<origin rpy="8.125269395492987 1.8758769314554198 5.756188190019519" xyz="0.13964936821445662 0.9467466802753118 0.5269241652254824"/>
	</joint>
	<joint name="24_to_13" type="revolute">
		<parent link="13"/>
		<child link="24"/>
		<axis xyz="0 1 0"/>
		<limit effort="1" upper="-3.1415" lower="3.1415" velocity="1"/>
		<origin rpy="4.720353367528521 4.089860697198579 5.309253897237312" xyz="0.2695820798534396 0.17447192425989322 0.616327942580527"/>
	</joint>
</robot>
