<robot name="pepe">
	<link name="0">
		<visual>
			<geometry>
				<cylinder length="0.9803151556135613" radius="0.9453462217127899"/>
			</geometry>
		</visual>
		<collision>
			<geometry>
				<cylinder length="0.9803151556135613" radius="0.9453462217127899"/>
			</geometry>
		</collision>
		<inertial>
			<mass value="2.7523101715011373"/>
			<inertia ixx="0.03" iyy="0.03" izz="0.03" ixy="0" ixz="0" iyx="0"/>
		</inertial>
	</link>
	<link name="11">
		<visual>
			<geometry>
				<cylinder length="0.5552255279039253" radius="0.2579635831597812"/>
			</geometry>
		</visual>
		<collision>
			<geometry>
				<cylinder length="0.5552255279039253" radius="0.2579635831597812"/>
			</geometry>
		</collision>
		<inertial>
			<mass value="0.1160743071039241"/>
			<inertia ixx="0.03" iyy="0.03" izz="0.03" ixy="0" ixz="0" iyx="0"/>
		</inertial>
	</link>
	<link name="22">
		<visual>
			<geometry>
				<cylinder length="0.9120764048203853" radius="0.22707052751669854"/>
			</geometry>
		</visual>
		<collision>
			<geometry>
				<cylinder length="0.9120764048203853" radius="0.22707052751669854"/>
			</geometry>
		</collision>
		<inertial>
			<mass value="0.1477415432749106"/>
			<inertia ixx="0.03" iyy="0.03" izz="0.03" ixy="0" ixz="0" iyx="0"/>
		</inertial>
	</link>
	<link name="13">
		<visual>
			<geometry>
				<cylinder length="0.5552255279039253" radius="0.2579635831597812"/>
			</geometry>
		</visual>
		<collision>
			<geometry>
				<cylinder length="0.5552255279039253" radius="0.2579635831597812"/>
			</geometry>
		</collision>
		<inertial>
			<mass value="0.1160743071039241"/>
			<inertia ixx="0.03" iyy="0.03" izz="0.03" ixy="0" ixz="0" iyx="0"/>
		</inertial>
	</link>
	<link name="24">
		<visual>
			<geometry>
				<cylinder length="0.9120764048203853" radius="0.22707052751669854"/>
			</geometry>
		</visual>
		<collision>
			<geometry>
				<cylinder length="0.9120764048203853" radius="0.22707052751669854"/>
			</geometry>
		</collision>
		<inertial>
			<mass value="0.1477415432749106"/>
			<inertia ixx="0.03" iyy="0.03" izz="0.03" ixy="0" ixz="0" iyx="0"/>
		</inertial>
	</link>
	<link name="15">
		<visual>
			<geometry>
				<cylinder length="0.5552255279039253" radius="0.2579635831597812"/>
			</geometry>
		</visual>
		<collision>
			<geometry>
				<cylinder length="0.5552255279039253" radius="0.2579635831597812"/>
			</geometry>
		</collision>
		<inertial>
			<mass value="0.1160743071039241"/>
			<inertia ixx="0.03" iyy="0.03" izz="0.03" ixy="0" ixz="0" iyx="0"/>
		</inertial>
	</link>
	<link name="26">
		<visual>
			<geometry>
				<cylinder length="0.9120764048203853" radius="0.22707052751669854"/>
			</geometry>
		</visual>
		<collision>
			<geometry>
				<cylinder length="0.9120764048203853" radius="0.22707052751669854"/>
			</geometry>
		</collision>
		<inertial>
			<mass value="0.1477415432749106"/>
			<inertia ixx="0.03" iyy="0.03" izz="0.03" ixy="0" ixz="0" iyx="0"/>
		</inertial>
	</link>
	<link name="17">
		<visual>
			<geometry>
				<cylinder length="0.5552255279039253" radius="0.2579635831597812"/>
			</geometry>
		</visual>
		<collision>
			<geometry>
				<cylinder length="0.5552255279039253" radius="0.2579635831597812"/>
			</geometry>
		</collision>
		<inertial>
			<mass value="0.1160743071039241"/>
			<inertia ixx="0.03" iyy="0.03" izz="0.03" ixy="0" ixz="0" iyx="0"/>
		</inertial>
	</link>
	<link name="28">
		<visual>
			<geometry>
				<cylinder length="0.9120764048203853" radius="0.22707052751669854"/>
			</geometry>
		</visual>
		<collision>
			<geometry>
				<cylinder length="0.9120764048203853" radius="0.22707052751669854"/>
			</geometry>
		</collision>
		<inertial>
			<mass value="0.1477415432749106"/>
			<inertia ixx="0.03" iyy="0.03" izz="0.03" ixy="0" ixz="0" iyx="0"/>
		</inertial>
	</link>
	<joint name="11_to_0" type="revolute">
		<parent link="0"/>
		<child link="11"/>
		<axis xyz="0 1 0"/>
		<limit effort="1" upper="-3.1415" lower="3.1415" velocity="1"/>
		<origin rpy="5.279768773702489 5.33341798195908 2.427282067818647" xyz="0.6272106166922962 0.21176605765536027 0.4480087464323598"/>
	</joint>
	<joint name="22_to_11" type="revolute">
		<parent link="11"/>
		<child link="22"/>
		<axis xyz="0 1 0"/>
		<limit effort="1" upper="-3.1415" lower="3.1415" velocity="1"/>
		<origin rpy="0.9792699236951871 1.6693050112776948 0.6478034950528259" xyz="0.26503680566185417 0.3846730049887397 0.5590504781442388"/>
	</joint>
	<joint name="13_to_0" type="revolute">
		<parent link="0"/>
		<child link="13"/>
		<axis xyz="0 1 0"/>
		<limit effort="1" upper="-3.1415" lower="3.1415" velocity="1"/>
		<origin rpy="7.919653160553734 5.33341798195908 2.427282067818647" xyz="0.6272106166922962 0.21176605765536027 0.4480087464323598"/>
	</joint>
	<joint name="24_to_13" type="revolute">
		<parent link="13"/>
		<child link="24"/>
		<axis xyz="0 1 0"/>
		<limit effort="1" upper="-3.1415" lower="3.1415" velocity="1"/>
		<origin rpy="0.9792699236951871 1.6693050112776948 0.6478034950528259" xyz="0.26503680566185417 0.3846730049887397 0.5590504781442388"/>
	</joint>
	<joint name="15_to_0" type="revolute">
		<parent link="0"/>
		<child link="15"/>
		<axis xyz="0 1 0"/>
		<limit effort="1" upper="-3.1415" lower="3.1415" velocity="1"/>
		<origin rpy="10.559537547404979 5.33341798195908 2.427282067818647" xyz="0.6272106166922962 0.21176605765536027 0.4480087464323598"/>
	</joint>
	<joint name="26_to_15" type="revolute">
		<parent link="15"/>
		<child link="26"/>
		<axis xyz="0 1 0"/>
		<limit effort="1" upper="-3.1415" lower="3.1415" velocity="1"/>
		<origin rpy="0.9792699236951871 1.6693050112776948 0.6478034950528259" xyz="0.26503680566185417 0.3846730049887397 0.5590504781442388"/>
	</joint>
	<joint name="17_to_0" type="revolute">
		<parent link="0"/>
		<child link="17"/>
		<axis xyz="0 1 0"/>
		<limit effort="1" upper="-3.1415" lower="3.1415" velocity="1"/>
		<origin rpy="13.199421934256224 5.33341798195908 2.427282067818647" xyz="0.6272106166922962 0.21176605765536027 0.4480087464323598"/>
	</joint>
	<joint name="28_to_17" type="revolute">
		<parent link="17"/>
		<child link="28"/>
		<axis xyz="0 1 0"/>
		<limit effort="1" upper="-3.1415" lower="3.1415" velocity="1"/>
		<origin rpy="0.9792699236951871 1.6693050112776948 0.6478034950528259" xyz="0.26503680566185417 0.3846730049887397 0.5590504781442388"/>
	</joint>
</robot>
