<robot name="pepe">
	<link name="0">
		<visual>
			<geometry>
				<cylinder length="0.7398194816812099" radius="0.052722073107775325"/>
			</geometry>
		</visual>
		<collision>
			<geometry>
				<cylinder length="0.7398194816812099" radius="0.052722073107775325"/>
			</geometry>
		</collision>
		<inertial>
			<mass value="0.0064604176374358875"/>
			<inertia ixx="0.03" iyy="0.03" izz="0.03" ixy="0" ixz="0" iyx="0"/>
		</inertial>
	</link>
	<link name="11">
		<visual>
			<geometry>
				<cylinder length="0.8079665842948784" radius="0.5435762453866043"/>
			</geometry>
		</visual>
		<collision>
			<geometry>
				<cylinder length="0.8079665842948784" radius="0.5435762453866043"/>
			</geometry>
		</collision>
		<inertial>
			<mass value="0.7500050911628182"/>
			<inertia ixx="0.03" iyy="0.03" izz="0.03" ixy="0" ixz="0" iyx="0"/>
		</inertial>
	</link>
	<link name="12">
		<visual>
			<geometry>
				<cylinder length="0.8079665842948784" radius="0.5435762453866043"/>
			</geometry>
		</visual>
		<collision>
			<geometry>
				<cylinder length="0.8079665842948784" radius="0.5435762453866043"/>
			</geometry>
		</collision>
		<inertial>
			<mass value="0.7500050911628182"/>
			<inertia ixx="0.03" iyy="0.03" izz="0.03" ixy="0" ixz="0" iyx="0"/>
		</inertial>
	</link>
	<link name="13">
		<visual>
			<geometry>
				<cylinder length="0.8079665842948784" radius="0.5435762453866043"/>
			</geometry>
		</visual>
		<collision>
			<geometry>
				<cylinder length="0.8079665842948784" radius="0.5435762453866043"/>
			</geometry>
		</collision>
		<inertial>
			<mass value="0.7500050911628182"/>
			<inertia ixx="0.03" iyy="0.03" izz="0.03" ixy="0" ixz="0" iyx="0"/>
		</inertial>
	</link>
	<link name="24">
		<visual>
			<geometry>
				<cylinder length="0.25608601985342594" radius="0.6138115436793089"/>
			</geometry>
		</visual>
		<collision>
			<geometry>
				<cylinder length="0.25608601985342594" radius="0.6138115436793089"/>
			</geometry>
		</collision>
		<inertial>
			<mass value="0.30311389586038784"/>
			<inertia ixx="0.03" iyy="0.03" izz="0.03" ixy="0" ixz="0" iyx="0"/>
		</inertial>
	</link>
	<link name="25">
		<visual>
			<geometry>
				<cylinder length="0.25608601985342594" radius="0.6138115436793089"/>
			</geometry>
		</visual>
		<collision>
			<geometry>
				<cylinder length="0.25608601985342594" radius="0.6138115436793089"/>
			</geometry>
		</collision>
		<inertial>
			<mass value="0.30311389586038784"/>
			<inertia ixx="0.03" iyy="0.03" izz="0.03" ixy="0" ixz="0" iyx="0"/>
		</inertial>
	</link>
	<link name="26">
		<visual>
			<geometry>
				<cylinder length="0.25608601985342594" radius="0.6138115436793089"/>
			</geometry>
		</visual>
		<collision>
			<geometry>
				<cylinder length="0.25608601985342594" radius="0.6138115436793089"/>
			</geometry>
		</collision>
		<inertial>
			<mass value="0.30311389586038784"/>
			<inertia ixx="0.03" iyy="0.03" izz="0.03" ixy="0" ixz="0" iyx="0"/>
		</inertial>
	</link>
	<link name="27">
		<visual>
			<geometry>
				<cylinder length="0.25608601985342594" radius="0.6138115436793089"/>
			</geometry>
		</visual>
		<collision>
			<geometry>
				<cylinder length="0.25608601985342594" radius="0.6138115436793089"/>
			</geometry>
		</collision>
		<inertial>
			<mass value="0.30311389586038784"/>
			<inertia ixx="0.03" iyy="0.03" izz="0.03" ixy="0" ixz="0" iyx="0"/>
		</inertial>
	</link>
	<link name="38">
		<visual>
			<geometry>
				<cylinder length="0.5648319820878035" radius="0.6684432004977734"/>
			</geometry>
		</visual>
		<collision>
			<geometry>
				<cylinder length="0.5648319820878035" radius="0.6684432004977734"/>
			</geometry>
		</collision>
		<inertial>
			<mass value="0.7928630377353932"/>
			<inertia ixx="0.03" iyy="0.03" izz="0.03" ixy="0" ixz="0" iyx="0"/>
		</inertial>
	</link>
	<link name="49">
		<visual>
			<geometry>
				<cylinder length="0.11300592893562522" radius="0.07228779532535293"/>
			</geometry>
		</visual>
		<collision>
			<geometry>
				<cylinder length="0.11300592893562522" radius="0.07228779532535293"/>
			</geometry>
		</collision>
		<inertial>
			<mass value="0.0018551586750009963"/>
			<inertia ixx="0.03" iyy="0.03" izz="0.03" ixy="0" ixz="0" iyx="0"/>
		</inertial>
	</link>
	<link name="410">
		<visual>
			<geometry>
				<cylinder length="0.11300592893562522" radius="0.07228779532535293"/>
			</geometry>
		</visual>
		<collision>
			<geometry>
				<cylinder length="0.11300592893562522" radius="0.07228779532535293"/>
			</geometry>
		</collision>
		<inertial>
			<mass value="0.0018551586750009963"/>
			<inertia ixx="0.03" iyy="0.03" izz="0.03" ixy="0" ixz="0" iyx="0"/>
		</inertial>
	</link>
	<link name="411">
		<visual>
			<geometry>
				<cylinder length="0.11300592893562522" radius="0.07228779532535293"/>
			</geometry>
		</visual>
		<collision>
			<geometry>
				<cylinder length="0.11300592893562522" radius="0.07228779532535293"/>
			</geometry>
		</collision>
		<inertial>
			<mass value="0.0018551586750009963"/>
			<inertia ixx="0.03" iyy="0.03" izz="0.03" ixy="0" ixz="0" iyx="0"/>
		</inertial>
	</link>
	<link name="412">
		<visual>
			<geometry>
				<cylinder length="0.11300592893562522" radius="0.07228779532535293"/>
			</geometry>
		</visual>
		<collision>
			<geometry>
				<cylinder length="0.11300592893562522" radius="0.07228779532535293"/>
			</geometry>
		</collision>
		<inertial>
			<mass value="0.0018551586750009963"/>
			<inertia ixx="0.03" iyy="0.03" izz="0.03" ixy="0" ixz="0" iyx="0"/>
		</inertial>
	</link>
	<link name="513">
		<visual>
			<geometry>
				<cylinder length="0.41249236978437687" radius="0.24948180493566863"/>
			</geometry>
		</visual>
		<collision>
			<geometry>
				<cylinder length="0.41249236978437687" radius="0.24948180493566863"/>
			</geometry>
		</collision>
		<inertial>
			<mass value="0.08065727530256071"/>
			<inertia ixx="0.03" iyy="0.03" izz="0.03" ixy="0" ixz="0" iyx="0"/>
		</inertial>
	</link>
	<link name="514">
		<visual>
			<geometry>
				<cylinder length="0.41249236978437687" radius="0.24948180493566863"/>
			</geometry>
		</visual>
		<collision>
			<geometry>
				<cylinder length="0.41249236978437687" radius="0.24948180493566863"/>
			</geometry>
		</collision>
		<inertial>
			<mass value="0.08065727530256071"/>
			<inertia ixx="0.03" iyy="0.03" izz="0.03" ixy="0" ixz="0" iyx="0"/>
		</inertial>
	</link>
	<link name="315">
		<visual>
			<geometry>
				<cylinder length="0.5648319820878035" radius="0.6684432004977734"/>
			</geometry>
		</visual>
		<collision>
			<geometry>
				<cylinder length="0.5648319820878035" radius="0.6684432004977734"/>
			</geometry>
		</collision>
		<inertial>
			<mass value="0.7928630377353932"/>
			<inertia ixx="0.03" iyy="0.03" izz="0.03" ixy="0" ixz="0" iyx="0"/>
		</inertial>
	</link>
	<link name="416">
		<visual>
			<geometry>
				<cylinder length="0.11300592893562522" radius="0.07228779532535293"/>
			</geometry>
		</visual>
		<collision>
			<geometry>
				<cylinder length="0.11300592893562522" radius="0.07228779532535293"/>
			</geometry>
		</collision>
		<inertial>
			<mass value="0.0018551586750009963"/>
			<inertia ixx="0.03" iyy="0.03" izz="0.03" ixy="0" ixz="0" iyx="0"/>
		</inertial>
	</link>
	<link name="417">
		<visual>
			<geometry>
				<cylinder length="0.11300592893562522" radius="0.07228779532535293"/>
			</geometry>
		</visual>
		<collision>
			<geometry>
				<cylinder length="0.11300592893562522" radius="0.07228779532535293"/>
			</geometry>
		</collision>
		<inertial>
			<mass value="0.0018551586750009963"/>
			<inertia ixx="0.03" iyy="0.03" izz="0.03" ixy="0" ixz="0" iyx="0"/>
		</inertial>
	</link>
	<link name="418">
		<visual>
			<geometry>
				<cylinder length="0.11300592893562522" radius="0.07228779532535293"/>
			</geometry>
		</visual>
		<collision>
			<geometry>
				<cylinder length="0.11300592893562522" radius="0.07228779532535293"/>
			</geometry>
		</collision>
		<inertial>
			<mass value="0.0018551586750009963"/>
			<inertia ixx="0.03" iyy="0.03" izz="0.03" ixy="0" ixz="0" iyx="0"/>
		</inertial>
	</link>
	<link name="419">
		<visual>
			<geometry>
				<cylinder length="0.11300592893562522" radius="0.07228779532535293"/>
			</geometry>
		</visual>
		<collision>
			<geometry>
				<cylinder length="0.11300592893562522" radius="0.07228779532535293"/>
			</geometry>
		</collision>
		<inertial>
			<mass value="0.0018551586750009963"/>
			<inertia ixx="0.03" iyy="0.03" izz="0.03" ixy="0" ixz="0" iyx="0"/>
		</inertial>
	</link>
	<link name="520">
		<visual>
			<geometry>
				<cylinder length="0.41249236978437687" radius="0.24948180493566863"/>
			</geometry>
		</visual>
		<collision>
			<geometry>
				<cylinder length="0.41249236978437687" radius="0.24948180493566863"/>
			</geometry>
		</collision>
		<inertial>
			<mass value="0.08065727530256071"/>
			<inertia ixx="0.03" iyy="0.03" izz="0.03" ixy="0" ixz="0" iyx="0"/>
		</inertial>
	</link>
	<link name="521">
		<visual>
			<geometry>
				<cylinder length="0.41249236978437687" radius="0.24948180493566863"/>
			</geometry>
		</visual>
		<collision>
			<geometry>
				<cylinder length="0.41249236978437687" radius="0.24948180493566863"/>
			</geometry>
		</collision>
		<inertial>
			<mass value="0.08065727530256071"/>
			<inertia ixx="0.03" iyy="0.03" izz="0.03" ixy="0" ixz="0" iyx="0"/>
		</inertial>
	</link>
	<link name="322">
		<visual>
			<geometry>
				<cylinder length="0.5648319820878035" radius="0.6684432004977734"/>
			</geometry>
		</visual>
		<collision>
			<geometry>
				<cylinder length="0.5648319820878035" radius="0.6684432004977734"/>
			</geometry>
		</collision>
		<inertial>
			<mass value="0.7928630377353932"/>
			<inertia ixx="0.03" iyy="0.03" izz="0.03" ixy="0" ixz="0" iyx="0"/>
		</inertial>
	</link>
	<link name="423">
		<visual>
			<geometry>
				<cylinder length="0.11300592893562522" radius="0.07228779532535293"/>
			</geometry>
		</visual>
		<collision>
			<geometry>
				<cylinder length="0.11300592893562522" radius="0.07228779532535293"/>
			</geometry>
		</collision>
		<inertial>
			<mass value="0.0018551586750009963"/>
			<inertia ixx="0.03" iyy="0.03" izz="0.03" ixy="0" ixz="0" iyx="0"/>
		</inertial>
	</link>
	<link name="424">
		<visual>
			<geometry>
				<cylinder length="0.11300592893562522" radius="0.07228779532535293"/>
			</geometry>
		</visual>
		<collision>
			<geometry>
				<cylinder length="0.11300592893562522" radius="0.07228779532535293"/>
			</geometry>
		</collision>
		<inertial>
			<mass value="0.0018551586750009963"/>
			<inertia ixx="0.03" iyy="0.03" izz="0.03" ixy="0" ixz="0" iyx="0"/>
		</inertial>
	</link>
	<link name="425">
		<visual>
			<geometry>
				<cylinder length="0.11300592893562522" radius="0.07228779532535293"/>
			</geometry>
		</visual>
		<collision>
			<geometry>
				<cylinder length="0.11300592893562522" radius="0.07228779532535293"/>
			</geometry>
		</collision>
		<inertial>
			<mass value="0.0018551586750009963"/>
			<inertia ixx="0.03" iyy="0.03" izz="0.03" ixy="0" ixz="0" iyx="0"/>
		</inertial>
	</link>
	<link name="426">
		<visual>
			<geometry>
				<cylinder length="0.11300592893562522" radius="0.07228779532535293"/>
			</geometry>
		</visual>
		<collision>
			<geometry>
				<cylinder length="0.11300592893562522" radius="0.07228779532535293"/>
			</geometry>
		</collision>
		<inertial>
			<mass value="0.0018551586750009963"/>
			<inertia ixx="0.03" iyy="0.03" izz="0.03" ixy="0" ixz="0" iyx="0"/>
		</inertial>
	</link>
	<link name="527">
		<visual>
			<geometry>
				<cylinder length="0.41249236978437687" radius="0.24948180493566863"/>
			</geometry>
		</visual>
		<collision>
			<geometry>
				<cylinder length="0.41249236978437687" radius="0.24948180493566863"/>
			</geometry>
		</collision>
		<inertial>
			<mass value="0.08065727530256071"/>
			<inertia ixx="0.03" iyy="0.03" izz="0.03" ixy="0" ixz="0" iyx="0"/>
		</inertial>
	</link>
	<link name="528">
		<visual>
			<geometry>
				<cylinder length="0.41249236978437687" radius="0.24948180493566863"/>
			</geometry>
		</visual>
		<collision>
			<geometry>
				<cylinder length="0.41249236978437687" radius="0.24948180493566863"/>
			</geometry>
		</collision>
		<inertial>
			<mass value="0.08065727530256071"/>
			<inertia ixx="0.03" iyy="0.03" izz="0.03" ixy="0" ixz="0" iyx="0"/>
		</inertial>
	</link>
	<joint name="11_to_0" type="revolute">
		<parent link="0"/>
		<child link="11"/>
		<axis xyz="1 0 0"/>
		<limit effort="1" upper="-3.1415" lower="3.1415" velocity="1"/>
		<origin rpy="10.623475154237155 2.8342104177696292 3.1496784475622124" xyz="0.8189271008336009 0.7563699647312384 0.9146125821125136"/>
	</joint>
	<joint name="12_to_0" type="revolute">
		<parent link="0"/>
		<child link="12"/>
		<axis xyz="1 0 0"/>
		<limit effort="1" upper="-3.1415" lower="3.1415" velocity="1"/>
		<origin rpy="15.935212731355733 2.8342104177696292 3.1496784475622124" xyz="0.8189271008336009 0.7563699647312384 0.9146125821125136"/>
	</joint>
	<joint name="13_to_0" type="revolute">
		<parent link="0"/>
		<child link="13"/>
		<axis xyz="1 0 0"/>
		<limit effort="1" upper="-3.1415" lower="3.1415" velocity="1"/>
		<origin rpy="21.24695030847431 2.8342104177696292 3.1496784475622124" xyz="0.8189271008336009 0.7563699647312384 0.9146125821125136"/>
	</joint>
	<joint name="24_to_0" type="revolute">
		<parent link="0"/>
		<child link="24"/>
		<axis xyz="0 0 1"/>
		<limit effort="1" upper="-3.1415" lower="3.1415" velocity="1"/>
		<origin rpy="3.6096130912238684 4.593741357315073 2.920237593251638" xyz="0.4792750306320812 0.847968414659369 0.6114083677445136"/>
	</joint>
	<joint name="25_to_0" type="revolute">
		<parent link="0"/>
		<child link="25"/>
		<axis xyz="0 0 1"/>
		<limit effort="1" upper="-3.1415" lower="3.1415" velocity="1"/>
		<origin rpy="4.331535709468642 4.593741357315073 2.920237593251638" xyz="0.4792750306320812 0.847968414659369 0.6114083677445136"/>
	</joint>
	<joint name="26_to_0" type="revolute">
		<parent link="0"/>
		<child link="26"/>
		<axis xyz="0 0 1"/>
		<limit effort="1" upper="-3.1415" lower="3.1415" velocity="1"/>
		<origin rpy="5.0534583277134155 4.593741357315073 2.920237593251638" xyz="0.4792750306320812 0.847968414659369 0.6114083677445136"/>
	</joint>
	<joint name="27_to_0" type="revolute">
		<parent link="0"/>
		<child link="27"/>
		<axis xyz="0 0 1"/>
		<limit effort="1" upper="-3.1415" lower="3.1415" velocity="1"/>
		<origin rpy="5.775380945958189 4.593741357315073 2.920237593251638" xyz="0.4792750306320812 0.847968414659369 0.6114083677445136"/>
	</joint>
	<joint name="38_to_0" type="revolute">
		<parent link="0"/>
		<child link="38"/>
		<axis xyz="1 0 0"/>
		<limit effort="1" upper="-3.1415" lower="3.1415" velocity="1"/>
		<origin rpy="25.190829237579877 4.374845030959743 4.138503952253977" xyz="0.3118866016961451 0.5823182734858764 0.3863162482295788"/>
	</joint>
	<joint name="49_to_38" type="revolute">
		<parent link="38"/>
		<child link="49"/>
		<axis xyz="1 0 0"/>
		<limit effort="1" upper="-3.1415" lower="3.1415" velocity="1"/>
		<origin rpy="8.924823628119341 1.560239935475121 5.488178981069835" xyz="0.8315829132698226 0.45835141060981477 0.38774351315058364"/>
	</joint>
	<joint name="410_to_38" type="revolute">
		<parent link="38"/>
		<child link="410"/>
		<axis xyz="1 0 0"/>
		<limit effort="1" upper="-3.1415" lower="3.1415" velocity="1"/>
		<origin rpy="13.387235442179012 1.560239935475121 5.488178981069835" xyz="0.8315829132698226 0.45835141060981477 0.38774351315058364"/>
	</joint>
	<joint name="411_to_38" type="revolute">
		<parent link="38"/>
		<child link="411"/>
		<axis xyz="1 0 0"/>
		<limit effort="1" upper="-3.1415" lower="3.1415" velocity="1"/>
		<origin rpy="17.849647256238683 1.560239935475121 5.488178981069835" xyz="0.8315829132698226 0.45835141060981477 0.38774351315058364"/>
	</joint>
	<joint name="412_to_38" type="revolute">
		<parent link="38"/>
		<child link="412"/>
		<axis xyz="1 0 0"/>
		<limit effort="1" upper="-3.1415" lower="3.1415" velocity="1"/>
		<origin rpy="22.312059070298353 1.560239935475121 5.488178981069835" xyz="0.8315829132698226 0.45835141060981477 0.38774351315058364"/>
	</joint>
	<joint name="513_to_38" type="revolute">
		<parent link="38"/>
		<child link="513"/>
		<axis xyz="0 0 1"/>
		<limit effort="1" upper="-3.1415" lower="3.1415" velocity="1"/>
		<origin rpy="1.212471714388968 4.3268445074729645 1.8450168743867772" xyz="0.3932373811047234 0.4337965548036756 0.9168223392760185"/>
	</joint>
	<joint name="514_to_38" type="revolute">
		<parent link="38"/>
		<child link="514"/>
		<axis xyz="0 0 1"/>
		<limit effort="1" upper="-3.1415" lower="3.1415" velocity="1"/>
		<origin rpy="1.414550333453796 4.3268445074729645 1.8450168743867772" xyz="0.3932373811047234 0.4337965548036756 0.9168223392760185"/>
	</joint>
	<joint name="315_to_0" type="revolute">
		<parent link="0"/>
		<child link="315"/>
		<axis xyz="1 0 0"/>
		<limit effort="1" upper="-3.1415" lower="3.1415" velocity="1"/>
		<origin rpy="27.98981026397764 4.374845030959743 4.138503952253977" xyz="0.3118866016961451 0.5823182734858764 0.3863162482295788"/>
	</joint>
	<joint name="416_to_315" type="revolute">
		<parent link="315"/>
		<child link="416"/>
		<axis xyz="1 0 0"/>
		<limit effort="1" upper="-3.1415" lower="3.1415" velocity="1"/>
		<origin rpy="8.924823628119341 1.560239935475121 5.488178981069835" xyz="0.8315829132698226 0.45835141060981477 0.38774351315058364"/>
	</joint>
	<joint name="417_to_315" type="revolute">
		<parent link="315"/>
		<child link="417"/>
		<axis xyz="1 0 0"/>
		<limit effort="1" upper="-3.1415" lower="3.1415" velocity="1"/>
		<origin rpy="13.387235442179012 1.560239935475121 5.488178981069835" xyz="0.8315829132698226 0.45835141060981477 0.38774351315058364"/>
	</joint>
	<joint name="418_to_315" type="revolute">
		<parent link="315"/>
		<child link="418"/>
		<axis xyz="1 0 0"/>
		<limit effort="1" upper="-3.1415" lower="3.1415" velocity="1"/>
		<origin rpy="17.849647256238683 1.560239935475121 5.488178981069835" xyz="0.8315829132698226 0.45835141060981477 0.38774351315058364"/>
	</joint>
	<joint name="419_to_315" type="revolute">
		<parent link="315"/>
		<child link="419"/>
		<axis xyz="1 0 0"/>
		<limit effort="1" upper="-3.1415" lower="3.1415" velocity="1"/>
		<origin rpy="22.312059070298353 1.560239935475121 5.488178981069835" xyz="0.8315829132698226 0.45835141060981477 0.38774351315058364"/>
	</joint>
	<joint name="520_to_315" type="revolute">
		<parent link="315"/>
		<child link="520"/>
		<axis xyz="0 0 1"/>
		<limit effort="1" upper="-3.1415" lower="3.1415" velocity="1"/>
		<origin rpy="1.212471714388968 4.3268445074729645 1.8450168743867772" xyz="0.3932373811047234 0.4337965548036756 0.9168223392760185"/>
	</joint>
	<joint name="521_to_315" type="revolute">
		<parent link="315"/>
		<child link="521"/>
		<axis xyz="0 0 1"/>
		<limit effort="1" upper="-3.1415" lower="3.1415" velocity="1"/>
		<origin rpy="1.414550333453796 4.3268445074729645 1.8450168743867772" xyz="0.3932373811047234 0.4337965548036756 0.9168223392760185"/>
	</joint>
	<joint name="322_to_0" type="revolute">
		<parent link="0"/>
		<child link="322"/>
		<axis xyz="1 0 0"/>
		<limit effort="1" upper="-3.1415" lower="3.1415" velocity="1"/>
		<origin rpy="30.788791290375404 4.374845030959743 4.138503952253977" xyz="0.3118866016961451 0.5823182734858764 0.3863162482295788"/>
	</joint>
	<joint name="423_to_322" type="revolute">
		<parent link="322"/>
		<child link="423"/>
		<axis xyz="1 0 0"/>
		<limit effort="1" upper="-3.1415" lower="3.1415" velocity="1"/>
		<origin rpy="8.924823628119341 1.560239935475121 5.488178981069835" xyz="0.8315829132698226 0.45835141060981477 0.38774351315058364"/>
	</joint>
	<joint name="424_to_322" type="revolute">
		<parent link="322"/>
		<child link="424"/>
		<axis xyz="1 0 0"/>
		<limit effort="1" upper="-3.1415" lower="3.1415" velocity="1"/>
		<origin rpy="13.387235442179012 1.560239935475121 5.488178981069835" xyz="0.8315829132698226 0.45835141060981477 0.38774351315058364"/>
	</joint>
	<joint name="425_to_322" type="revolute">
		<parent link="322"/>
		<child link="425"/>
		<axis xyz="1 0 0"/>
		<limit effort="1" upper="-3.1415" lower="3.1415" velocity="1"/>
		<origin rpy="17.849647256238683 1.560239935475121 5.488178981069835" xyz="0.8315829132698226 0.45835141060981477 0.38774351315058364"/>
	</joint>
	<joint name="426_to_322" type="revolute">
		<parent link="322"/>
		<child link="426"/>
		<axis xyz="1 0 0"/>
		<limit effort="1" upper="-3.1415" lower="3.1415" velocity="1"/>
		<origin rpy="22.312059070298353 1.560239935475121 5.488178981069835" xyz="0.8315829132698226 0.45835141060981477 0.38774351315058364"/>
	</joint>
	<joint name="527_to_322" type="revolute">
		<parent link="322"/>
		<child link="527"/>
		<axis xyz="0 0 1"/>
		<limit effort="1" upper="-3.1415" lower="3.1415" velocity="1"/>
		<origin rpy="1.212471714388968 4.3268445074729645 1.8450168743867772" xyz="0.3932373811047234 0.4337965548036756 0.9168223392760185"/>
	</joint>
	<joint name="528_to_322" type="revolute">
		<parent link="322"/>
		<child link="528"/>
		<axis xyz="0 0 1"/>
		<limit effort="1" upper="-3.1415" lower="3.1415" velocity="1"/>
		<origin rpy="1.414550333453796 4.3268445074729645 1.8450168743867772" xyz="0.3932373811047234 0.4337965548036756 0.9168223392760185"/>
	</joint>
</robot>
