<robot name="pepe">
	<link name="0">
		<visual>
			<geometry>
				<cylinder length="0.019972807067224967" radius="0.002011686301548709"/>
			</geometry>
		</visual>
		<collision>
			<geometry>
				<cylinder length="0.019972807067224967" radius="0.002011686301548709"/>
			</geometry>
		</collision>
		<inertial>
			<mass value="2.5392735959833216e-07"/>
			<inertia ixx="0.03" iyy="0.03" izz="0.03" ixy="0" ixz="0" iyx="0"/>
		</inertial>
	</link>
	<link name="11">
		<visual>
			<geometry>
				<cylinder length="0.00018669200855736634" radius="0.6433571912630214"/>
			</geometry>
		</visual>
		<collision>
			<geometry>
				<cylinder length="0.00018669200855736634" radius="0.6433571912630214"/>
			</geometry>
		</collision>
		<inertial>
			<mass value="0.00024276156039558443"/>
			<inertia ixx="0.03" iyy="0.03" izz="0.03" ixy="0" ixz="0" iyx="0"/>
		</inertial>
	</link>
	<link name="22">
		<visual>
			<geometry>
				<cylinder length="0.5825346973094198" radius="0.1344101030337398"/>
			</geometry>
		</visual>
		<collision>
			<geometry>
				<cylinder length="0.5825346973094198" radius="0.1344101030337398"/>
			</geometry>
		</collision>
		<inertial>
			<mass value="0.03306248549946934"/>
			<inertia ixx="0.03" iyy="0.03" izz="0.03" ixy="0" ixz="0" iyx="0"/>
		</inertial>
	</link>
	<link name="53">
		<visual>
			<geometry>
				<cylinder length="0.32991061629635154" radius="0.659888503144035"/>
			</geometry>
		</visual>
		<collision>
			<geometry>
				<cylinder length="0.32991061629635154" radius="0.659888503144035"/>
			</geometry>
		</collision>
		<inertial>
			<mass value="0.45132281440264777"/>
			<inertia ixx="0.03" iyy="0.03" izz="0.03" ixy="0" ixz="0" iyx="0"/>
		</inertial>
	</link>
	<link name="34">
		<visual>
			<geometry>
				<cylinder length="0.6767822617877952" radius="0.8325034157491421"/>
			</geometry>
		</visual>
		<collision>
			<geometry>
				<cylinder length="0.6767822617877952" radius="0.8325034157491421"/>
			</geometry>
		</collision>
		<inertial>
			<mass value="1.473570397274502"/>
			<inertia ixx="0.03" iyy="0.03" izz="0.03" ixy="0" ixz="0" iyx="0"/>
		</inertial>
	</link>
	<link name="45">
		<visual>
			<geometry>
				<cylinder length="0.358516004105492" radius="0.6289221186312428"/>
			</geometry>
		</visual>
		<collision>
			<geometry>
				<cylinder length="0.358516004105492" radius="0.6289221186312428"/>
			</geometry>
		</collision>
		<inertial>
			<mass value="0.4455045639168888"/>
			<inertia ixx="0.03" iyy="0.03" izz="0.03" ixy="0" ixz="0" iyx="0"/>
		</inertial>
	</link>
	<link name="66">
		<visual>
			<geometry>
				<cylinder length="0.00153756204312816" radius="0.02708229181987041"/>
			</geometry>
		</visual>
		<collision>
			<geometry>
				<cylinder length="0.00153756204312816" radius="0.02708229181987041"/>
			</geometry>
		</collision>
		<inertial>
			<mass value="3.5428547611058314e-06"/>
			<inertia ixx="0.03" iyy="0.03" izz="0.03" ixy="0" ixz="0" iyx="0"/>
		</inertial>
	</link>
	<link name="67">
		<visual>
			<geometry>
				<cylinder length="0.00153756204312816" radius="0.02708229181987041"/>
			</geometry>
		</visual>
		<collision>
			<geometry>
				<cylinder length="0.00153756204312816" radius="0.02708229181987041"/>
			</geometry>
		</collision>
		<inertial>
			<mass value="3.5428547611058314e-06"/>
			<inertia ixx="0.03" iyy="0.03" izz="0.03" ixy="0" ixz="0" iyx="0"/>
		</inertial>
	</link>
	<link name="78">
		<visual>
			<geometry>
				<cylinder length="0.38568033073831387" radius="0.14498309565483913"/>
			</geometry>
		</visual>
		<collision>
			<geometry>
				<cylinder length="0.38568033073831387" radius="0.14498309565483913"/>
			</geometry>
		</collision>
		<inertial>
			<mass value="0.02546901215002619"/>
			<inertia ixx="0.03" iyy="0.03" izz="0.03" ixy="0" ixz="0" iyx="0"/>
		</inertial>
	</link>
	<joint name="11_to_0" type="revolute">
		<parent link="0"/>
		<child link="11"/>
		<axis xyz="0 0 1"/>
		<limit effort="1" upper="-3.1415" lower="3.1415" velocity="1"/>
		<origin rpy="4.599220098856529 3.612390086619138 0.046742745195824255" xyz="0.6270726565351545 0.45386870664634127 0.9934344682645572"/>
	</joint>
	<joint name="22_to_11" type="revolute">
		<parent link="11"/>
		<child link="22"/>
		<axis xyz="1 0 0"/>
		<limit effort="1" upper="-3.1415" lower="3.1415" velocity="1"/>
		<origin rpy="11.626505171087503 5.516802298202429 0.7791319437868018" xyz="0.0019279200350848108 0.0005248485264476697 0.18877120123119884"/>
	</joint>
	<joint name="53_to_22" type="revolute">
		<parent link="22"/>
		<child link="53"/>
		<axis xyz="0 0 1"/>
		<limit effort="1" upper="-3.1415" lower="3.1415" velocity="1"/>
		<origin rpy="0.10051264616390823 1.3953726500600625 3.620509695951334" xyz="0.6345348520150791 0.6369416216841768 0.23249578398044024"/>
	</joint>
	<joint name="34_to_11" type="revolute">
		<parent link="11"/>
		<child link="34"/>
		<axis xyz="0 1 0"/>
		<limit effort="1" upper="-3.1415" lower="3.1415" velocity="1"/>
		<origin rpy="15.855197879314145 4.22851677776207 0.5600087386388388" xyz="0.807546668794237 0.9347432046170919 0.26792392211434435"/>
	</joint>
	<joint name="45_to_34" type="revolute">
		<parent link="34"/>
		<child link="45"/>
		<axis xyz="0 1 0"/>
		<limit effort="1" upper="-3.1415" lower="3.1415" velocity="1"/>
		<origin rpy="6.785089119530647 2.3121756090544063 4.853502502754321" xyz="0.7134389939078161 0.9788641507588274 0.06884801253084266"/>
	</joint>
	<joint name="66_to_11" type="revolute">
		<parent link="11"/>
		<child link="66"/>
		<axis xyz="0 0 1"/>
		<limit effort="1" upper="-3.1415" lower="3.1415" velocity="1"/>
		<origin rpy="8.017034822677475 0.49041554351940575 3.3105613913002006" xyz="0.7252082934959747 0.33647244760358364 0.807868748932156"/>
	</joint>
	<joint name="67_to_11" type="revolute">
		<parent link="11"/>
		<child link="67"/>
		<axis xyz="0 0 1"/>
		<limit effort="1" upper="-3.1415" lower="3.1415" velocity="1"/>
		<origin rpy="10.021293528346844 0.49041554351940575 3.3105613913002006" xyz="0.7252082934959747 0.33647244760358364 0.807868748932156"/>
	</joint>
	<joint name="78_to_0" type="revolute">
		<parent link="0"/>
		<child link="78"/>
		<axis xyz="1 0 0"/>
		<limit effort="1" upper="-3.1415" lower="3.1415" velocity="1"/>
		<origin rpy="1.1154521210637325 5.645245554031331 0.3804203609110539" xyz="0.9868216203458197 0.9527891737852079 0.1514539156005167"/>
	</joint>
</robot>
