<robot name="pepe">
	<link name="0">
		<visual>
			<geometry>
				<cylinder length="0.8592440908158552" radius="0.8410109571107248"/>
			</geometry>
		</visual>
		<collision>
			<geometry>
				<cylinder length="0.8592440908158552" radius="0.8410109571107248"/>
			</geometry>
		</collision>
		<inertial>
			<mass value="1.9092804905754177"/>
			<inertia ixx="0.03" iyy="0.03" izz="0.03" ixy="0" ixz="0" iyx="0"/>
		</inertial>
	</link>
	<link name="11">
		<visual>
			<geometry>
				<cylinder length="0.931342287061448" radius="0.029604239777924146"/>
			</geometry>
		</visual>
		<collision>
			<geometry>
				<cylinder length="0.931342287061448" radius="0.029604239777924146"/>
			</geometry>
		</collision>
		<inertial>
			<mass value="0.0025642893058701504"/>
			<inertia ixx="0.03" iyy="0.03" izz="0.03" ixy="0" ixz="0" iyx="0"/>
		</inertial>
	</link>
	<link name="12">
		<visual>
			<geometry>
				<cylinder length="0.931342287061448" radius="0.029604239777924146"/>
			</geometry>
		</visual>
		<collision>
			<geometry>
				<cylinder length="0.931342287061448" radius="0.029604239777924146"/>
			</geometry>
		</collision>
		<inertial>
			<mass value="0.0025642893058701504"/>
			<inertia ixx="0.03" iyy="0.03" izz="0.03" ixy="0" ixz="0" iyx="0"/>
		</inertial>
	</link>
	<link name="23">
		<visual>
			<geometry>
				<cylinder length="0.3762620677441708" radius="0.1789246460986148"/>
			</geometry>
		</visual>
		<collision>
			<geometry>
				<cylinder length="0.3762620677441708" radius="0.1789246460986148"/>
			</geometry>
		</collision>
		<inertial>
			<mass value="0.03784257185920819"/>
			<inertia ixx="0.03" iyy="0.03" izz="0.03" ixy="0" ixz="0" iyx="0"/>
		</inertial>
	</link>
	<link name="24">
		<visual>
			<geometry>
				<cylinder length="0.3762620677441708" radius="0.1789246460986148"/>
			</geometry>
		</visual>
		<collision>
			<geometry>
				<cylinder length="0.3762620677441708" radius="0.1789246460986148"/>
			</geometry>
		</collision>
		<inertial>
			<mass value="0.03784257185920819"/>
			<inertia ixx="0.03" iyy="0.03" izz="0.03" ixy="0" ixz="0" iyx="0"/>
		</inertial>
	</link>
	<link name="25">
		<visual>
			<geometry>
				<cylinder length="0.3762620677441708" radius="0.1789246460986148"/>
			</geometry>
		</visual>
		<collision>
			<geometry>
				<cylinder length="0.3762620677441708" radius="0.1789246460986148"/>
			</geometry>
		</collision>
		<inertial>
			<mass value="0.03784257185920819"/>
			<inertia ixx="0.03" iyy="0.03" izz="0.03" ixy="0" ixz="0" iyx="0"/>
		</inertial>
	</link>
	<joint name="11_to_0" type="revolute">
		<parent link="0"/>
		<child link="11"/>
		<axis xyz="0 0 1"/>
		<limit effort="1" upper="-3.1415" lower="3.1415" velocity="1"/>
		<origin rpy="6.18035866737744 3.4702977233726573 0.3258792651083962" xyz="0.17689580424762807 0.44069609796301823 0.7589384082652485"/>
	</joint>
	<joint name="12_to_0" type="revolute">
		<parent link="0"/>
		<child link="12"/>
		<axis xyz="0 0 1"/>
		<limit effort="1" upper="-3.1415" lower="3.1415" velocity="1"/>
		<origin rpy="9.27053800106616 3.4702977233726573 0.3258792651083962" xyz="0.17689580424762807 0.44069609796301823 0.7589384082652485"/>
	</joint>
	<joint name="23_to_0" type="revolute">
		<parent link="0"/>
		<child link="23"/>
		<axis xyz="0 0 1"/>
		<limit effort="1" upper="-3.1415" lower="3.1415" velocity="1"/>
		<origin rpy="10.11349457794136 5.402199333057146 1.9591320375952974" xyz="0.4994598277855792 0.3916007418430635 0.15798073054839057"/>
	</joint>
	<joint name="24_to_0" type="revolute">
		<parent link="0"/>
		<child link="24"/>
		<axis xyz="0 0 1"/>
		<limit effort="1" upper="-3.1415" lower="3.1415" velocity="1"/>
		<origin rpy="12.6418682224267 5.402199333057146 1.9591320375952974" xyz="0.4994598277855792 0.3916007418430635 0.15798073054839057"/>
	</joint>
	<joint name="25_to_0" type="revolute">
		<parent link="0"/>
		<child link="25"/>
		<axis xyz="0 0 1"/>
		<limit effort="1" upper="-3.1415" lower="3.1415" velocity="1"/>
		<origin rpy="15.17024186691204 5.402199333057146 1.9591320375952974" xyz="0.4994598277855792 0.3916007418430635 0.15798073054839057"/>
	</joint>
</robot>
