<robot name="pepe">
	<link name="0">
		<visual>
			<geometry>
				<cylinder length="0.016136948851283806" radius="0.3460895240892162"/>
			</geometry>
		</visual>
		<collision>
			<geometry>
				<cylinder length="0.016136948851283806" radius="0.3460895240892162"/>
			</geometry>
		</collision>
		<inertial>
			<mass value="0.0060722298511448605"/>
			<inertia ixx="0.03" iyy="0.03" izz="0.03" ixy="0" ixz="0" iyx="0"/>
		</inertial>
	</link>
	<link name="11">
		<visual>
			<geometry>
				<cylinder length="0.18959202448349888" radius="0.7669901686478788"/>
			</geometry>
		</visual>
		<collision>
			<geometry>
				<cylinder length="0.18959202448349888" radius="0.7669901686478788"/>
			</geometry>
		</collision>
		<inertial>
			<mass value="0.3503882476091541"/>
			<inertia ixx="0.03" iyy="0.03" izz="0.03" ixy="0" ixz="0" iyx="0"/>
		</inertial>
	</link>
	<link name="12">
		<visual>
			<geometry>
				<cylinder length="0.18959202448349888" radius="0.7669901686478788"/>
			</geometry>
		</visual>
		<collision>
			<geometry>
				<cylinder length="0.18959202448349888" radius="0.7669901686478788"/>
			</geometry>
		</collision>
		<inertial>
			<mass value="0.3503882476091541"/>
			<inertia ixx="0.03" iyy="0.03" izz="0.03" ixy="0" ixz="0" iyx="0"/>
		</inertial>
	</link>
	<link name="23">
		<visual>
			<geometry>
				<cylinder length="0.3820965905006577" radius="0.08797632819885409"/>
			</geometry>
		</visual>
		<collision>
			<geometry>
				<cylinder length="0.3820965905006577" radius="0.08797632819885409"/>
			</geometry>
		</collision>
		<inertial>
			<mass value="0.009290833977696132"/>
			<inertia ixx="0.03" iyy="0.03" izz="0.03" ixy="0" ixz="0" iyx="0"/>
		</inertial>
	</link>
	<link name="24">
		<visual>
			<geometry>
				<cylinder length="0.3820965905006577" radius="0.08797632819885409"/>
			</geometry>
		</visual>
		<collision>
			<geometry>
				<cylinder length="0.3820965905006577" radius="0.08797632819885409"/>
			</geometry>
		</collision>
		<inertial>
			<mass value="0.009290833977696132"/>
			<inertia ixx="0.03" iyy="0.03" izz="0.03" ixy="0" ixz="0" iyx="0"/>
		</inertial>
	</link>
	<link name="25">
		<visual>
			<geometry>
				<cylinder length="0.3820965905006577" radius="0.08797632819885409"/>
			</geometry>
		</visual>
		<collision>
			<geometry>
				<cylinder length="0.3820965905006577" radius="0.08797632819885409"/>
			</geometry>
		</collision>
		<inertial>
			<mass value="0.009290833977696132"/>
			<inertia ixx="0.03" iyy="0.03" izz="0.03" ixy="0" ixz="0" iyx="0"/>
		</inertial>
	</link>
	<link name="36">
		<visual>
			<geometry>
				<cylinder length="0.47873618895081393" radius="0.83723507812674"/>
			</geometry>
		</visual>
		<collision>
			<geometry>
				<cylinder length="0.47873618895081393" radius="0.83723507812674"/>
			</geometry>
		</collision>
		<inertial>
			<mass value="1.0542435746390661"/>
			<inertia ixx="0.03" iyy="0.03" izz="0.03" ixy="0" ixz="0" iyx="0"/>
		</inertial>
	</link>
	<link name="37">
		<visual>
			<geometry>
				<cylinder length="0.47873618895081393" radius="0.83723507812674"/>
			</geometry>
		</visual>
		<collision>
			<geometry>
				<cylinder length="0.47873618895081393" radius="0.83723507812674"/>
			</geometry>
		</collision>
		<inertial>
			<mass value="1.0542435746390661"/>
			<inertia ixx="0.03" iyy="0.03" izz="0.03" ixy="0" ixz="0" iyx="0"/>
		</inertial>
	</link>
	<joint name="11_to_0" type="revolute">
		<parent link="0"/>
		<child link="11"/>
		<axis xyz="0 0 1"/>
		<limit effort="1" upper="-3.1415" lower="3.1415" velocity="1"/>
		<origin rpy="2.8323644764938667 1.293594387544998 2.9678389505507834" xyz="0.15986039852037626 0.89154775402469 0.8579656493726011"/>
	</joint>
	<joint name="12_to_0" type="revolute">
		<parent link="0"/>
		<child link="12"/>
		<axis xyz="0 0 1"/>
		<limit effort="1" upper="-3.1415" lower="3.1415" velocity="1"/>
		<origin rpy="4.2485467147408 1.293594387544998 2.9678389505507834" xyz="0.15986039852037626 0.89154775402469 0.8579656493726011"/>
	</joint>
	<joint name="23_to_0" type="revolute">
		<parent link="0"/>
		<child link="23"/>
		<axis xyz="0 0 1"/>
		<limit effort="1" upper="-3.1415" lower="3.1415" velocity="1"/>
		<origin rpy="11.044730016460337 4.45914966589873 1.0604263560398164" xyz="0.052269880848787253 0.8061694095075347 0.4089083237316975"/>
	</joint>
	<joint name="24_to_0" type="revolute">
		<parent link="0"/>
		<child link="24"/>
		<axis xyz="0 0 1"/>
		<limit effort="1" upper="-3.1415" lower="3.1415" velocity="1"/>
		<origin rpy="13.80591252057542 4.45914966589873 1.0604263560398164" xyz="0.052269880848787253 0.8061694095075347 0.4089083237316975"/>
	</joint>
	<joint name="25_to_0" type="revolute">
		<parent link="0"/>
		<child link="25"/>
		<axis xyz="0 0 1"/>
		<limit effort="1" upper="-3.1415" lower="3.1415" velocity="1"/>
		<origin rpy="16.567095024690506 4.45914966589873 1.0604263560398164" xyz="0.052269880848787253 0.8061694095075347 0.4089083237316975"/>
	</joint>
	<joint name="36_to_0" type="revolute">
		<parent link="0"/>
		<child link="36"/>
		<axis xyz="0 1 0"/>
		<limit effort="1" upper="-3.1415" lower="3.1415" velocity="1"/>
		<origin rpy="35.75376411287067 2.3763127697311552 6.0317205382454775" xyz="0.08567222345446368 0.24299484257419157 0.9831121552511143"/>
	</joint>
	<joint name="37_to_0" type="revolute">
		<parent link="0"/>
		<child link="37"/>
		<axis xyz="0 1 0"/>
		<limit effort="1" upper="-3.1415" lower="3.1415" velocity="1"/>
		<origin rpy="40.86144470042362 2.3763127697311552 6.0317205382454775" xyz="0.08567222345446368 0.24299484257419157 0.9831121552511143"/>
	</joint>
</robot>
