<robot name="pepe">
	<link name="0">
		<visual>
			<geometry>
				<cylinder length="0.7398194816812099" radius="0.052722073107775325"/>
			</geometry>
		</visual>
		<collision>
			<geometry>
				<cylinder length="0.7398194816812099" radius="0.052722073107775325"/>
			</geometry>
		</collision>
		<inertial>
			<mass value="0.0064604176374358875"/>
			<inertia ixx="0.03" iyy="0.03" izz="0.03" ixy="0" ixz="0" iyx="0"/>
		</inertial>
	</link>
	<link name="11">
		<visual>
			<geometry>
				<cylinder length="0.8079665842948784" radius="0.5435762453866043"/>
			</geometry>
		</visual>
		<collision>
			<geometry>
				<cylinder length="0.8079665842948784" radius="0.5435762453866043"/>
			</geometry>
		</collision>
		<inertial>
			<mass value="0.7500050911628182"/>
			<inertia ixx="0.03" iyy="0.03" izz="0.03" ixy="0" ixz="0" iyx="0"/>
		</inertial>
	</link>
	<link name="32">
		<visual>
			<geometry>
				<cylinder length="0.09013608297959042" radius="0.39929124390240167"/>
			</geometry>
		</visual>
		<collision>
			<geometry>
				<cylinder length="0.09013608297959042" radius="0.39929124390240167"/>
			</geometry>
		</collision>
		<inertial>
			<mass value="0.045146919967871665"/>
			<inertia ixx="0.03" iyy="0.03" izz="0.03" ixy="0" ixz="0" iyx="0"/>
		</inertial>
	</link>
	<link name="33">
		<visual>
			<geometry>
				<cylinder length="0.09013608297959042" radius="0.39929124390240167"/>
			</geometry>
		</visual>
		<collision>
			<geometry>
				<cylinder length="0.09013608297959042" radius="0.39929124390240167"/>
			</geometry>
		</collision>
		<inertial>
			<mass value="0.045146919967871665"/>
			<inertia ixx="0.03" iyy="0.03" izz="0.03" ixy="0" ixz="0" iyx="0"/>
		</inertial>
	</link>
	<link name="14">
		<visual>
			<geometry>
				<cylinder length="0.8079665842948784" radius="0.5435762453866043"/>
			</geometry>
		</visual>
		<collision>
			<geometry>
				<cylinder length="0.8079665842948784" radius="0.5435762453866043"/>
			</geometry>
		</collision>
		<inertial>
			<mass value="0.7500050911628182"/>
			<inertia ixx="0.03" iyy="0.03" izz="0.03" ixy="0" ixz="0" iyx="0"/>
		</inertial>
	</link>
	<link name="35">
		<visual>
			<geometry>
				<cylinder length="0.09013608297959042" radius="0.39929124390240167"/>
			</geometry>
		</visual>
		<collision>
			<geometry>
				<cylinder length="0.09013608297959042" radius="0.39929124390240167"/>
			</geometry>
		</collision>
		<inertial>
			<mass value="0.045146919967871665"/>
			<inertia ixx="0.03" iyy="0.03" izz="0.03" ixy="0" ixz="0" iyx="0"/>
		</inertial>
	</link>
	<link name="36">
		<visual>
			<geometry>
				<cylinder length="0.09013608297959042" radius="0.39929124390240167"/>
			</geometry>
		</visual>
		<collision>
			<geometry>
				<cylinder length="0.09013608297959042" radius="0.39929124390240167"/>
			</geometry>
		</collision>
		<inertial>
			<mass value="0.045146919967871665"/>
			<inertia ixx="0.03" iyy="0.03" izz="0.03" ixy="0" ixz="0" iyx="0"/>
		</inertial>
	</link>
	<link name="17">
		<visual>
			<geometry>
				<cylinder length="0.8079665842948784" radius="0.5435762453866043"/>
			</geometry>
		</visual>
		<collision>
			<geometry>
				<cylinder length="0.8079665842948784" radius="0.5435762453866043"/>
			</geometry>
		</collision>
		<inertial>
			<mass value="0.7500050911628182"/>
			<inertia ixx="0.03" iyy="0.03" izz="0.03" ixy="0" ixz="0" iyx="0"/>
		</inertial>
	</link>
	<link name="38">
		<visual>
			<geometry>
				<cylinder length="0.09013608297959042" radius="0.39929124390240167"/>
			</geometry>
		</visual>
		<collision>
			<geometry>
				<cylinder length="0.09013608297959042" radius="0.39929124390240167"/>
			</geometry>
		</collision>
		<inertial>
			<mass value="0.045146919967871665"/>
			<inertia ixx="0.03" iyy="0.03" izz="0.03" ixy="0" ixz="0" iyx="0"/>
		</inertial>
	</link>
	<link name="39">
		<visual>
			<geometry>
				<cylinder length="0.09013608297959042" radius="0.39929124390240167"/>
			</geometry>
		</visual>
		<collision>
			<geometry>
				<cylinder length="0.09013608297959042" radius="0.39929124390240167"/>
			</geometry>
		</collision>
		<inertial>
			<mass value="0.045146919967871665"/>
			<inertia ixx="0.03" iyy="0.03" izz="0.03" ixy="0" ixz="0" iyx="0"/>
		</inertial>
	</link>
	<link name="210">
		<visual>
			<geometry>
				<cylinder length="0.506465919751153" radius="0.6094846133177597"/>
			</geometry>
		</visual>
		<collision>
			<geometry>
				<cylinder length="0.506465919751153" radius="0.6094846133177597"/>
			</geometry>
		</collision>
		<inertial>
			<mass value="0.5910518647734716"/>
			<inertia ixx="0.03" iyy="0.03" izz="0.03" ixy="0" ixz="0" iyx="0"/>
		</inertial>
	</link>
	<link name="211">
		<visual>
			<geometry>
				<cylinder length="0.506465919751153" radius="0.6094846133177597"/>
			</geometry>
		</visual>
		<collision>
			<geometry>
				<cylinder length="0.506465919751153" radius="0.6094846133177597"/>
			</geometry>
		</collision>
		<inertial>
			<mass value="0.5910518647734716"/>
			<inertia ixx="0.03" iyy="0.03" izz="0.03" ixy="0" ixz="0" iyx="0"/>
		</inertial>
	</link>
	<joint name="11_to_0" type="revolute">
		<parent link="0"/>
		<child link="11"/>
		<axis xyz="1 0 0"/>
		<limit effort="1" upper="-3.1415" lower="3.1415" velocity="1"/>
		<origin rpy="10.623475154237155 2.8342104177696292 3.1496784475622124" xyz="0.8189271008336009 0.7563699647312384 0.9146125821125136"/>
	</joint>
	<joint name="32_to_11" type="revolute">
		<parent link="11"/>
		<child link="32"/>
		<axis xyz="0 1 0"/>
		<limit effort="1" upper="-3.1415" lower="3.1415" velocity="1"/>
		<origin rpy="6.6891395130062845 1.5183582995820537 0.7057087984852327" xyz="0.1114322170173423 0.18234494282378877 0.3626155174611123"/>
	</joint>
	<joint name="33_to_11" type="revolute">
		<parent link="11"/>
		<child link="33"/>
		<axis xyz="0 1 0"/>
		<limit effort="1" upper="-3.1415" lower="3.1415" velocity="1"/>
		<origin rpy="10.033709269509426 1.5183582995820537 0.7057087984852327" xyz="0.1114322170173423 0.18234494282378877 0.3626155174611123"/>
	</joint>
	<joint name="14_to_0" type="revolute">
		<parent link="0"/>
		<child link="14"/>
		<axis xyz="1 0 0"/>
		<limit effort="1" upper="-3.1415" lower="3.1415" velocity="1"/>
		<origin rpy="15.935212731355733 2.8342104177696292 3.1496784475622124" xyz="0.8189271008336009 0.7563699647312384 0.9146125821125136"/>
	</joint>
	<joint name="35_to_14" type="revolute">
		<parent link="14"/>
		<child link="35"/>
		<axis xyz="0 1 0"/>
		<limit effort="1" upper="-3.1415" lower="3.1415" velocity="1"/>
		<origin rpy="6.6891395130062845 1.5183582995820537 0.7057087984852327" xyz="0.1114322170173423 0.18234494282378877 0.3626155174611123"/>
	</joint>
	<joint name="36_to_14" type="revolute">
		<parent link="14"/>
		<child link="36"/>
		<axis xyz="0 1 0"/>
		<limit effort="1" upper="-3.1415" lower="3.1415" velocity="1"/>
		<origin rpy="10.033709269509426 1.5183582995820537 0.7057087984852327" xyz="0.1114322170173423 0.18234494282378877 0.3626155174611123"/>
	</joint>
	<joint name="17_to_0" type="revolute">
		<parent link="0"/>
		<child link="17"/>
		<axis xyz="1 0 0"/>
		<limit effort="1" upper="-3.1415" lower="3.1415" velocity="1"/>
		<origin rpy="21.24695030847431 2.8342104177696292 3.1496784475622124" xyz="0.8189271008336009 0.7563699647312384 0.9146125821125136"/>
	</joint>
	<joint name="38_to_17" type="revolute">
		<parent link="17"/>
		<child link="38"/>
		<axis xyz="0 1 0"/>
		<limit effort="1" upper="-3.1415" lower="3.1415" velocity="1"/>
		<origin rpy="6.6891395130062845 1.5183582995820537 0.7057087984852327" xyz="0.1114322170173423 0.18234494282378877 0.3626155174611123"/>
	</joint>
	<joint name="39_to_17" type="revolute">
		<parent link="17"/>
		<child link="39"/>
		<axis xyz="0 1 0"/>
		<limit effort="1" upper="-3.1415" lower="3.1415" velocity="1"/>
		<origin rpy="10.033709269509426 1.5183582995820537 0.7057087984852327" xyz="0.1114322170173423 0.18234494282378877 0.3626155174611123"/>
	</joint>
	<joint name="210_to_0" type="revolute">
		<parent link="0"/>
		<child link="210"/>
		<axis xyz="0 0 1"/>
		<limit effort="1" upper="-3.1415" lower="3.1415" velocity="1"/>
		<origin rpy="8.492888449428452 0.9050096959036379 3.6076154805198013" xyz="0.026822661312480456 0.7657070746088926 0.9703833558210094"/>
	</joint>
	<joint name="211_to_0" type="revolute">
		<parent link="0"/>
		<child link="211"/>
		<axis xyz="0 0 1"/>
		<limit effort="1" upper="-3.1415" lower="3.1415" velocity="1"/>
		<origin rpy="10.191466139314144 0.9050096959036379 3.6076154805198013" xyz="0.026822661312480456 0.7657070746088926 0.9703833558210094"/>
	</joint>
</robot>
