<robot name="pepe">
	<link name="0">
		<visual>
			<geometry>
				<cylinder length="0.7398194816812099" radius="0.052722073107775325"/>
			</geometry>
		</visual>
		<collision>
			<geometry>
				<cylinder length="0.7398194816812099" radius="0.052722073107775325"/>
			</geometry>
		</collision>
		<inertial>
			<mass value="0.0064604176374358875"/>
			<inertia ixx="0.03" iyy="0.03" izz="0.03" ixy="0" ixz="0" iyx="0"/>
		</inertial>
	</link>
	<link name="11">
		<visual>
			<geometry>
				<cylinder length="0.8079665842948784" radius="0.5435762453866043"/>
			</geometry>
		</visual>
		<collision>
			<geometry>
				<cylinder length="0.8079665842948784" radius="0.5435762453866043"/>
			</geometry>
		</collision>
		<inertial>
			<mass value="0.7500050911628182"/>
			<inertia ixx="0.03" iyy="0.03" izz="0.03" ixy="0" ixz="0" iyx="0"/>
		</inertial>
	</link>
	<link name="12">
		<visual>
			<geometry>
				<cylinder length="0.8079665842948784" radius="0.5435762453866043"/>
			</geometry>
		</visual>
		<collision>
			<geometry>
				<cylinder length="0.8079665842948784" radius="0.5435762453866043"/>
			</geometry>
		</collision>
		<inertial>
			<mass value="0.7500050911628182"/>
			<inertia ixx="0.03" iyy="0.03" izz="0.03" ixy="0" ixz="0" iyx="0"/>
		</inertial>
	</link>
	<link name="13">
		<visual>
			<geometry>
				<cylinder length="0.8079665842948784" radius="0.5435762453866043"/>
			</geometry>
		</visual>
		<collision>
			<geometry>
				<cylinder length="0.8079665842948784" radius="0.5435762453866043"/>
			</geometry>
		</collision>
		<inertial>
			<mass value="0.7500050911628182"/>
			<inertia ixx="0.03" iyy="0.03" izz="0.03" ixy="0" ixz="0" iyx="0"/>
		</inertial>
	</link>
	<link name="24">
		<visual>
			<geometry>
				<cylinder length="0.506465919751153" radius="0.6094846133177597"/>
			</geometry>
		</visual>
		<collision>
			<geometry>
				<cylinder length="0.506465919751153" radius="0.6094846133177597"/>
			</geometry>
		</collision>
		<inertial>
			<mass value="0.5910518647734716"/>
			<inertia ixx="0.03" iyy="0.03" izz="0.03" ixy="0" ixz="0" iyx="0"/>
		</inertial>
	</link>
	<link name="25">
		<visual>
			<geometry>
				<cylinder length="0.506465919751153" radius="0.6094846133177597"/>
			</geometry>
		</visual>
		<collision>
			<geometry>
				<cylinder length="0.506465919751153" radius="0.6094846133177597"/>
			</geometry>
		</collision>
		<inertial>
			<mass value="0.5910518647734716"/>
			<inertia ixx="0.03" iyy="0.03" izz="0.03" ixy="0" ixz="0" iyx="0"/>
		</inertial>
	</link>
	<joint name="11_to_0" type="revolute">
		<parent link="0"/>
		<child link="11"/>
		<axis xyz="1 0 0"/>
		<limit effort="1" upper="-3.1415" lower="3.1415" velocity="1"/>
		<origin rpy="10.623475154237155 2.8342104177696292 3.1496784475622124" xyz="0.8189271008336009 0.7563699647312384 0.9146125821125136"/>
	</joint>
	<joint name="12_to_0" type="revolute">
		<parent link="0"/>
		<child link="12"/>
		<axis xyz="1 0 0"/>
		<limit effort="1" upper="-3.1415" lower="3.1415" velocity="1"/>
		<origin rpy="15.935212731355733 2.8342104177696292 3.1496784475622124" xyz="0.8189271008336009 0.7563699647312384 0.9146125821125136"/>
	</joint>
	<joint name="13_to_0" type="revolute">
		<parent link="0"/>
		<child link="13"/>
		<axis xyz="1 0 0"/>
		<limit effort="1" upper="-3.1415" lower="3.1415" velocity="1"/>
		<origin rpy="21.24695030847431 2.8342104177696292 3.1496784475622124" xyz="0.8189271008336009 0.7563699647312384 0.9146125821125136"/>
	</joint>
	<joint name="24_to_0" type="revolute">
		<parent link="0"/>
		<child link="24"/>
		<axis xyz="0 0 1"/>
		<limit effort="1" upper="-3.1415" lower="3.1415" velocity="1"/>
		<origin rpy="8.492888449428452 0.9050096959036379 3.6076154805198013" xyz="0.026822661312480456 0.7657070746088926 0.9703833558210094"/>
	</joint>
	<joint name="25_to_0" type="revolute">
		<parent link="0"/>
		<child link="25"/>
		<axis xyz="0 0 1"/>
		<limit effort="1" upper="-3.1415" lower="3.1415" velocity="1"/>
		<origin rpy="10.191466139314144 0.9050096959036379 3.6076154805198013" xyz="0.026822661312480456 0.7657070746088926 0.9703833558210094"/>
	</joint>
</robot>
