<robot name="pepe">
	<link name="0">
		<visual>
			<geometry>
				<cylinder length="0.6893211687453101" radius="0.9622298383937432"/>
			</geometry>
		</visual>
		<collision>
			<geometry>
				<cylinder length="0.6893211687453101" radius="0.9622298383937432"/>
			</geometry>
		</collision>
		<inertial>
			<mass value="2.0050681046279117"/>
			<inertia ixx="0.03" iyy="0.03" izz="0.03" ixy="0" ixz="0" iyx="0"/>
		</inertial>
	</link>
	<link name="11">
		<visual>
			<geometry>
				<cylinder length="-0.053988214517676714" radius="0.31518134025626066"/>
			</geometry>
		</visual>
		<collision>
			<geometry>
				<cylinder length="-0.053988214517676714" radius="0.31518134025626066"/>
			</geometry>
		</collision>
		<inertial>
			<mass value="-0.01684883329975156"/>
			<inertia ixx="0.03" iyy="0.03" izz="0.03" ixy="0" ixz="0" iyx="0"/>
		</inertial>
	</link>
	<joint name="11_to_0" type="revolute">
		<parent link="0"/>
		<child link="11"/>
		<axis xyz="0 1 0"/>
		<limit effort="1" upper="-3.1415" lower="3.1415" velocity="1"/>
		<origin rpy="5.310947683618419 3.3888769401123273 1.150405977621466" xyz="0.48343593380848504 0.18201528261013786 0.7914967187520997"/>
	</joint>
</robot>
