<robot name="pepe">
	<link name="0">
		<visual>
			<geometry>
				<cylinder length="0.2514329775891432" radius="0.4813585494165482"/>
			</geometry>
		</visual>
		<collision>
			<geometry>
				<cylinder length="0.2514329775891432" radius="0.4813585494165482"/>
			</geometry>
		</collision>
		<inertial>
			<mass value="0.18302461024354932"/>
			<inertia ixx="0.03" iyy="0.03" izz="0.03" ixy="0" ixz="0" iyx="0"/>
		</inertial>
	</link>
	<link name="11">
		<visual>
			<geometry>
				<cylinder length="0.9724069702602065" radius="0.9392577343978782"/>
			</geometry>
		</visual>
		<collision>
			<geometry>
				<cylinder length="0.9724069702602065" radius="0.9392577343978782"/>
			</geometry>
		</collision>
		<inertial>
			<mass value="2.6950541517302082"/>
			<inertia ixx="0.03" iyy="0.03" izz="0.03" ixy="0" ixz="0" iyx="0"/>
		</inertial>
	</link>
	<link name="12">
		<visual>
			<geometry>
				<cylinder length="0.9724069702602065" radius="0.9392577343978782"/>
			</geometry>
		</visual>
		<collision>
			<geometry>
				<cylinder length="0.9724069702602065" radius="0.9392577343978782"/>
			</geometry>
		</collision>
		<inertial>
			<mass value="2.6950541517302082"/>
			<inertia ixx="0.03" iyy="0.03" izz="0.03" ixy="0" ixz="0" iyx="0"/>
		</inertial>
	</link>
	<link name="13">
		<visual>
			<geometry>
				<cylinder length="0.9724069702602065" radius="0.9392577343978782"/>
			</geometry>
		</visual>
		<collision>
			<geometry>
				<cylinder length="0.9724069702602065" radius="0.9392577343978782"/>
			</geometry>
		</collision>
		<inertial>
			<mass value="2.6950541517302082"/>
			<inertia ixx="0.03" iyy="0.03" izz="0.03" ixy="0" ixz="0" iyx="0"/>
		</inertial>
	</link>
	<joint name="11_to_0" type="revolute">
		<parent link="0"/>
		<child link="11"/>
		<axis xyz="0 1 0"/>
		<limit effort="1" upper="-3.1415" lower="3.1415" velocity="1"/>
		<origin rpy="11.870000634389736 1.6046171044347293 4.003629441277388" xyz="0.8595805157200221 0.26263827915132143 0.9544215578851041"/>
	</joint>
	<joint name="12_to_0" type="revolute">
		<parent link="0"/>
		<child link="12"/>
		<axis xyz="0 1 0"/>
		<limit effort="1" upper="-3.1415" lower="3.1415" velocity="1"/>
		<origin rpy="17.805000951584603 1.6046171044347293 4.003629441277388" xyz="0.8595805157200221 0.26263827915132143 0.9544215578851041"/>
	</joint>
	<joint name="13_to_0" type="revolute">
		<parent link="0"/>
		<child link="13"/>
		<axis xyz="0 1 0"/>
		<limit effort="1" upper="-3.1415" lower="3.1415" velocity="1"/>
		<origin rpy="23.740001268779473 1.6046171044347293 4.003629441277388" xyz="0.8595805157200221 0.26263827915132143 0.9544215578851041"/>
	</joint>
</robot>
