<robot name="pepe">
	<link name="0">
		<visual>
			<geometry>
				<cylinder length="0.9068003465220729" radius="0.8956612198609273"/>
			</geometry>
		</visual>
		<collision>
			<geometry>
				<cylinder length="0.9068003465220729" radius="0.8956612198609273"/>
			</geometry>
		</collision>
		<inertial>
			<mass value="2.2853308979250015"/>
			<inertia ixx="0.03" iyy="0.03" izz="0.03" ixy="0" ixz="0" iyx="0"/>
		</inertial>
	</link>
	<link name="11">
		<visual>
			<geometry>
				<cylinder length="0.17528452880688317" radius="0.10259425207657724"/>
			</geometry>
		</visual>
		<collision>
			<geometry>
				<cylinder length="0.17528452880688317" radius="0.10259425207657724"/>
			</geometry>
		</collision>
		<inertial>
			<mass value="0.005796148686580906"/>
			<inertia ixx="0.03" iyy="0.03" izz="0.03" ixy="0" ixz="0" iyx="0"/>
		</inertial>
	</link>
	<link name="12">
		<visual>
			<geometry>
				<cylinder length="0.17528452880688317" radius="0.10259425207657724"/>
			</geometry>
		</visual>
		<collision>
			<geometry>
				<cylinder length="0.17528452880688317" radius="0.10259425207657724"/>
			</geometry>
		</collision>
		<inertial>
			<mass value="0.005796148686580906"/>
			<inertia ixx="0.03" iyy="0.03" izz="0.03" ixy="0" ixz="0" iyx="0"/>
		</inertial>
	</link>
	<link name="13">
		<visual>
			<geometry>
				<cylinder length="0.17528452880688317" radius="0.10259425207657724"/>
			</geometry>
		</visual>
		<collision>
			<geometry>
				<cylinder length="0.17528452880688317" radius="0.10259425207657724"/>
			</geometry>
		</collision>
		<inertial>
			<mass value="0.005796148686580906"/>
			<inertia ixx="0.03" iyy="0.03" izz="0.03" ixy="0" ixz="0" iyx="0"/>
		</inertial>
	</link>
	<link name="24">
		<visual>
			<geometry>
				<cylinder length="0.5284323168926627" radius="0.5831026272272751"/>
			</geometry>
		</visual>
		<collision>
			<geometry>
				<cylinder length="0.5284323168926627" radius="0.5831026272272751"/>
			</geometry>
		</collision>
		<inertial>
			<mass value="0.5644548884602517"/>
			<inertia ixx="0.03" iyy="0.03" izz="0.03" ixy="0" ixz="0" iyx="0"/>
		</inertial>
	</link>
	<link name="25">
		<visual>
			<geometry>
				<cylinder length="0.5284323168926627" radius="0.5831026272272751"/>
			</geometry>
		</visual>
		<collision>
			<geometry>
				<cylinder length="0.5284323168926627" radius="0.5831026272272751"/>
			</geometry>
		</collision>
		<inertial>
			<mass value="0.5644548884602517"/>
			<inertia ixx="0.03" iyy="0.03" izz="0.03" ixy="0" ixz="0" iyx="0"/>
		</inertial>
	</link>
	<link name="26">
		<visual>
			<geometry>
				<cylinder length="0.5284323168926627" radius="0.5831026272272751"/>
			</geometry>
		</visual>
		<collision>
			<geometry>
				<cylinder length="0.5284323168926627" radius="0.5831026272272751"/>
			</geometry>
		</collision>
		<inertial>
			<mass value="0.5644548884602517"/>
			<inertia ixx="0.03" iyy="0.03" izz="0.03" ixy="0" ixz="0" iyx="0"/>
		</inertial>
	</link>
	<link name="27">
		<visual>
			<geometry>
				<cylinder length="0.5284323168926627" radius="0.5831026272272751"/>
			</geometry>
		</visual>
		<collision>
			<geometry>
				<cylinder length="0.5284323168926627" radius="0.5831026272272751"/>
			</geometry>
		</collision>
		<inertial>
			<mass value="0.5644548884602517"/>
			<inertia ixx="0.03" iyy="0.03" izz="0.03" ixy="0" ixz="0" iyx="0"/>
		</inertial>
	</link>
	<joint name="11_to_0" type="revolute">
		<parent link="0"/>
		<child link="11"/>
		<axis xyz="0 1 0"/>
		<limit effort="1" upper="-3.1415" lower="3.1415" velocity="1"/>
		<origin rpy="3.921584775810498 4.579208367830996 1.767410602776518" xyz="0.5981472401964166 0.6837668493997091 0.3309743206386433"/>
	</joint>
	<joint name="12_to_0" type="revolute">
		<parent link="0"/>
		<child link="12"/>
		<axis xyz="0 1 0"/>
		<limit effort="1" upper="-3.1415" lower="3.1415" velocity="1"/>
		<origin rpy="5.882377163715747 4.579208367830996 1.767410602776518" xyz="0.5981472401964166 0.6837668493997091 0.3309743206386433"/>
	</joint>
	<joint name="13_to_0" type="revolute">
		<parent link="0"/>
		<child link="13"/>
		<axis xyz="0 1 0"/>
		<limit effort="1" upper="-3.1415" lower="3.1415" velocity="1"/>
		<origin rpy="7.843169551620996 4.579208367830996 1.767410602776518" xyz="0.5981472401964166 0.6837668493997091 0.3309743206386433"/>
	</joint>
	<joint name="24_to_0" type="revolute">
		<parent link="0"/>
		<child link="24"/>
		<axis xyz="0 0 1"/>
		<limit effort="1" upper="-3.1415" lower="3.1415" velocity="1"/>
		<origin rpy="2.611765692894928 3.2512058550525254 4.063865690242365" xyz="0.6243419250113228 0.13848085640355667 0.2909787552741978"/>
	</joint>
	<joint name="25_to_0" type="revolute">
		<parent link="0"/>
		<child link="25"/>
		<axis xyz="0 0 1"/>
		<limit effort="1" upper="-3.1415" lower="3.1415" velocity="1"/>
		<origin rpy="3.134118831473914 3.2512058550525254 4.063865690242365" xyz="0.6243419250113228 0.13848085640355667 0.2909787552741978"/>
	</joint>
	<joint name="26_to_0" type="revolute">
		<parent link="0"/>
		<child link="26"/>
		<axis xyz="0 0 1"/>
		<limit effort="1" upper="-3.1415" lower="3.1415" velocity="1"/>
		<origin rpy="3.6564719700529 3.2512058550525254 4.063865690242365" xyz="0.6243419250113228 0.13848085640355667 0.2909787552741978"/>
	</joint>
	<joint name="27_to_0" type="revolute">
		<parent link="0"/>
		<child link="27"/>
		<axis xyz="0 0 1"/>
		<limit effort="1" upper="-3.1415" lower="3.1415" velocity="1"/>
		<origin rpy="4.1788251086318855 3.2512058550525254 4.063865690242365" xyz="0.6243419250113228 0.13848085640355667 0.2909787552741978"/>
	</joint>
</robot>
