<robot name="pepe">
	<link name="0">
		<visual>
			<geometry>
				<cylinder length="0.00014309724393646306" radius="0.878015169482812"/>
			</geometry>
		</visual>
		<collision>
			<geometry>
				<cylinder length="0.00014309724393646306" radius="0.878015169482812"/>
			</geometry>
		</collision>
		<inertial>
			<mass value="0.000346565382932485"/>
			<inertia ixx="0.03" iyy="0.03" izz="0.03" ixy="0" ixz="0" iyx="0"/>
		</inertial>
	</link>
	<link name="11">
		<visual>
			<geometry>
				<cylinder length="0.8470135737048601" radius="0.09237619993412371"/>
			</geometry>
		</visual>
		<collision>
			<geometry>
				<cylinder length="0.8470135737048601" radius="0.09237619993412371"/>
			</geometry>
		</collision>
		<inertial>
			<mass value="0.02270703494692649"/>
			<inertia ixx="0.03" iyy="0.03" izz="0.03" ixy="0" ixz="0" iyx="0"/>
		</inertial>
	</link>
	<link name="12">
		<visual>
			<geometry>
				<cylinder length="0.8470135737048601" radius="0.09237619993412371"/>
			</geometry>
		</visual>
		<collision>
			<geometry>
				<cylinder length="0.8470135737048601" radius="0.09237619993412371"/>
			</geometry>
		</collision>
		<inertial>
			<mass value="0.02270703494692649"/>
			<inertia ixx="0.03" iyy="0.03" izz="0.03" ixy="0" ixz="0" iyx="0"/>
		</inertial>
	</link>
	<link name="13">
		<visual>
			<geometry>
				<cylinder length="0.8470135737048601" radius="0.09237619993412371"/>
			</geometry>
		</visual>
		<collision>
			<geometry>
				<cylinder length="0.8470135737048601" radius="0.09237619993412371"/>
			</geometry>
		</collision>
		<inertial>
			<mass value="0.02270703494692649"/>
			<inertia ixx="0.03" iyy="0.03" izz="0.03" ixy="0" ixz="0" iyx="0"/>
		</inertial>
	</link>
	<link name="14">
		<visual>
			<geometry>
				<cylinder length="0.8470135737048601" radius="0.09237619993412371"/>
			</geometry>
		</visual>
		<collision>
			<geometry>
				<cylinder length="0.8470135737048601" radius="0.09237619993412371"/>
			</geometry>
		</collision>
		<inertial>
			<mass value="0.02270703494692649"/>
			<inertia ixx="0.03" iyy="0.03" izz="0.03" ixy="0" ixz="0" iyx="0"/>
		</inertial>
	</link>
	<joint name="11_to_0" type="revolute">
		<parent link="0"/>
		<child link="11"/>
		<axis xyz="0 0 1"/>
		<limit effort="1" upper="-3.1415" lower="3.1415" velocity="1"/>
		<origin rpy="7.319695941767772 0.3792176625421638 5.870559705641843" xyz="0.34167592979167816 0.7741555189693887 0.11745861032152582"/>
	</joint>
	<joint name="12_to_0" type="revolute">
		<parent link="0"/>
		<child link="12"/>
		<axis xyz="0 0 1"/>
		<limit effort="1" upper="-3.1415" lower="3.1415" velocity="1"/>
		<origin rpy="10.979543912651657 0.3792176625421638 5.870559705641843" xyz="0.34167592979167816 0.7741555189693887 0.11745861032152582"/>
	</joint>
	<joint name="13_to_0" type="revolute">
		<parent link="0"/>
		<child link="13"/>
		<axis xyz="0 0 1"/>
		<limit effort="1" upper="-3.1415" lower="3.1415" velocity="1"/>
		<origin rpy="14.639391883535543 0.3792176625421638 5.870559705641843" xyz="0.34167592979167816 0.7741555189693887 0.11745861032152582"/>
	</joint>
	<joint name="14_to_0" type="revolute">
		<parent link="0"/>
		<child link="14"/>
		<axis xyz="0 0 1"/>
		<limit effort="1" upper="-3.1415" lower="3.1415" velocity="1"/>
		<origin rpy="18.29923985441943 0.3792176625421638 5.870559705641843" xyz="0.34167592979167816 0.7741555189693887 0.11745861032152582"/>
	</joint>
</robot>
