<robot name="pepe">
	<link name="0">
		<visual>
			<geometry>
				<cylinder length="0.3163732279676421" radius="0.2570301519389081"/>
			</geometry>
		</visual>
		<collision>
			<geometry>
				<cylinder length="0.3163732279676421" radius="0.2570301519389081"/>
			</geometry>
		</collision>
		<inertial>
			<mass value="0.0656625499606453"/>
			<inertia ixx="0.03" iyy="0.03" izz="0.03" ixy="0" ixz="0" iyx="0"/>
		</inertial>
	</link>
	<link name="11">
		<visual>
			<geometry>
				<cylinder length="0.09441289300432174" radius="0.574142248387529"/>
			</geometry>
		</visual>
		<collision>
			<geometry>
				<cylinder length="0.09441289300432174" radius="0.574142248387529"/>
			</geometry>
		</collision>
		<inertial>
			<mass value="0.09777328110326605"/>
			<inertia ixx="0.03" iyy="0.03" izz="0.03" ixy="0" ixz="0" iyx="0"/>
		</inertial>
	</link>
	<joint name="11_to_0" type="revolute">
		<parent link="0"/>
		<child link="11"/>
		<axis xyz="1 0 0"/>
		<limit effort="1" upper="-3.1415" lower="3.1415" velocity="1"/>
		<origin rpy="6.021208138471891 3.827880140251571 3.497393685292438" xyz="0.6952506915179402 0.8815945829934303 0.4522187053142819"/>
	</joint>
</robot>
