<robot name="pepe">
	<link name="0">
		<visual>
			<geometry>
				<cylinder length="0.2514329775891432" radius="0.4813585494165482"/>
			</geometry>
		</visual>
		<collision>
			<geometry>
				<cylinder length="0.2514329775891432" radius="0.4813585494165482"/>
			</geometry>
		</collision>
		<inertial>
			<mass value="0.18302461024354932"/>
			<inertia ixx="0.03" iyy="0.03" izz="0.03" ixy="0" ixz="0" iyx="0"/>
		</inertial>
	</link>
	<link name="11">
		<visual>
			<geometry>
				<cylinder length="0.9724069702602065" radius="0.9392577343978782"/>
			</geometry>
		</visual>
		<collision>
			<geometry>
				<cylinder length="0.9724069702602065" radius="0.9392577343978782"/>
			</geometry>
		</collision>
		<inertial>
			<mass value="2.6950541517302082"/>
			<inertia ixx="0.03" iyy="0.03" izz="0.03" ixy="0" ixz="0" iyx="0"/>
		</inertial>
	</link>
	<link name="22">
		<visual>
			<geometry>
				<cylinder length="0.8157967461195692" radius="0.32445357987726464"/>
			</geometry>
		</visual>
		<collision>
			<geometry>
				<cylinder length="0.8157967461195692" radius="0.32445357987726464"/>
			</geometry>
		</collision>
		<inertial>
			<mass value="0.26979691668443595"/>
			<inertia ixx="0.03" iyy="0.03" izz="0.03" ixy="0" ixz="0" iyx="0"/>
		</inertial>
	</link>
	<link name="23">
		<visual>
			<geometry>
				<cylinder length="0.8157967461195692" radius="0.32445357987726464"/>
			</geometry>
		</visual>
		<collision>
			<geometry>
				<cylinder length="0.8157967461195692" radius="0.32445357987726464"/>
			</geometry>
		</collision>
		<inertial>
			<mass value="0.26979691668443595"/>
			<inertia ixx="0.03" iyy="0.03" izz="0.03" ixy="0" ixz="0" iyx="0"/>
		</inertial>
	</link>
	<link name="14">
		<visual>
			<geometry>
				<cylinder length="0.9724069702602065" radius="0.9392577343978782"/>
			</geometry>
		</visual>
		<collision>
			<geometry>
				<cylinder length="0.9724069702602065" radius="0.9392577343978782"/>
			</geometry>
		</collision>
		<inertial>
			<mass value="2.6950541517302082"/>
			<inertia ixx="0.03" iyy="0.03" izz="0.03" ixy="0" ixz="0" iyx="0"/>
		</inertial>
	</link>
	<link name="25">
		<visual>
			<geometry>
				<cylinder length="0.8157967461195692" radius="0.32445357987726464"/>
			</geometry>
		</visual>
		<collision>
			<geometry>
				<cylinder length="0.8157967461195692" radius="0.32445357987726464"/>
			</geometry>
		</collision>
		<inertial>
			<mass value="0.26979691668443595"/>
			<inertia ixx="0.03" iyy="0.03" izz="0.03" ixy="0" ixz="0" iyx="0"/>
		</inertial>
	</link>
	<link name="26">
		<visual>
			<geometry>
				<cylinder length="0.8157967461195692" radius="0.32445357987726464"/>
			</geometry>
		</visual>
		<collision>
			<geometry>
				<cylinder length="0.8157967461195692" radius="0.32445357987726464"/>
			</geometry>
		</collision>
		<inertial>
			<mass value="0.26979691668443595"/>
			<inertia ixx="0.03" iyy="0.03" izz="0.03" ixy="0" ixz="0" iyx="0"/>
		</inertial>
	</link>
	<link name="17">
		<visual>
			<geometry>
				<cylinder length="0.9724069702602065" radius="0.9392577343978782"/>
			</geometry>
		</visual>
		<collision>
			<geometry>
				<cylinder length="0.9724069702602065" radius="0.9392577343978782"/>
			</geometry>
		</collision>
		<inertial>
			<mass value="2.6950541517302082"/>
			<inertia ixx="0.03" iyy="0.03" izz="0.03" ixy="0" ixz="0" iyx="0"/>
		</inertial>
	</link>
	<link name="28">
		<visual>
			<geometry>
				<cylinder length="0.8157967461195692" radius="0.32445357987726464"/>
			</geometry>
		</visual>
		<collision>
			<geometry>
				<cylinder length="0.8157967461195692" radius="0.32445357987726464"/>
			</geometry>
		</collision>
		<inertial>
			<mass value="0.26979691668443595"/>
			<inertia ixx="0.03" iyy="0.03" izz="0.03" ixy="0" ixz="0" iyx="0"/>
		</inertial>
	</link>
	<link name="29">
		<visual>
			<geometry>
				<cylinder length="0.8157967461195692" radius="0.32445357987726464"/>
			</geometry>
		</visual>
		<collision>
			<geometry>
				<cylinder length="0.8157967461195692" radius="0.32445357987726464"/>
			</geometry>
		</collision>
		<inertial>
			<mass value="0.26979691668443595"/>
			<inertia ixx="0.03" iyy="0.03" izz="0.03" ixy="0" ixz="0" iyx="0"/>
		</inertial>
	</link>
	<link name="310">
		<visual>
			<geometry>
				<cylinder length="0.26264248158970627" radius="0.18361855234033975"/>
			</geometry>
		</visual>
		<collision>
			<geometry>
				<cylinder length="0.26264248158970627" radius="0.18361855234033975"/>
			</geometry>
		</collision>
		<inertial>
			<mass value="0.02781941313071133"/>
			<inertia ixx="0.03" iyy="0.03" izz="0.03" ixy="0" ixz="0" iyx="0"/>
		</inertial>
	</link>
	<link name="311">
		<visual>
			<geometry>
				<cylinder length="0.26264248158970627" radius="0.18361855234033975"/>
			</geometry>
		</visual>
		<collision>
			<geometry>
				<cylinder length="0.26264248158970627" radius="0.18361855234033975"/>
			</geometry>
		</collision>
		<inertial>
			<mass value="0.02781941313071133"/>
			<inertia ixx="0.03" iyy="0.03" izz="0.03" ixy="0" ixz="0" iyx="0"/>
		</inertial>
	</link>
	<link name="312">
		<visual>
			<geometry>
				<cylinder length="0.26264248158970627" radius="0.18361855234033975"/>
			</geometry>
		</visual>
		<collision>
			<geometry>
				<cylinder length="0.26264248158970627" radius="0.18361855234033975"/>
			</geometry>
		</collision>
		<inertial>
			<mass value="0.02781941313071133"/>
			<inertia ixx="0.03" iyy="0.03" izz="0.03" ixy="0" ixz="0" iyx="0"/>
		</inertial>
	</link>
	<joint name="11_to_0" type="revolute">
		<parent link="0"/>
		<child link="11"/>
		<axis xyz="0 1 0"/>
		<limit effort="1" upper="-3.1415" lower="3.1415" velocity="1"/>
		<origin rpy="11.870000634389736 1.6046171044347293 4.003629441277388" xyz="0.7611592138178738 0.26263827915132143 0.9544215578851041"/>
	</joint>
	<joint name="22_to_11" type="revolute">
		<parent link="11"/>
		<child link="22"/>
		<axis xyz="0 0 1"/>
		<limit effort="1" upper="-3.1415" lower="3.1415" velocity="1"/>
		<origin rpy="4.925507931950128 1.9938912850860744 0.707773777047744" xyz="0.3018089232343095 0.19770403714540463 0.392045896834455"/>
	</joint>
	<joint name="23_to_11" type="revolute">
		<parent link="11"/>
		<child link="23"/>
		<axis xyz="0 0 1"/>
		<limit effort="1" upper="-3.1415" lower="3.1415" velocity="1"/>
		<origin rpy="7.388261897925192 1.9938912850860744 0.707773777047744" xyz="0.3018089232343095 0.19770403714540463 0.392045896834455"/>
	</joint>
	<joint name="14_to_0" type="revolute">
		<parent link="0"/>
		<child link="14"/>
		<axis xyz="0 1 0"/>
		<limit effort="1" upper="-3.1415" lower="3.1415" velocity="1"/>
		<origin rpy="17.805000951584603 1.6046171044347293 4.003629441277388" xyz="0.7611592138178738 0.26263827915132143 0.9544215578851041"/>
	</joint>
	<joint name="25_to_14" type="revolute">
		<parent link="14"/>
		<child link="25"/>
		<axis xyz="0 0 1"/>
		<limit effort="1" upper="-3.1415" lower="3.1415" velocity="1"/>
		<origin rpy="4.925507931950128 1.9938912850860744 0.707773777047744" xyz="0.3018089232343095 0.19770403714540463 0.392045896834455"/>
	</joint>
	<joint name="26_to_14" type="revolute">
		<parent link="14"/>
		<child link="26"/>
		<axis xyz="0 0 1"/>
		<limit effort="1" upper="-3.1415" lower="3.1415" velocity="1"/>
		<origin rpy="7.388261897925192 1.9938912850860744 0.707773777047744" xyz="0.3018089232343095 0.19770403714540463 0.392045896834455"/>
	</joint>
	<joint name="17_to_0" type="revolute">
		<parent link="0"/>
		<child link="17"/>
		<axis xyz="0 1 0"/>
		<limit effort="1" upper="-3.1415" lower="3.1415" velocity="1"/>
		<origin rpy="23.740001268779473 1.6046171044347293 4.003629441277388" xyz="0.7611592138178738 0.26263827915132143 0.9544215578851041"/>
	</joint>
	<joint name="28_to_17" type="revolute">
		<parent link="17"/>
		<child link="28"/>
		<axis xyz="0 0 1"/>
		<limit effort="1" upper="-3.1415" lower="3.1415" velocity="1"/>
		<origin rpy="4.925507931950128 1.9938912850860744 0.707773777047744" xyz="0.3018089232343095 0.19770403714540463 0.392045896834455"/>
	</joint>
	<joint name="29_to_17" type="revolute">
		<parent link="17"/>
		<child link="29"/>
		<axis xyz="0 0 1"/>
		<limit effort="1" upper="-3.1415" lower="3.1415" velocity="1"/>
		<origin rpy="7.388261897925192 1.9938912850860744 0.707773777047744" xyz="0.3018089232343095 0.19770403714540463 0.392045896834455"/>
	</joint>
	<joint name="310_to_0" type="revolute">
		<parent link="0"/>
		<child link="310"/>
		<axis xyz="0 1 0"/>
		<limit effort="1" upper="-3.1415" lower="3.1415" velocity="1"/>
		<origin rpy="1.4746569238811085 3.6850640218778414 4.85315252788258" xyz="0.12254074350822408 0.3648144969918299 0.17142991860581258"/>
	</joint>
	<joint name="311_to_0" type="revolute">
		<parent link="0"/>
		<child link="311"/>
		<axis xyz="0 1 0"/>
		<limit effort="1" upper="-3.1415" lower="3.1415" velocity="1"/>
		<origin rpy="1.7695883086573303 3.6850640218778414 4.85315252788258" xyz="0.12254074350822408 0.3648144969918299 0.17142991860581258"/>
	</joint>
	<joint name="312_to_0" type="revolute">
		<parent link="0"/>
		<child link="312"/>
		<axis xyz="0 1 0"/>
		<limit effort="1" upper="-3.1415" lower="3.1415" velocity="1"/>
		<origin rpy="2.064519693433552 3.6850640218778414 4.85315252788258" xyz="0.12254074350822408 0.3648144969918299 0.17142991860581258"/>
	</joint>
</robot>
