<robot name="pepe">
	<link name="0">
		<visual>
			<geometry>
				<cylinder length="0.7398194816812099" radius="0.052722073107775325"/>
			</geometry>
		</visual>
		<collision>
			<geometry>
				<cylinder length="0.7398194816812099" radius="0.052722073107775325"/>
			</geometry>
		</collision>
		<inertial>
			<mass value="0.0064604176374358875"/>
			<inertia ixx="0.03" iyy="0.03" izz="0.03" ixy="0" ixz="0" iyx="0"/>
		</inertial>
	</link>
	<link name="11">
		<visual>
			<geometry>
				<cylinder length="0.8179125385502696" radius="0.163225633163701"/>
			</geometry>
		</visual>
		<collision>
			<geometry>
				<cylinder length="0.8179125385502696" radius="0.163225633163701"/>
			</geometry>
		</collision>
		<inertial>
			<mass value="0.06845945895472486"/>
			<inertia ixx="0.03" iyy="0.03" izz="0.03" ixy="0" ixz="0" iyx="0"/>
		</inertial>
	</link>
	<link name="12">
		<visual>
			<geometry>
				<cylinder length="0.8179125385502696" radius="0.163225633163701"/>
			</geometry>
		</visual>
		<collision>
			<geometry>
				<cylinder length="0.8179125385502696" radius="0.163225633163701"/>
			</geometry>
		</collision>
		<inertial>
			<mass value="0.06845945895472486"/>
			<inertia ixx="0.03" iyy="0.03" izz="0.03" ixy="0" ixz="0" iyx="0"/>
		</inertial>
	</link>
	<link name="23">
		<visual>
			<geometry>
				<cylinder length="0.506465919751153" radius="0.6094846133177597"/>
			</geometry>
		</visual>
		<collision>
			<geometry>
				<cylinder length="0.506465919751153" radius="0.6094846133177597"/>
			</geometry>
		</collision>
		<inertial>
			<mass value="0.5910518647734716"/>
			<inertia ixx="0.03" iyy="0.03" izz="0.03" ixy="0" ixz="0" iyx="0"/>
		</inertial>
	</link>
	<link name="24">
		<visual>
			<geometry>
				<cylinder length="0.506465919751153" radius="0.6094846133177597"/>
			</geometry>
		</visual>
		<collision>
			<geometry>
				<cylinder length="0.506465919751153" radius="0.6094846133177597"/>
			</geometry>
		</collision>
		<inertial>
			<mass value="0.5910518647734716"/>
			<inertia ixx="0.03" iyy="0.03" izz="0.03" ixy="0" ixz="0" iyx="0"/>
		</inertial>
	</link>
	<joint name="11_to_0" type="revolute">
		<parent link="0"/>
		<child link="11"/>
		<axis xyz="0 0 1"/>
		<limit effort="1" upper="-3.1415" lower="3.1415" velocity="1"/>
		<origin rpy="9.808126357122962 2.5233665411156254 4.787943064201908" xyz="0.6356337499132794 0.6031902401349394 0.23405451282220213"/>
	</joint>
	<joint name="12_to_0" type="revolute">
		<parent link="0"/>
		<child link="12"/>
		<axis xyz="0 0 1"/>
		<limit effort="1" upper="-3.1415" lower="3.1415" velocity="1"/>
		<origin rpy="14.712189535684443 2.5233665411156254 4.787943064201908" xyz="0.6356337499132794 0.6031902401349394 0.23405451282220213"/>
	</joint>
	<joint name="23_to_0" type="revolute">
		<parent link="0"/>
		<child link="23"/>
		<axis xyz="0 0 1"/>
		<limit effort="1" upper="-3.1415" lower="3.1415" velocity="1"/>
		<origin rpy="6.794310759542762 0.9050096959036379 3.6076154805198013" xyz="0.026822661312480456 0.7657070746088926 0.9703833558210094"/>
	</joint>
	<joint name="24_to_0" type="revolute">
		<parent link="0"/>
		<child link="24"/>
		<axis xyz="0 0 1"/>
		<limit effort="1" upper="-3.1415" lower="3.1415" velocity="1"/>
		<origin rpy="8.492888449428452 0.9050096959036379 3.6076154805198013" xyz="0.026822661312480456 0.7657070746088926 0.9703833558210094"/>
	</joint>
</robot>
