<robot name="pepe">
	<link name="0">
		<visual>
			<geometry>
				<cylinder length="0.35940935990721423" radius="0.10762790799951505"/>
			</geometry>
		</visual>
		<collision>
			<geometry>
				<cylinder length="0.35940935990721423" radius="0.10762790799951505"/>
			</geometry>
		</collision>
		<inertial>
			<mass value="0.013079437091548709"/>
			<inertia ixx="0.03" iyy="0.03" izz="0.03" ixy="0" ixz="0" iyx="0"/>
		</inertial>
	</link>
	<link name="11">
		<visual>
			<geometry>
				<cylinder length="0.00014309724393646306" radius="0.878015169482812"/>
			</geometry>
		</visual>
		<collision>
			<geometry>
				<cylinder length="0.00014309724393646306" radius="0.878015169482812"/>
			</geometry>
		</collision>
		<inertial>
			<mass value="0.000346565382932485"/>
			<inertia ixx="0.03" iyy="0.03" izz="0.03" ixy="0" ixz="0" iyx="0"/>
		</inertial>
	</link>
	<link name="22">
		<visual>
			<geometry>
				<cylinder length="0.6698241132036055" radius="0.20281904790217475"/>
			</geometry>
		</visual>
		<collision>
			<geometry>
				<cylinder length="0.6698241132036055" radius="0.20281904790217475"/>
			</geometry>
		</collision>
		<inertial>
			<mass value="0.08656216894796107"/>
			<inertia ixx="0.03" iyy="0.03" izz="0.03" ixy="0" ixz="0" iyx="0"/>
		</inertial>
	</link>
	<link name="33">
		<visual>
			<geometry>
				<cylinder length="0.6594143880653701" radius="0.7924739066722428"/>
			</geometry>
		</visual>
		<collision>
			<geometry>
				<cylinder length="0.6594143880653701" radius="0.7924739066722428"/>
			</geometry>
		</collision>
		<inertial>
			<mass value="1.3010028094564627"/>
			<inertia ixx="0.03" iyy="0.03" izz="0.03" ixy="0" ixz="0" iyx="0"/>
		</inertial>
	</link>
	<link name="34">
		<visual>
			<geometry>
				<cylinder length="0.6594143880653701" radius="0.7924739066722428"/>
			</geometry>
		</visual>
		<collision>
			<geometry>
				<cylinder length="0.6594143880653701" radius="0.7924739066722428"/>
			</geometry>
		</collision>
		<inertial>
			<mass value="1.3010028094564627"/>
			<inertia ixx="0.03" iyy="0.03" izz="0.03" ixy="0" ixz="0" iyx="0"/>
		</inertial>
	</link>
	<link name="35">
		<visual>
			<geometry>
				<cylinder length="0.6594143880653701" radius="0.7924739066722428"/>
			</geometry>
		</visual>
		<collision>
			<geometry>
				<cylinder length="0.6594143880653701" radius="0.7924739066722428"/>
			</geometry>
		</collision>
		<inertial>
			<mass value="1.3010028094564627"/>
			<inertia ixx="0.03" iyy="0.03" izz="0.03" ixy="0" ixz="0" iyx="0"/>
		</inertial>
	</link>
	<link name="26">
		<visual>
			<geometry>
				<cylinder length="0.6698241132036055" radius="0.20281904790217475"/>
			</geometry>
		</visual>
		<collision>
			<geometry>
				<cylinder length="0.6698241132036055" radius="0.20281904790217475"/>
			</geometry>
		</collision>
		<inertial>
			<mass value="0.08656216894796107"/>
			<inertia ixx="0.03" iyy="0.03" izz="0.03" ixy="0" ixz="0" iyx="0"/>
		</inertial>
	</link>
	<link name="37">
		<visual>
			<geometry>
				<cylinder length="0.6594143880653701" radius="0.7924739066722428"/>
			</geometry>
		</visual>
		<collision>
			<geometry>
				<cylinder length="0.6594143880653701" radius="0.7924739066722428"/>
			</geometry>
		</collision>
		<inertial>
			<mass value="1.3010028094564627"/>
			<inertia ixx="0.03" iyy="0.03" izz="0.03" ixy="0" ixz="0" iyx="0"/>
		</inertial>
	</link>
	<link name="38">
		<visual>
			<geometry>
				<cylinder length="0.6594143880653701" radius="0.7924739066722428"/>
			</geometry>
		</visual>
		<collision>
			<geometry>
				<cylinder length="0.6594143880653701" radius="0.7924739066722428"/>
			</geometry>
		</collision>
		<inertial>
			<mass value="1.3010028094564627"/>
			<inertia ixx="0.03" iyy="0.03" izz="0.03" ixy="0" ixz="0" iyx="0"/>
		</inertial>
	</link>
	<link name="39">
		<visual>
			<geometry>
				<cylinder length="0.6594143880653701" radius="0.7924739066722428"/>
			</geometry>
		</visual>
		<collision>
			<geometry>
				<cylinder length="0.6594143880653701" radius="0.7924739066722428"/>
			</geometry>
		</collision>
		<inertial>
			<mass value="1.3010028094564627"/>
			<inertia ixx="0.03" iyy="0.03" izz="0.03" ixy="0" ixz="0" iyx="0"/>
		</inertial>
	</link>
	<link name="210">
		<visual>
			<geometry>
				<cylinder length="0.6698241132036055" radius="0.20281904790217475"/>
			</geometry>
		</visual>
		<collision>
			<geometry>
				<cylinder length="0.6698241132036055" radius="0.20281904790217475"/>
			</geometry>
		</collision>
		<inertial>
			<mass value="0.08656216894796107"/>
			<inertia ixx="0.03" iyy="0.03" izz="0.03" ixy="0" ixz="0" iyx="0"/>
		</inertial>
	</link>
	<link name="311">
		<visual>
			<geometry>
				<cylinder length="0.6594143880653701" radius="0.7924739066722428"/>
			</geometry>
		</visual>
		<collision>
			<geometry>
				<cylinder length="0.6594143880653701" radius="0.7924739066722428"/>
			</geometry>
		</collision>
		<inertial>
			<mass value="1.3010028094564627"/>
			<inertia ixx="0.03" iyy="0.03" izz="0.03" ixy="0" ixz="0" iyx="0"/>
		</inertial>
	</link>
	<link name="312">
		<visual>
			<geometry>
				<cylinder length="0.6594143880653701" radius="0.7924739066722428"/>
			</geometry>
		</visual>
		<collision>
			<geometry>
				<cylinder length="0.6594143880653701" radius="0.7924739066722428"/>
			</geometry>
		</collision>
		<inertial>
			<mass value="1.3010028094564627"/>
			<inertia ixx="0.03" iyy="0.03" izz="0.03" ixy="0" ixz="0" iyx="0"/>
		</inertial>
	</link>
	<link name="313">
		<visual>
			<geometry>
				<cylinder length="0.6594143880653701" radius="0.7924739066722428"/>
			</geometry>
		</visual>
		<collision>
			<geometry>
				<cylinder length="0.6594143880653701" radius="0.7924739066722428"/>
			</geometry>
		</collision>
		<inertial>
			<mass value="1.3010028094564627"/>
			<inertia ixx="0.03" iyy="0.03" izz="0.03" ixy="0" ixz="0" iyx="0"/>
		</inertial>
	</link>
	<link name="214">
		<visual>
			<geometry>
				<cylinder length="0.6698241132036055" radius="0.20281904790217475"/>
			</geometry>
		</visual>
		<collision>
			<geometry>
				<cylinder length="0.6698241132036055" radius="0.20281904790217475"/>
			</geometry>
		</collision>
		<inertial>
			<mass value="0.08656216894796107"/>
			<inertia ixx="0.03" iyy="0.03" izz="0.03" ixy="0" ixz="0" iyx="0"/>
		</inertial>
	</link>
	<link name="315">
		<visual>
			<geometry>
				<cylinder length="0.6594143880653701" radius="0.7924739066722428"/>
			</geometry>
		</visual>
		<collision>
			<geometry>
				<cylinder length="0.6594143880653701" radius="0.7924739066722428"/>
			</geometry>
		</collision>
		<inertial>
			<mass value="1.3010028094564627"/>
			<inertia ixx="0.03" iyy="0.03" izz="0.03" ixy="0" ixz="0" iyx="0"/>
		</inertial>
	</link>
	<link name="316">
		<visual>
			<geometry>
				<cylinder length="0.6594143880653701" radius="0.7924739066722428"/>
			</geometry>
		</visual>
		<collision>
			<geometry>
				<cylinder length="0.6594143880653701" radius="0.7924739066722428"/>
			</geometry>
		</collision>
		<inertial>
			<mass value="1.3010028094564627"/>
			<inertia ixx="0.03" iyy="0.03" izz="0.03" ixy="0" ixz="0" iyx="0"/>
		</inertial>
	</link>
	<link name="317">
		<visual>
			<geometry>
				<cylinder length="0.6594143880653701" radius="0.7924739066722428"/>
			</geometry>
		</visual>
		<collision>
			<geometry>
				<cylinder length="0.6594143880653701" radius="0.7924739066722428"/>
			</geometry>
		</collision>
		<inertial>
			<mass value="1.3010028094564627"/>
			<inertia ixx="0.03" iyy="0.03" izz="0.03" ixy="0" ixz="0" iyx="0"/>
		</inertial>
	</link>
	<joint name="11_to_0" type="revolute">
		<parent link="0"/>
		<child link="11"/>
		<axis xyz="1 0 0"/>
		<limit effort="1" upper="-3.1415" lower="3.1415" velocity="1"/>
		<origin rpy="0.14649725603420974 4.846653697982699 5.321823417325937" xyz="0.14857603399565733 0.850922854525532 0.8784038689011624"/>
	</joint>
	<joint name="22_to_11" type="revolute">
		<parent link="11"/>
		<child link="22"/>
		<axis xyz="0 0 1"/>
		<limit effort="1" upper="-3.1415" lower="3.1415" velocity="1"/>
		<origin rpy="0.7445599795989941 2.753265867417977 0.13256535444230305" xyz="0.6462597085189629 0.8247703460954684 0.3225897180783439"/>
	</joint>
	<joint name="33_to_22" type="revolute">
		<parent link="22"/>
		<child link="33"/>
		<axis xyz="0 0 1"/>
		<limit effort="1" upper="-3.1415" lower="3.1415" velocity="1"/>
		<origin rpy="5.69284500720614 6.231285609868876 1.6356365506562816" xyz="0.21244740337731205 0.30963795507434566 0.7532611592364375"/>
	</joint>
	<joint name="34_to_22" type="revolute">
		<parent link="22"/>
		<child link="34"/>
		<axis xyz="0 0 1"/>
		<limit effort="1" upper="-3.1415" lower="3.1415" velocity="1"/>
		<origin rpy="8.53926751080921 6.231285609868876 1.6356365506562816" xyz="0.21244740337731205 0.30963795507434566 0.7532611592364375"/>
	</joint>
	<joint name="35_to_22" type="revolute">
		<parent link="22"/>
		<child link="35"/>
		<axis xyz="0 0 1"/>
		<limit effort="1" upper="-3.1415" lower="3.1415" velocity="1"/>
		<origin rpy="11.38569001441228 6.231285609868876 1.6356365506562816" xyz="0.21244740337731205 0.30963795507434566 0.7532611592364375"/>
	</joint>
	<joint name="26_to_11" type="revolute">
		<parent link="11"/>
		<child link="26"/>
		<axis xyz="0 0 1"/>
		<limit effort="1" upper="-3.1415" lower="3.1415" velocity="1"/>
		<origin rpy="1.1168399693984912 2.753265867417977 0.13256535444230305" xyz="0.6462597085189629 0.8247703460954684 0.3225897180783439"/>
	</joint>
	<joint name="37_to_26" type="revolute">
		<parent link="26"/>
		<child link="37"/>
		<axis xyz="0 0 1"/>
		<limit effort="1" upper="-3.1415" lower="3.1415" velocity="1"/>
		<origin rpy="5.69284500720614 6.231285609868876 1.6356365506562816" xyz="0.21244740337731205 0.30963795507434566 0.7532611592364375"/>
	</joint>
	<joint name="38_to_26" type="revolute">
		<parent link="26"/>
		<child link="38"/>
		<axis xyz="0 0 1"/>
		<limit effort="1" upper="-3.1415" lower="3.1415" velocity="1"/>
		<origin rpy="8.53926751080921 6.231285609868876 1.6356365506562816" xyz="0.21244740337731205 0.30963795507434566 0.7532611592364375"/>
	</joint>
	<joint name="39_to_26" type="revolute">
		<parent link="26"/>
		<child link="39"/>
		<axis xyz="0 0 1"/>
		<limit effort="1" upper="-3.1415" lower="3.1415" velocity="1"/>
		<origin rpy="11.38569001441228 6.231285609868876 1.6356365506562816" xyz="0.21244740337731205 0.30963795507434566 0.7532611592364375"/>
	</joint>
	<joint name="210_to_11" type="revolute">
		<parent link="11"/>
		<child link="210"/>
		<axis xyz="0 0 1"/>
		<limit effort="1" upper="-3.1415" lower="3.1415" velocity="1"/>
		<origin rpy="1.4891199591979882 2.753265867417977 0.13256535444230305" xyz="0.6462597085189629 0.8247703460954684 0.3225897180783439"/>
	</joint>
	<joint name="311_to_210" type="revolute">
		<parent link="210"/>
		<child link="311"/>
		<axis xyz="0 0 1"/>
		<limit effort="1" upper="-3.1415" lower="3.1415" velocity="1"/>
		<origin rpy="5.69284500720614 6.231285609868876 1.6356365506562816" xyz="0.21244740337731205 0.30963795507434566 0.7532611592364375"/>
	</joint>
	<joint name="312_to_210" type="revolute">
		<parent link="210"/>
		<child link="312"/>
		<axis xyz="0 0 1"/>
		<limit effort="1" upper="-3.1415" lower="3.1415" velocity="1"/>
		<origin rpy="8.53926751080921 6.231285609868876 1.6356365506562816" xyz="0.21244740337731205 0.30963795507434566 0.7532611592364375"/>
	</joint>
	<joint name="313_to_210" type="revolute">
		<parent link="210"/>
		<child link="313"/>
		<axis xyz="0 0 1"/>
		<limit effort="1" upper="-3.1415" lower="3.1415" velocity="1"/>
		<origin rpy="11.38569001441228 6.231285609868876 1.6356365506562816" xyz="0.21244740337731205 0.30963795507434566 0.7532611592364375"/>
	</joint>
	<joint name="214_to_11" type="revolute">
		<parent link="11"/>
		<child link="214"/>
		<axis xyz="0 0 1"/>
		<limit effort="1" upper="-3.1415" lower="3.1415" velocity="1"/>
		<origin rpy="1.8613999489974853 2.753265867417977 0.13256535444230305" xyz="0.6462597085189629 0.8247703460954684 0.3225897180783439"/>
	</joint>
	<joint name="315_to_214" type="revolute">
		<parent link="214"/>
		<child link="315"/>
		<axis xyz="0 0 1"/>
		<limit effort="1" upper="-3.1415" lower="3.1415" velocity="1"/>
		<origin rpy="5.69284500720614 6.231285609868876 1.6356365506562816" xyz="0.21244740337731205 0.30963795507434566 0.7532611592364375"/>
	</joint>
	<joint name="316_to_214" type="revolute">
		<parent link="214"/>
		<child link="316"/>
		<axis xyz="0 0 1"/>
		<limit effort="1" upper="-3.1415" lower="3.1415" velocity="1"/>
		<origin rpy="8.53926751080921 6.231285609868876 1.6356365506562816" xyz="0.21244740337731205 0.30963795507434566 0.7532611592364375"/>
	</joint>
	<joint name="317_to_214" type="revolute">
		<parent link="214"/>
		<child link="317"/>
		<axis xyz="0 0 1"/>
		<limit effort="1" upper="-3.1415" lower="3.1415" velocity="1"/>
		<origin rpy="11.38569001441228 6.231285609868876 1.6356365506562816" xyz="0.21244740337731205 0.30963795507434566 0.7532611592364375"/>
	</joint>
</robot>
