<robot name="pepe">
	<link name="0">
		<visual>
			<geometry>
				<cylinder length="0.15435591176167718" radius="0.2994062127368676"/>
			</geometry>
		</visual>
		<collision>
			<geometry>
				<cylinder length="0.15435591176167718" radius="0.2994062127368676"/>
			</geometry>
		</collision>
		<inertial>
			<mass value="0.04347051203192725"/>
			<inertia ixx="0.03" iyy="0.03" izz="0.03" ixy="0" ixz="0" iyx="0"/>
		</inertial>
	</link>
	<link name="11">
		<visual>
			<geometry>
				<cylinder length="0.27814994112326397" radius="0.07639857056478638"/>
			</geometry>
		</visual>
		<collision>
			<geometry>
				<cylinder length="0.27814994112326397" radius="0.07639857056478638"/>
			</geometry>
		</collision>
		<inertial>
			<mass value="0.005100342146141253"/>
			<inertia ixx="0.03" iyy="0.03" izz="0.03" ixy="0" ixz="0" iyx="0"/>
		</inertial>
	</link>
	<link name="22">
		<visual>
			<geometry>
				<cylinder length="0.21209830246423322" radius="0.7945834176377092"/>
			</geometry>
		</visual>
		<collision>
			<geometry>
				<cylinder length="0.21209830246423322" radius="0.7945834176377092"/>
			</geometry>
		</collision>
		<inertial>
			<mass value="0.4206937501478465"/>
			<inertia ixx="0.03" iyy="0.03" izz="0.03" ixy="0" ixz="0" iyx="0"/>
		</inertial>
	</link>
	<link name="23">
		<visual>
			<geometry>
				<cylinder length="0.21209830246423322" radius="0.7945834176377092"/>
			</geometry>
		</visual>
		<collision>
			<geometry>
				<cylinder length="0.21209830246423322" radius="0.7945834176377092"/>
			</geometry>
		</collision>
		<inertial>
			<mass value="0.4206937501478465"/>
			<inertia ixx="0.03" iyy="0.03" izz="0.03" ixy="0" ixz="0" iyx="0"/>
		</inertial>
	</link>
	<link name="24">
		<visual>
			<geometry>
				<cylinder length="0.21209830246423322" radius="0.7945834176377092"/>
			</geometry>
		</visual>
		<collision>
			<geometry>
				<cylinder length="0.21209830246423322" radius="0.7945834176377092"/>
			</geometry>
		</collision>
		<inertial>
			<mass value="0.4206937501478465"/>
			<inertia ixx="0.03" iyy="0.03" izz="0.03" ixy="0" ixz="0" iyx="0"/>
		</inertial>
	</link>
	<link name="25">
		<visual>
			<geometry>
				<cylinder length="0.21209830246423322" radius="0.7945834176377092"/>
			</geometry>
		</visual>
		<collision>
			<geometry>
				<cylinder length="0.21209830246423322" radius="0.7945834176377092"/>
			</geometry>
		</collision>
		<inertial>
			<mass value="0.4206937501478465"/>
			<inertia ixx="0.03" iyy="0.03" izz="0.03" ixy="0" ixz="0" iyx="0"/>
		</inertial>
	</link>
	<joint name="11_to_0" type="revolute">
		<parent link="0"/>
		<child link="11"/>
		<axis xyz="0 1 0"/>
		<limit effort="1" upper="-3.1415" lower="3.1415" velocity="1"/>
		<origin rpy="5.408803134057071 5.637893656869307 2.729294022443484" xyz="0.7521023326004612 0.9480186651090544 0.7629739683307908"/>
	</joint>
	<joint name="22_to_11" type="revolute">
		<parent link="11"/>
		<child link="22"/>
		<axis xyz="0 1 0"/>
		<limit effort="1" upper="-3.1415" lower="3.1415" velocity="1"/>
		<origin rpy="1.5527121510212911 1.3080765871031113 0.5697859125288693" xyz="0.08641685938415444 0.6006357600063799 0.3535584227296037"/>
	</joint>
	<joint name="23_to_11" type="revolute">
		<parent link="11"/>
		<child link="23"/>
		<axis xyz="0 1 0"/>
		<limit effort="1" upper="-3.1415" lower="3.1415" velocity="1"/>
		<origin rpy="2.3290682265319367 1.3080765871031113 0.5697859125288693" xyz="0.08641685938415444 0.6006357600063799 0.3535584227296037"/>
	</joint>
	<joint name="24_to_11" type="revolute">
		<parent link="11"/>
		<child link="24"/>
		<axis xyz="0 1 0"/>
		<limit effort="1" upper="-3.1415" lower="3.1415" velocity="1"/>
		<origin rpy="3.1054243020425822 1.3080765871031113 0.5697859125288693" xyz="0.08641685938415444 0.6006357600063799 0.3535584227296037"/>
	</joint>
	<joint name="25_to_11" type="revolute">
		<parent link="11"/>
		<child link="25"/>
		<axis xyz="0 1 0"/>
		<limit effort="1" upper="-3.1415" lower="3.1415" velocity="1"/>
		<origin rpy="3.881780377553228 1.3080765871031113 0.5697859125288693" xyz="0.08641685938415444 0.6006357600063799 0.3535584227296037"/>
	</joint>
</robot>
