<robot name="pepe">
	<link name="0">
		<visual>
			<geometry>
				<cylinder length="0.35940935990721423" radius="0.10762790799951505"/>
			</geometry>
		</visual>
		<collision>
			<geometry>
				<cylinder length="0.35940935990721423" radius="0.10762790799951505"/>
			</geometry>
		</collision>
		<inertial>
			<mass value="0.013079437091548709"/>
			<inertia ixx="0.03" iyy="0.03" izz="0.03" ixy="0" ixz="0" iyx="0"/>
		</inertial>
	</link>
	<link name="11">
		<visual>
			<geometry>
				<cylinder length="0.00014309724393646306" radius="0.878015169482812"/>
			</geometry>
		</visual>
		<collision>
			<geometry>
				<cylinder length="0.00014309724393646306" radius="0.878015169482812"/>
			</geometry>
		</collision>
		<inertial>
			<mass value="0.000346565382932485"/>
			<inertia ixx="0.03" iyy="0.03" izz="0.03" ixy="0" ixz="0" iyx="0"/>
		</inertial>
	</link>
	<link name="22">
		<visual>
			<geometry>
				<cylinder length="0.6698241132036055" radius="0.20281904790217475"/>
			</geometry>
		</visual>
		<collision>
			<geometry>
				<cylinder length="0.6698241132036055" radius="0.20281904790217475"/>
			</geometry>
		</collision>
		<inertial>
			<mass value="0.08656216894796107"/>
			<inertia ixx="0.03" iyy="0.03" izz="0.03" ixy="0" ixz="0" iyx="0"/>
		</inertial>
	</link>
	<link name="23">
		<visual>
			<geometry>
				<cylinder length="0.6698241132036055" radius="0.20281904790217475"/>
			</geometry>
		</visual>
		<collision>
			<geometry>
				<cylinder length="0.6698241132036055" radius="0.20281904790217475"/>
			</geometry>
		</collision>
		<inertial>
			<mass value="0.08656216894796107"/>
			<inertia ixx="0.03" iyy="0.03" izz="0.03" ixy="0" ixz="0" iyx="0"/>
		</inertial>
	</link>
	<link name="24">
		<visual>
			<geometry>
				<cylinder length="0.6698241132036055" radius="0.20281904790217475"/>
			</geometry>
		</visual>
		<collision>
			<geometry>
				<cylinder length="0.6698241132036055" radius="0.20281904790217475"/>
			</geometry>
		</collision>
		<inertial>
			<mass value="0.08656216894796107"/>
			<inertia ixx="0.03" iyy="0.03" izz="0.03" ixy="0" ixz="0" iyx="0"/>
		</inertial>
	</link>
	<link name="25">
		<visual>
			<geometry>
				<cylinder length="0.6698241132036055" radius="0.20281904790217475"/>
			</geometry>
		</visual>
		<collision>
			<geometry>
				<cylinder length="0.6698241132036055" radius="0.20281904790217475"/>
			</geometry>
		</collision>
		<inertial>
			<mass value="0.08656216894796107"/>
			<inertia ixx="0.03" iyy="0.03" izz="0.03" ixy="0" ixz="0" iyx="0"/>
		</inertial>
	</link>
	<joint name="11_to_0" type="revolute">
		<parent link="0"/>
		<child link="11"/>
		<axis xyz="1 0 0"/>
		<limit effort="1" upper="-3.1415" lower="3.1415" velocity="1"/>
		<origin rpy="0.14649725603420974 4.846653697982699 5.321823417325937" xyz="0.006344866733315244 0.850922854525532 0.8784038689011624"/>
	</joint>
	<joint name="22_to_11" type="revolute">
		<parent link="11"/>
		<child link="22"/>
		<axis xyz="0 0 1"/>
		<limit effort="1" upper="-3.1415" lower="3.1415" velocity="1"/>
		<origin rpy="0.7445599795989941 2.753265867417977 0.13256535444230305" xyz="0.6462597085189629 0.8247703460954684 0.3225897180783439"/>
	</joint>
	<joint name="23_to_11" type="revolute">
		<parent link="11"/>
		<child link="23"/>
		<axis xyz="0 0 1"/>
		<limit effort="1" upper="-3.1415" lower="3.1415" velocity="1"/>
		<origin rpy="1.1168399693984912 2.753265867417977 0.13256535444230305" xyz="0.6462597085189629 0.8247703460954684 0.3225897180783439"/>
	</joint>
	<joint name="24_to_11" type="revolute">
		<parent link="11"/>
		<child link="24"/>
		<axis xyz="0 0 1"/>
		<limit effort="1" upper="-3.1415" lower="3.1415" velocity="1"/>
		<origin rpy="1.4891199591979882 2.753265867417977 0.13256535444230305" xyz="0.6462597085189629 0.8247703460954684 0.3225897180783439"/>
	</joint>
	<joint name="25_to_11" type="revolute">
		<parent link="11"/>
		<child link="25"/>
		<axis xyz="0 0 1"/>
		<limit effort="1" upper="-3.1415" lower="3.1415" velocity="1"/>
		<origin rpy="1.8613999489974853 2.753265867417977 0.13256535444230305" xyz="0.6462597085189629 0.8247703460954684 0.3225897180783439"/>
	</joint>
</robot>
