<robot name="pepe">
	<link name="0">
		<visual>
			<geometry>
				<cylinder length="0.4090045134946908" radius="0.6746196692928174"/>
			</geometry>
		</visual>
		<collision>
			<geometry>
				<cylinder length="0.4090045134946908" radius="0.6746196692928174"/>
			</geometry>
		</collision>
		<inertial>
			<mass value="0.5847846604400668"/>
			<inertia ixx="0.03" iyy="0.03" izz="0.03" ixy="0" ixz="0" iyx="0"/>
		</inertial>
	</link>
	<link name="11">
		<visual>
			<geometry>
				<cylinder length="0.637638808771346" radius="0.5788750892855647"/>
			</geometry>
		</visual>
		<collision>
			<geometry>
				<cylinder length="0.637638808771346" radius="0.5788750892855647"/>
			</geometry>
		</collision>
		<inertial>
			<mass value="0.6712655145949162"/>
			<inertia ixx="0.03" iyy="0.03" izz="0.03" ixy="0" ixz="0" iyx="0"/>
		</inertial>
	</link>
	<link name="12">
		<visual>
			<geometry>
				<cylinder length="0.637638808771346" radius="0.5788750892855647"/>
			</geometry>
		</visual>
		<collision>
			<geometry>
				<cylinder length="0.637638808771346" radius="0.5788750892855647"/>
			</geometry>
		</collision>
		<inertial>
			<mass value="0.6712655145949162"/>
			<inertia ixx="0.03" iyy="0.03" izz="0.03" ixy="0" ixz="0" iyx="0"/>
		</inertial>
	</link>
	<link name="23">
		<visual>
			<geometry>
				<cylinder length="0.6893211687453101" radius="0.9622298383937432"/>
			</geometry>
		</visual>
		<collision>
			<geometry>
				<cylinder length="0.6893211687453101" radius="0.9622298383937432"/>
			</geometry>
		</collision>
		<inertial>
			<mass value="2.0050681046279117"/>
			<inertia ixx="0.03" iyy="0.03" izz="0.03" ixy="0" ixz="0" iyx="0"/>
		</inertial>
	</link>
	<link name="24">
		<visual>
			<geometry>
				<cylinder length="0.6893211687453101" radius="0.9622298383937432"/>
			</geometry>
		</visual>
		<collision>
			<geometry>
				<cylinder length="0.6893211687453101" radius="0.9622298383937432"/>
			</geometry>
		</collision>
		<inertial>
			<mass value="2.0050681046279117"/>
			<inertia ixx="0.03" iyy="0.03" izz="0.03" ixy="0" ixz="0" iyx="0"/>
		</inertial>
	</link>
	<link name="25">
		<visual>
			<geometry>
				<cylinder length="0.6893211687453101" radius="0.9622298383937432"/>
			</geometry>
		</visual>
		<collision>
			<geometry>
				<cylinder length="0.6893211687453101" radius="0.9622298383937432"/>
			</geometry>
		</collision>
		<inertial>
			<mass value="2.0050681046279117"/>
			<inertia ixx="0.03" iyy="0.03" izz="0.03" ixy="0" ixz="0" iyx="0"/>
		</inertial>
	</link>
	<link name="26">
		<visual>
			<geometry>
				<cylinder length="0.6893211687453101" radius="0.9622298383937432"/>
			</geometry>
		</visual>
		<collision>
			<geometry>
				<cylinder length="0.6893211687453101" radius="0.9622298383937432"/>
			</geometry>
		</collision>
		<inertial>
			<mass value="2.0050681046279117"/>
			<inertia ixx="0.03" iyy="0.03" izz="0.03" ixy="0" ixz="0" iyx="0"/>
		</inertial>
	</link>
	<joint name="11_to_0" type="revolute">
		<parent link="0"/>
		<child link="11"/>
		<axis xyz="0 1 0"/>
		<limit effort="1" upper="-3.1415" lower="3.1415" velocity="1"/>
		<origin rpy="3.737570177931551 3.414411235914689 5.490238915458134" xyz="0.6900897530161155 0.5076701787930972 0.795419965552044"/>
	</joint>
	<joint name="12_to_0" type="revolute">
		<parent link="0"/>
		<child link="12"/>
		<axis xyz="0 1 0"/>
		<limit effort="1" upper="-3.1415" lower="3.1415" velocity="1"/>
		<origin rpy="5.606355266897326 3.414411235914689 5.490238915458134" xyz="0.6900897530161155 0.5076701787930972 0.795419965552044"/>
	</joint>
	<joint name="23_to_0" type="revolute">
		<parent link="0"/>
		<child link="23"/>
		<axis xyz="0 1 0"/>
		<limit effort="1" upper="-3.1415" lower="3.1415" velocity="1"/>
		<origin rpy="20.08566481352396 0.25339753699709533 2.2338164889001972" xyz="0.7089214976795559 0.9119129134753976 0.9739570469538621"/>
	</joint>
	<joint name="24_to_0" type="revolute">
		<parent link="0"/>
		<child link="24"/>
		<axis xyz="0 1 0"/>
		<limit effort="1" upper="-3.1415" lower="3.1415" velocity="1"/>
		<origin rpy="25.10708101690495 0.25339753699709533 2.2338164889001972" xyz="0.7089214976795559 0.9119129134753976 0.9739570469538621"/>
	</joint>
	<joint name="25_to_0" type="revolute">
		<parent link="0"/>
		<child link="25"/>
		<axis xyz="0 1 0"/>
		<limit effort="1" upper="-3.1415" lower="3.1415" velocity="1"/>
		<origin rpy="30.128497220285936 0.25339753699709533 2.2338164889001972" xyz="0.7089214976795559 0.9119129134753976 0.9739570469538621"/>
	</joint>
	<joint name="26_to_0" type="revolute">
		<parent link="0"/>
		<child link="26"/>
		<axis xyz="0 1 0"/>
		<limit effort="1" upper="-3.1415" lower="3.1415" velocity="1"/>
		<origin rpy="35.14991342366693 0.25339753699709533 2.2338164889001972" xyz="0.7089214976795559 0.9119129134753976 0.9739570469538621"/>
	</joint>
</robot>
