<robot name="pepe">
	<link name="0">
		<visual>
			<geometry>
				<cylinder length="0.35940935990721423" radius="0.10762790799951505"/>
			</geometry>
		</visual>
		<collision>
			<geometry>
				<cylinder length="0.35940935990721423" radius="0.10762790799951505"/>
			</geometry>
		</collision>
		<inertial>
			<mass value="0.013079437091548709"/>
			<inertia ixx="0.03" iyy="0.03" izz="0.03" ixy="0" ixz="0" iyx="0"/>
		</inertial>
	</link>
	<link name="11">
		<visual>
			<geometry>
				<cylinder length="0.00014309724393646306" radius="0.878015169482812"/>
			</geometry>
		</visual>
		<collision>
			<geometry>
				<cylinder length="0.00014309724393646306" radius="0.878015169482812"/>
			</geometry>
		</collision>
		<inertial>
			<mass value="0.000346565382932485"/>
			<inertia ixx="0.03" iyy="0.03" izz="0.03" ixy="0" ixz="0" iyx="0"/>
		</inertial>
	</link>
	<link name="22">
		<visual>
			<geometry>
				<cylinder length="0.5885490024600376" radius="0.774072067857943"/>
			</geometry>
		</visual>
		<collision>
			<geometry>
				<cylinder length="0.5885490024600376" radius="0.774072067857943"/>
			</geometry>
		</collision>
		<inertial>
			<mass value="1.1078865586730096"/>
			<inertia ixx="0.03" iyy="0.03" izz="0.03" ixy="0" ixz="0" iyx="0"/>
		</inertial>
	</link>
	<link name="23">
		<visual>
			<geometry>
				<cylinder length="0.5885490024600376" radius="0.774072067857943"/>
			</geometry>
		</visual>
		<collision>
			<geometry>
				<cylinder length="0.5885490024600376" radius="0.774072067857943"/>
			</geometry>
		</collision>
		<inertial>
			<mass value="1.1078865586730096"/>
			<inertia ixx="0.03" iyy="0.03" izz="0.03" ixy="0" ixz="0" iyx="0"/>
		</inertial>
	</link>
	<link name="24">
		<visual>
			<geometry>
				<cylinder length="0.5885490024600376" radius="0.774072067857943"/>
			</geometry>
		</visual>
		<collision>
			<geometry>
				<cylinder length="0.5885490024600376" radius="0.774072067857943"/>
			</geometry>
		</collision>
		<inertial>
			<mass value="1.1078865586730096"/>
			<inertia ixx="0.03" iyy="0.03" izz="0.03" ixy="0" ixz="0" iyx="0"/>
		</inertial>
	</link>
	<link name="25">
		<visual>
			<geometry>
				<cylinder length="0.5885490024600376" radius="0.774072067857943"/>
			</geometry>
		</visual>
		<collision>
			<geometry>
				<cylinder length="0.5885490024600376" radius="0.774072067857943"/>
			</geometry>
		</collision>
		<inertial>
			<mass value="1.1078865586730096"/>
			<inertia ixx="0.03" iyy="0.03" izz="0.03" ixy="0" ixz="0" iyx="0"/>
		</inertial>
	</link>
	<link name="36">
		<visual>
			<geometry>
				<cylinder length="0.6698241132036055" radius="0.20281904790217475"/>
			</geometry>
		</visual>
		<collision>
			<geometry>
				<cylinder length="0.6698241132036055" radius="0.20281904790217475"/>
			</geometry>
		</collision>
		<inertial>
			<mass value="0.08656216894796107"/>
			<inertia ixx="0.03" iyy="0.03" izz="0.03" ixy="0" ixz="0" iyx="0"/>
		</inertial>
	</link>
	<link name="37">
		<visual>
			<geometry>
				<cylinder length="0.6698241132036055" radius="0.20281904790217475"/>
			</geometry>
		</visual>
		<collision>
			<geometry>
				<cylinder length="0.6698241132036055" radius="0.20281904790217475"/>
			</geometry>
		</collision>
		<inertial>
			<mass value="0.08656216894796107"/>
			<inertia ixx="0.03" iyy="0.03" izz="0.03" ixy="0" ixz="0" iyx="0"/>
		</inertial>
	</link>
	<link name="38">
		<visual>
			<geometry>
				<cylinder length="0.6698241132036055" radius="0.20281904790217475"/>
			</geometry>
		</visual>
		<collision>
			<geometry>
				<cylinder length="0.6698241132036055" radius="0.20281904790217475"/>
			</geometry>
		</collision>
		<inertial>
			<mass value="0.08656216894796107"/>
			<inertia ixx="0.03" iyy="0.03" izz="0.03" ixy="0" ixz="0" iyx="0"/>
		</inertial>
	</link>
	<link name="39">
		<visual>
			<geometry>
				<cylinder length="0.6698241132036055" radius="0.20281904790217475"/>
			</geometry>
		</visual>
		<collision>
			<geometry>
				<cylinder length="0.6698241132036055" radius="0.20281904790217475"/>
			</geometry>
		</collision>
		<inertial>
			<mass value="0.08656216894796107"/>
			<inertia ixx="0.03" iyy="0.03" izz="0.03" ixy="0" ixz="0" iyx="0"/>
		</inertial>
	</link>
	<joint name="11_to_0" type="revolute">
		<parent link="0"/>
		<child link="11"/>
		<axis xyz="1 0 0"/>
		<limit effort="1" upper="-3.1415" lower="3.1415" velocity="1"/>
		<origin rpy="0.14649725603420974 4.846653697982699 5.321823417325937" xyz="0.14857603399565733 0.850922854525532 0.8784038689011624"/>
	</joint>
	<joint name="22_to_11" type="revolute">
		<parent link="11"/>
		<child link="22"/>
		<axis xyz="0 0 1"/>
		<limit effort="1" upper="-3.1415" lower="3.1415" velocity="1"/>
		<origin rpy="3.187479884946322 0.5826987100304208 1.9187399681391597" xyz="0.7174258218115571 0.9241630040425354 0.6345313651243545"/>
	</joint>
	<joint name="23_to_11" type="revolute">
		<parent link="11"/>
		<child link="23"/>
		<axis xyz="0 0 1"/>
		<limit effort="1" upper="-3.1415" lower="3.1415" velocity="1"/>
		<origin rpy="4.781219827419483 0.5826987100304208 1.9187399681391597" xyz="0.7174258218115571 0.9241630040425354 0.6345313651243545"/>
	</joint>
	<joint name="24_to_11" type="revolute">
		<parent link="11"/>
		<child link="24"/>
		<axis xyz="0 0 1"/>
		<limit effort="1" upper="-3.1415" lower="3.1415" velocity="1"/>
		<origin rpy="6.374959769892644 0.5826987100304208 1.9187399681391597" xyz="0.7174258218115571 0.9241630040425354 0.6345313651243545"/>
	</joint>
	<joint name="25_to_11" type="revolute">
		<parent link="11"/>
		<child link="25"/>
		<axis xyz="0 0 1"/>
		<limit effort="1" upper="-3.1415" lower="3.1415" velocity="1"/>
		<origin rpy="7.968699712365805 0.5826987100304208 1.9187399681391597" xyz="0.7174258218115571 0.9241630040425354 0.6345313651243545"/>
	</joint>
	<joint name="36_to_11" type="revolute">
		<parent link="11"/>
		<child link="36"/>
		<axis xyz="0 0 1"/>
		<limit effort="1" upper="-3.1415" lower="3.1415" velocity="1"/>
		<origin rpy="2.2336799387969823 2.753265867417977 0.13256535444230305" xyz="0.6462597085189629 0.8247703460954684 0.3225897180783439"/>
	</joint>
	<joint name="37_to_11" type="revolute">
		<parent link="11"/>
		<child link="37"/>
		<axis xyz="0 0 1"/>
		<limit effort="1" upper="-3.1415" lower="3.1415" velocity="1"/>
		<origin rpy="2.605959928596479 2.753265867417977 0.13256535444230305" xyz="0.6462597085189629 0.8247703460954684 0.3225897180783439"/>
	</joint>
	<joint name="38_to_11" type="revolute">
		<parent link="11"/>
		<child link="38"/>
		<axis xyz="0 0 1"/>
		<limit effort="1" upper="-3.1415" lower="3.1415" velocity="1"/>
		<origin rpy="2.9782399183959765 2.753265867417977 0.13256535444230305" xyz="0.6462597085189629 0.8247703460954684 0.3225897180783439"/>
	</joint>
	<joint name="39_to_11" type="revolute">
		<parent link="11"/>
		<child link="39"/>
		<axis xyz="0 0 1"/>
		<limit effort="1" upper="-3.1415" lower="3.1415" velocity="1"/>
		<origin rpy="3.3505199081954737 2.753265867417977 0.13256535444230305" xyz="0.6462597085189629 0.8247703460954684 0.3225897180783439"/>
	</joint>
</robot>
