<robot name="pepe">
	<link name="0">
		<visual>
			<geometry>
				<cylinder length="0.016136948851283806" radius="0.41870879207200407"/>
			</geometry>
		</visual>
		<collision>
			<geometry>
				<cylinder length="0.016136948851283806" radius="0.41870879207200407"/>
			</geometry>
		</collision>
		<inertial>
			<mass value="0.008887824201159696"/>
			<inertia ixx="0.03" iyy="0.03" izz="0.03" ixy="0" ixz="0" iyx="0"/>
		</inertial>
	</link>
	<link name="11">
		<visual>
			<geometry>
				<cylinder length="0.18959202448349888" radius="0.7669901686478788"/>
			</geometry>
		</visual>
		<collision>
			<geometry>
				<cylinder length="0.18959202448349888" radius="0.7669901686478788"/>
			</geometry>
		</collision>
		<inertial>
			<mass value="0.3503882476091541"/>
			<inertia ixx="0.03" iyy="0.03" izz="0.03" ixy="0" ixz="0" iyx="0"/>
		</inertial>
	</link>
	<link name="12">
		<visual>
			<geometry>
				<cylinder length="0.18959202448349888" radius="0.7669901686478788"/>
			</geometry>
		</visual>
		<collision>
			<geometry>
				<cylinder length="0.18959202448349888" radius="0.7669901686478788"/>
			</geometry>
		</collision>
		<inertial>
			<mass value="0.3503882476091541"/>
			<inertia ixx="0.03" iyy="0.03" izz="0.03" ixy="0" ixz="0" iyx="0"/>
		</inertial>
	</link>
	<link name="23">
		<visual>
			<geometry>
				<cylinder length="0.3820965905006577" radius="0.08797632819885409"/>
			</geometry>
		</visual>
		<collision>
			<geometry>
				<cylinder length="0.3820965905006577" radius="0.08797632819885409"/>
			</geometry>
		</collision>
		<inertial>
			<mass value="0.009290833977696132"/>
			<inertia ixx="0.03" iyy="0.03" izz="0.03" ixy="0" ixz="0" iyx="0"/>
		</inertial>
	</link>
	<link name="24">
		<visual>
			<geometry>
				<cylinder length="0.3820965905006577" radius="0.08797632819885409"/>
			</geometry>
		</visual>
		<collision>
			<geometry>
				<cylinder length="0.3820965905006577" radius="0.08797632819885409"/>
			</geometry>
		</collision>
		<inertial>
			<mass value="0.009290833977696132"/>
			<inertia ixx="0.03" iyy="0.03" izz="0.03" ixy="0" ixz="0" iyx="0"/>
		</inertial>
	</link>
	<link name="25">
		<visual>
			<geometry>
				<cylinder length="0.3820965905006577" radius="0.08797632819885409"/>
			</geometry>
		</visual>
		<collision>
			<geometry>
				<cylinder length="0.3820965905006577" radius="0.08797632819885409"/>
			</geometry>
		</collision>
		<inertial>
			<mass value="0.009290833977696132"/>
			<inertia ixx="0.03" iyy="0.03" izz="0.03" ixy="0" ixz="0" iyx="0"/>
		</inertial>
	</link>
	<joint name="11_to_0" type="revolute">
		<parent link="0"/>
		<child link="11"/>
		<axis xyz="0 0 1"/>
		<limit effort="1" upper="-3.1415" lower="3.1415" velocity="1"/>
		<origin rpy="2.8323644764938667 1.293594387544998 2.9678389505507834" xyz="0.15986039852037626 0.89154775402469 0.8579656493726011"/>
	</joint>
	<joint name="12_to_0" type="revolute">
		<parent link="0"/>
		<child link="12"/>
		<axis xyz="0 0 1"/>
		<limit effort="1" upper="-3.1415" lower="3.1415" velocity="1"/>
		<origin rpy="4.2485467147408 1.293594387544998 2.9678389505507834" xyz="0.15986039852037626 0.89154775402469 0.8579656493726011"/>
	</joint>
	<joint name="23_to_0" type="revolute">
		<parent link="0"/>
		<child link="23"/>
		<axis xyz="0 0 1"/>
		<limit effort="1" upper="-3.1415" lower="3.1415" velocity="1"/>
		<origin rpy="11.044730016460337 4.45914966589873 1.0604263560398164" xyz="0.052269880848787253 0.8061694095075347 0.4089083237316975"/>
	</joint>
	<joint name="24_to_0" type="revolute">
		<parent link="0"/>
		<child link="24"/>
		<axis xyz="0 0 1"/>
		<limit effort="1" upper="-3.1415" lower="3.1415" velocity="1"/>
		<origin rpy="13.80591252057542 4.45914966589873 1.0604263560398164" xyz="0.052269880848787253 0.8061694095075347 0.4089083237316975"/>
	</joint>
	<joint name="25_to_0" type="revolute">
		<parent link="0"/>
		<child link="25"/>
		<axis xyz="0 0 1"/>
		<limit effort="1" upper="-3.1415" lower="3.1415" velocity="1"/>
		<origin rpy="16.567095024690506 4.45914966589873 1.0604263560398164" xyz="0.052269880848787253 0.8061694095075347 0.4089083237316975"/>
	</joint>
</robot>
