<robot name="pepe">
	<link name="0">
		<visual>
			<geometry>
				<cylinder length="0.2200615809877765" radius="0.2761654064408394"/>
			</geometry>
		</visual>
		<collision>
			<geometry>
				<cylinder length="0.2200615809877765" radius="0.2761654064408394"/>
			</geometry>
		</collision>
		<inertial>
			<mass value="0.05272695044460802"/>
			<inertia ixx="0.03" iyy="0.03" izz="0.03" ixy="0" ixz="0" iyx="0"/>
		</inertial>
	</link>
	<link name="11">
		<visual>
			<geometry>
				<cylinder length="0.46262696654027" radius="0.5495511403814227"/>
			</geometry>
		</visual>
		<collision>
			<geometry>
				<cylinder length="0.46262696654027" radius="0.5495511403814227"/>
			</geometry>
		</collision>
		<inertial>
			<mass value="0.43893179769285917"/>
			<inertia ixx="0.03" iyy="0.03" izz="0.03" ixy="0" ixz="0" iyx="0"/>
		</inertial>
	</link>
	<link name="22">
		<visual>
			<geometry>
				<cylinder length="0.7390980158932943" radius="0.539671473785115"/>
			</geometry>
		</visual>
		<collision>
			<geometry>
				<cylinder length="0.7390980158932943" radius="0.539671473785115"/>
			</geometry>
		</collision>
		<inertial>
			<mass value="0.6762555372256879"/>
			<inertia ixx="0.03" iyy="0.03" izz="0.03" ixy="0" ixz="0" iyx="0"/>
		</inertial>
	</link>
	<link name="23">
		<visual>
			<geometry>
				<cylinder length="0.7390980158932943" radius="0.539671473785115"/>
			</geometry>
		</visual>
		<collision>
			<geometry>
				<cylinder length="0.7390980158932943" radius="0.539671473785115"/>
			</geometry>
		</collision>
		<inertial>
			<mass value="0.6762555372256879"/>
			<inertia ixx="0.03" iyy="0.03" izz="0.03" ixy="0" ixz="0" iyx="0"/>
		</inertial>
	</link>
	<link name="24">
		<visual>
			<geometry>
				<cylinder length="0.7390980158932943" radius="0.539671473785115"/>
			</geometry>
		</visual>
		<collision>
			<geometry>
				<cylinder length="0.7390980158932943" radius="0.539671473785115"/>
			</geometry>
		</collision>
		<inertial>
			<mass value="0.6762555372256879"/>
			<inertia ixx="0.03" iyy="0.03" izz="0.03" ixy="0" ixz="0" iyx="0"/>
		</inertial>
	</link>
	<link name="25">
		<visual>
			<geometry>
				<cylinder length="0.7390980158932943" radius="0.539671473785115"/>
			</geometry>
		</visual>
		<collision>
			<geometry>
				<cylinder length="0.7390980158932943" radius="0.539671473785115"/>
			</geometry>
		</collision>
		<inertial>
			<mass value="0.6762555372256879"/>
			<inertia ixx="0.03" iyy="0.03" izz="0.03" ixy="0" ixz="0" iyx="0"/>
		</inertial>
	</link>
	<link name="36">
		<visual>
			<geometry>
				<cylinder length="0.3378902440409972" radius="0.5898404375557437"/>
			</geometry>
		</visual>
		<collision>
			<geometry>
				<cylinder length="0.3378902440409972" radius="0.5898404375557437"/>
			</geometry>
		</collision>
		<inertial>
			<mass value="0.3693130136257478"/>
			<inertia ixx="0.03" iyy="0.03" izz="0.03" ixy="0" ixz="0" iyx="0"/>
		</inertial>
	</link>
	<link name="37">
		<visual>
			<geometry>
				<cylinder length="0.3378902440409972" radius="0.5898404375557437"/>
			</geometry>
		</visual>
		<collision>
			<geometry>
				<cylinder length="0.3378902440409972" radius="0.5898404375557437"/>
			</geometry>
		</collision>
		<inertial>
			<mass value="0.3693130136257478"/>
			<inertia ixx="0.03" iyy="0.03" izz="0.03" ixy="0" ixz="0" iyx="0"/>
		</inertial>
	</link>
	<joint name="11_to_0" type="revolute">
		<parent link="0"/>
		<child link="11"/>
		<axis xyz="0 0 1"/>
		<limit effort="1" upper="-3.1415" lower="3.1415" velocity="1"/>
		<origin rpy="4.242709261096144 6.242736811171016 1.6189296120094512" xyz="0.8317592498885846 0.6506740518234515 0.028898558806017098"/>
	</joint>
	<joint name="22_to_11" type="revolute">
		<parent link="11"/>
		<child link="22"/>
		<axis xyz="0 0 1"/>
		<limit effort="1" upper="-3.1415" lower="3.1415" velocity="1"/>
		<origin rpy="1.1685017951966374 2.607990398758587 5.279593793770392" xyz="0.7713827438134189 0.8471844793559141 0.7733132300909366"/>
	</joint>
	<joint name="23_to_11" type="revolute">
		<parent link="11"/>
		<child link="23"/>
		<axis xyz="0 0 1"/>
		<limit effort="1" upper="-3.1415" lower="3.1415" velocity="1"/>
		<origin rpy="1.7527526927949562 2.607990398758587 5.279593793770392" xyz="0.7713827438134189 0.8471844793559141 0.7733132300909366"/>
	</joint>
	<joint name="24_to_11" type="revolute">
		<parent link="11"/>
		<child link="24"/>
		<axis xyz="0 0 1"/>
		<limit effort="1" upper="-3.1415" lower="3.1415" velocity="1"/>
		<origin rpy="2.337003590393275 2.607990398758587 5.279593793770392" xyz="0.7713827438134189 0.8471844793559141 0.7733132300909366"/>
	</joint>
	<joint name="25_to_11" type="revolute">
		<parent link="11"/>
		<child link="25"/>
		<axis xyz="0 0 1"/>
		<limit effort="1" upper="-3.1415" lower="3.1415" velocity="1"/>
		<origin rpy="2.9212544879915936 2.607990398758587 5.279593793770392" xyz="0.7713827438134189 0.8471844793559141 0.7733132300909366"/>
	</joint>
	<joint name="36_to_0" type="revolute">
		<parent link="0"/>
		<child link="36"/>
		<axis xyz="0 0 1"/>
		<limit effort="1" upper="-3.1415" lower="3.1415" velocity="1"/>
		<origin rpy="10.023161449708818 5.071470531415218 3.1593269496086744" xyz="0.3564701274709101 0.7731346677060382 0.5835350714842641"/>
	</joint>
	<joint name="37_to_0" type="revolute">
		<parent link="0"/>
		<child link="37"/>
		<axis xyz="0 0 1"/>
		<limit effort="1" upper="-3.1415" lower="3.1415" velocity="1"/>
		<origin rpy="13.364215266278423 5.071470531415218 3.1593269496086744" xyz="0.3564701274709101 0.7731346677060382 0.5835350714842641"/>
	</joint>
</robot>
